{
 "cells": [
  {
   "cell_type": "code",
   "execution_count": 21,
   "metadata": {},
   "outputs": [],
   "source": [
    "import pandas as pd\n",
    "import numpy as np\n",
    "import dash\n",
    "import flask\n",
    "from dash.dependencies import Input, Output\n",
    "import dash_core_components as dcc\n",
    "import dash_html_components as html\n",
    "from pandas_datareader import data as web\n",
    "from datetime import datetime as dt"
   ]
  },
  {
   "cell_type": "code",
   "execution_count": 22,
   "metadata": {},
   "outputs": [],
   "source": [
    "import pymongo"
   ]
  },
  {
   "cell_type": "code",
   "execution_count": 24,
   "metadata": {},
   "outputs": [],
   "source": [
    "from dotenv import load_dotenv\n",
    "load_dotenv()\n",
    "import os\n",
    "password = os.getenv(\"PASSWORD\")\n",
    "username = os.getenv(\"USERNAME\")"
   ]
  },
  {
   "cell_type": "code",
   "execution_count": 26,
   "metadata": {},
   "outputs": [],
   "source": [
    "client = pymongo.MongoClient('mongodb://%s:%s@127.0.0.1' % (username, password))\n",
    "db = client[\"1-gram_time\"]"
   ]
  },
  {
   "cell_type": "code",
   "execution_count": 27,
   "metadata": {},
   "outputs": [
    {
     "data": {
      "text/html": [
       "<div>\n",
       "<style scoped>\n",
       "    .dataframe tbody tr th:only-of-type {\n",
       "        vertical-align: middle;\n",
       "    }\n",
       "\n",
       "    .dataframe tbody tr th {\n",
       "        vertical-align: top;\n",
       "    }\n",
       "\n",
       "    .dataframe thead th {\n",
       "        text-align: right;\n",
       "    }\n",
       "</style>\n",
       "<table border=\"1\" class=\"dataframe\">\n",
       "  <thead>\n",
       "    <tr style=\"text-align: right;\">\n",
       "      <th></th>\n",
       "      <th>_id</th>\n",
       "      <th>counts</th>\n",
       "      <th>rank</th>\n",
       "      <th>time</th>\n",
       "      <th>word</th>\n",
       "    </tr>\n",
       "  </thead>\n",
       "  <tbody>\n",
       "    <tr>\n",
       "      <th>0</th>\n",
       "      <td>5c328d4a5920610636fb2ca0</td>\n",
       "      <td>2374312</td>\n",
       "      <td>8</td>\n",
       "      <td>2018-05-20</td>\n",
       "      <td>and</td>\n",
       "    </tr>\n",
       "    <tr>\n",
       "      <th>1</th>\n",
       "      <td>5c328d4d5920610636fcb3dc</td>\n",
       "      <td>2011354</td>\n",
       "      <td>9</td>\n",
       "      <td>2014-07-06</td>\n",
       "      <td>and</td>\n",
       "    </tr>\n",
       "    <tr>\n",
       "      <th>2</th>\n",
       "      <td>5c328d505920610636fe3b09</td>\n",
       "      <td>130232</td>\n",
       "      <td>9</td>\n",
       "      <td>2010-02-22</td>\n",
       "      <td>and</td>\n",
       "    </tr>\n",
       "    <tr>\n",
       "      <th>3</th>\n",
       "      <td>5c328d545920610636ffe431</td>\n",
       "      <td>1827301</td>\n",
       "      <td>9</td>\n",
       "      <td>2018-05-03</td>\n",
       "      <td>and</td>\n",
       "    </tr>\n",
       "    <tr>\n",
       "      <th>4</th>\n",
       "      <td>5c328d575920610636016df4</td>\n",
       "      <td>1917554</td>\n",
       "      <td>9</td>\n",
       "      <td>2015-02-17</td>\n",
       "      <td>and</td>\n",
       "    </tr>\n",
       "  </tbody>\n",
       "</table>\n",
       "</div>"
      ],
      "text/plain": [
       "                        _id   counts rank       time word\n",
       "0  5c328d4a5920610636fb2ca0  2374312    8 2018-05-20  and\n",
       "1  5c328d4d5920610636fcb3dc  2011354    9 2014-07-06  and\n",
       "2  5c328d505920610636fe3b09   130232    9 2010-02-22  and\n",
       "3  5c328d545920610636ffe431  1827301    9 2018-05-03  and\n",
       "4  5c328d575920610636016df4  1917554    9 2015-02-17  and"
      ]
     },
     "execution_count": 27,
     "metadata": {},
     "output_type": "execute_result"
    }
   ],
   "source": [
    "df = pd.DataFrame(list(db[\"tweets\"].find({ \"word\": \"and\" })))\n",
    "df.head(5)"
   ]
  },
  {
   "cell_type": "code",
   "execution_count": 7,
   "metadata": {},
   "outputs": [],
   "source": [
    "def load(word):\n",
    "    try:\n",
    "        df = pd.DataFrame(list(db[\"tweets\"].find({ \"word\": word})))\n",
    "        df = df.sort_values(by=['time'])\n",
    "        #df['date'] = [dt.strptime(time, '%Y-%m-%d') for time in df['time']]\n",
    "        df['year'] = [date.year for date in df['time']]\n",
    "        df['day'] = [date.timetuple().tm_yday for date in df['time']]\n",
    "        return df\n",
    "    except:\n",
    "        df = pd.DataFrame()\n",
    "        return df"
   ]
  },
  {
   "cell_type": "code",
   "execution_count": null,
   "metadata": {},
   "outputs": [
    {
     "name": "stdout",
     "output_type": "stream",
     "text": [
      " * Tip: There are .env files present. Do \"pip install python-dotenv\" to use them.\n",
      " * Serving Flask app \"__main__\" (lazy loading)\n",
      " * Environment: production\n",
      "   WARNING: Do not use the development server in a production environment.\n",
      "   Use a production WSGI server instead.\n",
      " * Debug mode: off\n"
     ]
    },
    {
     "name": "stderr",
     "output_type": "stream",
     "text": [
      " * Running on http://127.0.0.1:8050/ (Press CTRL+C to quit)\n",
      "127.0.0.1 - - [19/Mar/2019 12:52:20] \"GET / HTTP/1.1\" 200 -\n",
      "127.0.0.1 - - [19/Mar/2019 12:52:21] \"GET /styles.css HTTP/1.1\" 200 -\n",
      "127.0.0.1 - - [19/Mar/2019 12:52:21] \"GET /_dash-layout HTTP/1.1\" 200 -\n",
      "127.0.0.1 - - [19/Mar/2019 12:52:21] \"GET /_dash-dependencies HTTP/1.1\" 200 -\n",
      "[2019-03-19 12:52:21,769] ERROR in app: Exception on /_dash-update-component [POST]\n",
      "Traceback (most recent call last):\n",
      "  File \"/home/janeadams/.conda/envs/test_env/lib/python3.7/site-packages/pandas/core/indexes/base.py\", line 2656, in get_loc\n",
      "    return self._engine.get_loc(key)\n",
      "  File \"pandas/_libs/index.pyx\", line 108, in pandas._libs.index.IndexEngine.get_loc\n",
      "  File \"pandas/_libs/index.pyx\", line 132, in pandas._libs.index.IndexEngine.get_loc\n",
      "  File \"pandas/_libs/hashtable_class_helper.pxi\", line 1601, in pandas._libs.hashtable.PyObjectHashTable.get_item\n",
      "  File \"pandas/_libs/hashtable_class_helper.pxi\", line 1608, in pandas._libs.hashtable.PyObjectHashTable.get_item\n",
      "KeyError: 'time'\n",
      "\n",
      "During handling of the above exception, another exception occurred:\n",
      "\n",
      "Traceback (most recent call last):\n",
      "  File \"/home/janeadams/.conda/envs/test_env/lib/python3.7/site-packages/flask/app.py\", line 2292, in wsgi_app\n",
      "    response = self.full_dispatch_request()\n",
      "  File \"/home/janeadams/.conda/envs/test_env/lib/python3.7/site-packages/flask/app.py\", line 1815, in full_dispatch_request\n",
      "    rv = self.handle_user_exception(e)\n",
      "  File \"/home/janeadams/.conda/envs/test_env/lib/python3.7/site-packages/flask/app.py\", line 1718, in handle_user_exception\n",
      "    reraise(exc_type, exc_value, tb)\n",
      "  File \"/home/janeadams/.conda/envs/test_env/lib/python3.7/site-packages/flask/_compat.py\", line 35, in reraise\n",
      "    raise value\n",
      "  File \"/home/janeadams/.conda/envs/test_env/lib/python3.7/site-packages/flask/app.py\", line 1813, in full_dispatch_request\n",
      "    rv = self.dispatch_request()\n",
      "  File \"/home/janeadams/.conda/envs/test_env/lib/python3.7/site-packages/flask/app.py\", line 1799, in dispatch_request\n",
      "    return self.view_functions[rule.endpoint](**req.view_args)\n",
      "  File \"/home/janeadams/.conda/envs/test_env/lib/python3.7/site-packages/dash/dash.py\", line 960, in dispatch\n",
      "    return self.callback_map[target_id]['callback'](*args)\n",
      "  File \"/home/janeadams/.conda/envs/test_env/lib/python3.7/site-packages/dash/dash.py\", line 900, in add_context\n",
      "    output_value = func(*args, **kwargs)\n",
      "  File \"<ipython-input-28-8ad0d62df5cc>\", line 25, in update_graph\n",
      "    data.append({'x':df['time'], 'y':df['counts'],'name':item})\n",
      "  File \"/home/janeadams/.conda/envs/test_env/lib/python3.7/site-packages/pandas/core/frame.py\", line 2927, in __getitem__\n",
      "    indexer = self.columns.get_loc(key)\n",
      "  File \"/home/janeadams/.conda/envs/test_env/lib/python3.7/site-packages/pandas/core/indexes/base.py\", line 2658, in get_loc\n",
      "    return self._engine.get_loc(self._maybe_cast_indexer(key))\n",
      "  File \"pandas/_libs/index.pyx\", line 108, in pandas._libs.index.IndexEngine.get_loc\n",
      "  File \"pandas/_libs/index.pyx\", line 132, in pandas._libs.index.IndexEngine.get_loc\n",
      "  File \"pandas/_libs/hashtable_class_helper.pxi\", line 1601, in pandas._libs.hashtable.PyObjectHashTable.get_item\n",
      "  File \"pandas/_libs/hashtable_class_helper.pxi\", line 1608, in pandas._libs.hashtable.PyObjectHashTable.get_item\n",
      "KeyError: 'time'\n",
      "127.0.0.1 - - [19/Mar/2019 12:52:21] \"POST /_dash-update-component HTTP/1.1\" 500 -\n",
      "[2019-03-19 12:52:24,308] ERROR in app: Exception on /_dash-update-component [POST]\n",
      "Traceback (most recent call last):\n",
      "  File \"/home/janeadams/.conda/envs/test_env/lib/python3.7/site-packages/pandas/core/indexes/base.py\", line 2656, in get_loc\n",
      "    return self._engine.get_loc(key)\n",
      "  File \"pandas/_libs/index.pyx\", line 108, in pandas._libs.index.IndexEngine.get_loc\n",
      "  File \"pandas/_libs/index.pyx\", line 132, in pandas._libs.index.IndexEngine.get_loc\n",
      "  File \"pandas/_libs/hashtable_class_helper.pxi\", line 1601, in pandas._libs.hashtable.PyObjectHashTable.get_item\n",
      "  File \"pandas/_libs/hashtable_class_helper.pxi\", line 1608, in pandas._libs.hashtable.PyObjectHashTable.get_item\n",
      "KeyError: 'time'\n",
      "\n",
      "During handling of the above exception, another exception occurred:\n",
      "\n",
      "Traceback (most recent call last):\n",
      "  File \"/home/janeadams/.conda/envs/test_env/lib/python3.7/site-packages/flask/app.py\", line 2292, in wsgi_app\n",
      "    response = self.full_dispatch_request()\n",
      "  File \"/home/janeadams/.conda/envs/test_env/lib/python3.7/site-packages/flask/app.py\", line 1815, in full_dispatch_request\n",
      "    rv = self.handle_user_exception(e)\n",
      "  File \"/home/janeadams/.conda/envs/test_env/lib/python3.7/site-packages/flask/app.py\", line 1718, in handle_user_exception\n",
      "    reraise(exc_type, exc_value, tb)\n",
      "  File \"/home/janeadams/.conda/envs/test_env/lib/python3.7/site-packages/flask/_compat.py\", line 35, in reraise\n",
      "    raise value\n",
      "  File \"/home/janeadams/.conda/envs/test_env/lib/python3.7/site-packages/flask/app.py\", line 1813, in full_dispatch_request\n",
      "    rv = self.dispatch_request()\n",
      "  File \"/home/janeadams/.conda/envs/test_env/lib/python3.7/site-packages/flask/app.py\", line 1799, in dispatch_request\n",
      "    return self.view_functions[rule.endpoint](**req.view_args)\n",
      "  File \"/home/janeadams/.conda/envs/test_env/lib/python3.7/site-packages/dash/dash.py\", line 960, in dispatch\n",
      "    return self.callback_map[target_id]['callback'](*args)\n",
      "  File \"/home/janeadams/.conda/envs/test_env/lib/python3.7/site-packages/dash/dash.py\", line 900, in add_context\n",
      "    output_value = func(*args, **kwargs)\n",
      "  File \"<ipython-input-28-8ad0d62df5cc>\", line 25, in update_graph\n",
      "    data.append({'x':df['time'], 'y':df['counts'],'name':item})\n",
      "  File \"/home/janeadams/.conda/envs/test_env/lib/python3.7/site-packages/pandas/core/frame.py\", line 2927, in __getitem__\n",
      "    indexer = self.columns.get_loc(key)\n",
      "  File \"/home/janeadams/.conda/envs/test_env/lib/python3.7/site-packages/pandas/core/indexes/base.py\", line 2658, in get_loc\n",
      "    return self._engine.get_loc(self._maybe_cast_indexer(key))\n",
      "  File \"pandas/_libs/index.pyx\", line 108, in pandas._libs.index.IndexEngine.get_loc\n",
      "  File \"pandas/_libs/index.pyx\", line 132, in pandas._libs.index.IndexEngine.get_loc\n",
      "  File \"pandas/_libs/hashtable_class_helper.pxi\", line 1601, in pandas._libs.hashtable.PyObjectHashTable.get_item\n",
      "  File \"pandas/_libs/hashtable_class_helper.pxi\", line 1608, in pandas._libs.hashtable.PyObjectHashTable.get_item\n",
      "KeyError: 'time'\n",
      "127.0.0.1 - - [19/Mar/2019 12:52:24] \"POST /_dash-update-component HTTP/1.1\" 500 -\n",
      "[2019-03-19 12:52:24,599] ERROR in app: Exception on /_dash-update-component [POST]\n",
      "Traceback (most recent call last):\n",
      "  File \"/home/janeadams/.conda/envs/test_env/lib/python3.7/site-packages/pandas/core/indexes/base.py\", line 2656, in get_loc\n",
      "    return self._engine.get_loc(key)\n",
      "  File \"pandas/_libs/index.pyx\", line 108, in pandas._libs.index.IndexEngine.get_loc\n",
      "  File \"pandas/_libs/index.pyx\", line 132, in pandas._libs.index.IndexEngine.get_loc\n",
      "  File \"pandas/_libs/hashtable_class_helper.pxi\", line 1601, in pandas._libs.hashtable.PyObjectHashTable.get_item\n",
      "  File \"pandas/_libs/hashtable_class_helper.pxi\", line 1608, in pandas._libs.hashtable.PyObjectHashTable.get_item\n",
      "KeyError: 'time'\n",
      "\n",
      "During handling of the above exception, another exception occurred:\n",
      "\n",
      "Traceback (most recent call last):\n",
      "  File \"/home/janeadams/.conda/envs/test_env/lib/python3.7/site-packages/flask/app.py\", line 2292, in wsgi_app\n",
      "    response = self.full_dispatch_request()\n",
      "  File \"/home/janeadams/.conda/envs/test_env/lib/python3.7/site-packages/flask/app.py\", line 1815, in full_dispatch_request\n",
      "    rv = self.handle_user_exception(e)\n",
      "  File \"/home/janeadams/.conda/envs/test_env/lib/python3.7/site-packages/flask/app.py\", line 1718, in handle_user_exception\n",
      "    reraise(exc_type, exc_value, tb)\n",
      "  File \"/home/janeadams/.conda/envs/test_env/lib/python3.7/site-packages/flask/_compat.py\", line 35, in reraise\n",
      "    raise value\n",
      "  File \"/home/janeadams/.conda/envs/test_env/lib/python3.7/site-packages/flask/app.py\", line 1813, in full_dispatch_request\n",
      "    rv = self.dispatch_request()\n",
      "  File \"/home/janeadams/.conda/envs/test_env/lib/python3.7/site-packages/flask/app.py\", line 1799, in dispatch_request\n",
      "    return self.view_functions[rule.endpoint](**req.view_args)\n",
      "  File \"/home/janeadams/.conda/envs/test_env/lib/python3.7/site-packages/dash/dash.py\", line 960, in dispatch\n",
      "    return self.callback_map[target_id]['callback'](*args)\n",
      "  File \"/home/janeadams/.conda/envs/test_env/lib/python3.7/site-packages/dash/dash.py\", line 900, in add_context\n",
      "    output_value = func(*args, **kwargs)\n",
      "  File \"<ipython-input-28-8ad0d62df5cc>\", line 25, in update_graph\n",
      "    data.append({'x':df['time'], 'y':df['counts'],'name':item})\n",
      "  File \"/home/janeadams/.conda/envs/test_env/lib/python3.7/site-packages/pandas/core/frame.py\", line 2927, in __getitem__\n",
      "    indexer = self.columns.get_loc(key)\n",
      "  File \"/home/janeadams/.conda/envs/test_env/lib/python3.7/site-packages/pandas/core/indexes/base.py\", line 2658, in get_loc\n",
      "    return self._engine.get_loc(self._maybe_cast_indexer(key))\n",
      "  File \"pandas/_libs/index.pyx\", line 108, in pandas._libs.index.IndexEngine.get_loc\n",
      "  File \"pandas/_libs/index.pyx\", line 132, in pandas._libs.index.IndexEngine.get_loc\n",
      "  File \"pandas/_libs/hashtable_class_helper.pxi\", line 1601, in pandas._libs.hashtable.PyObjectHashTable.get_item\n",
      "  File \"pandas/_libs/hashtable_class_helper.pxi\", line 1608, in pandas._libs.hashtable.PyObjectHashTable.get_item\n",
      "KeyError: 'time'\n"
     ]
    },
    {
     "name": "stderr",
     "output_type": "stream",
     "text": [
      "127.0.0.1 - - [19/Mar/2019 12:52:24] \"POST /_dash-update-component HTTP/1.1\" 500 -\n",
      "[2019-03-19 12:52:24,807] ERROR in app: Exception on /_dash-update-component [POST]\n",
      "Traceback (most recent call last):\n",
      "  File \"/home/janeadams/.conda/envs/test_env/lib/python3.7/site-packages/pandas/core/indexes/base.py\", line 2656, in get_loc\n",
      "    return self._engine.get_loc(key)\n",
      "  File \"pandas/_libs/index.pyx\", line 108, in pandas._libs.index.IndexEngine.get_loc\n",
      "  File \"pandas/_libs/index.pyx\", line 132, in pandas._libs.index.IndexEngine.get_loc\n",
      "  File \"pandas/_libs/hashtable_class_helper.pxi\", line 1601, in pandas._libs.hashtable.PyObjectHashTable.get_item\n",
      "  File \"pandas/_libs/hashtable_class_helper.pxi\", line 1608, in pandas._libs.hashtable.PyObjectHashTable.get_item\n",
      "KeyError: 'time'\n",
      "\n",
      "During handling of the above exception, another exception occurred:\n",
      "\n",
      "Traceback (most recent call last):\n",
      "  File \"/home/janeadams/.conda/envs/test_env/lib/python3.7/site-packages/flask/app.py\", line 2292, in wsgi_app\n",
      "    response = self.full_dispatch_request()\n",
      "  File \"/home/janeadams/.conda/envs/test_env/lib/python3.7/site-packages/flask/app.py\", line 1815, in full_dispatch_request\n",
      "    rv = self.handle_user_exception(e)\n",
      "  File \"/home/janeadams/.conda/envs/test_env/lib/python3.7/site-packages/flask/app.py\", line 1718, in handle_user_exception\n",
      "    reraise(exc_type, exc_value, tb)\n",
      "  File \"/home/janeadams/.conda/envs/test_env/lib/python3.7/site-packages/flask/_compat.py\", line 35, in reraise\n",
      "    raise value\n",
      "  File \"/home/janeadams/.conda/envs/test_env/lib/python3.7/site-packages/flask/app.py\", line 1813, in full_dispatch_request\n",
      "    rv = self.dispatch_request()\n",
      "  File \"/home/janeadams/.conda/envs/test_env/lib/python3.7/site-packages/flask/app.py\", line 1799, in dispatch_request\n",
      "    return self.view_functions[rule.endpoint](**req.view_args)\n",
      "  File \"/home/janeadams/.conda/envs/test_env/lib/python3.7/site-packages/dash/dash.py\", line 960, in dispatch\n",
      "    return self.callback_map[target_id]['callback'](*args)\n",
      "  File \"/home/janeadams/.conda/envs/test_env/lib/python3.7/site-packages/dash/dash.py\", line 900, in add_context\n",
      "    output_value = func(*args, **kwargs)\n",
      "  File \"<ipython-input-28-8ad0d62df5cc>\", line 25, in update_graph\n",
      "    data.append({'x':df['time'], 'y':df['counts'],'name':item})\n",
      "  File \"/home/janeadams/.conda/envs/test_env/lib/python3.7/site-packages/pandas/core/frame.py\", line 2927, in __getitem__\n",
      "    indexer = self.columns.get_loc(key)\n",
      "  File \"/home/janeadams/.conda/envs/test_env/lib/python3.7/site-packages/pandas/core/indexes/base.py\", line 2658, in get_loc\n",
      "    return self._engine.get_loc(self._maybe_cast_indexer(key))\n",
      "  File \"pandas/_libs/index.pyx\", line 108, in pandas._libs.index.IndexEngine.get_loc\n",
      "  File \"pandas/_libs/index.pyx\", line 132, in pandas._libs.index.IndexEngine.get_loc\n",
      "  File \"pandas/_libs/hashtable_class_helper.pxi\", line 1601, in pandas._libs.hashtable.PyObjectHashTable.get_item\n",
      "  File \"pandas/_libs/hashtable_class_helper.pxi\", line 1608, in pandas._libs.hashtable.PyObjectHashTable.get_item\n",
      "KeyError: 'time'\n",
      "127.0.0.1 - - [19/Mar/2019 12:52:24] \"POST /_dash-update-component HTTP/1.1\" 500 -\n",
      "[2019-03-19 12:52:24,978] ERROR in app: Exception on /_dash-update-component [POST]\n",
      "Traceback (most recent call last):\n",
      "  File \"/home/janeadams/.conda/envs/test_env/lib/python3.7/site-packages/pandas/core/indexes/base.py\", line 2656, in get_loc\n",
      "    return self._engine.get_loc(key)\n",
      "  File \"pandas/_libs/index.pyx\", line 108, in pandas._libs.index.IndexEngine.get_loc\n",
      "  File \"pandas/_libs/index.pyx\", line 132, in pandas._libs.index.IndexEngine.get_loc\n",
      "  File \"pandas/_libs/hashtable_class_helper.pxi\", line 1601, in pandas._libs.hashtable.PyObjectHashTable.get_item\n",
      "  File \"pandas/_libs/hashtable_class_helper.pxi\", line 1608, in pandas._libs.hashtable.PyObjectHashTable.get_item\n",
      "KeyError: 'time'\n",
      "\n",
      "During handling of the above exception, another exception occurred:\n",
      "\n",
      "Traceback (most recent call last):\n",
      "  File \"/home/janeadams/.conda/envs/test_env/lib/python3.7/site-packages/flask/app.py\", line 2292, in wsgi_app\n",
      "    response = self.full_dispatch_request()\n",
      "  File \"/home/janeadams/.conda/envs/test_env/lib/python3.7/site-packages/flask/app.py\", line 1815, in full_dispatch_request\n",
      "    rv = self.handle_user_exception(e)\n",
      "  File \"/home/janeadams/.conda/envs/test_env/lib/python3.7/site-packages/flask/app.py\", line 1718, in handle_user_exception\n",
      "    reraise(exc_type, exc_value, tb)\n",
      "  File \"/home/janeadams/.conda/envs/test_env/lib/python3.7/site-packages/flask/_compat.py\", line 35, in reraise\n",
      "    raise value\n",
      "  File \"/home/janeadams/.conda/envs/test_env/lib/python3.7/site-packages/flask/app.py\", line 1813, in full_dispatch_request\n",
      "    rv = self.dispatch_request()\n",
      "  File \"/home/janeadams/.conda/envs/test_env/lib/python3.7/site-packages/flask/app.py\", line 1799, in dispatch_request\n",
      "    return self.view_functions[rule.endpoint](**req.view_args)\n",
      "  File \"/home/janeadams/.conda/envs/test_env/lib/python3.7/site-packages/dash/dash.py\", line 960, in dispatch\n",
      "    return self.callback_map[target_id]['callback'](*args)\n",
      "  File \"/home/janeadams/.conda/envs/test_env/lib/python3.7/site-packages/dash/dash.py\", line 900, in add_context\n",
      "    output_value = func(*args, **kwargs)\n",
      "  File \"<ipython-input-28-8ad0d62df5cc>\", line 25, in update_graph\n",
      "    data.append({'x':df['time'], 'y':df['counts'],'name':item})\n",
      "  File \"/home/janeadams/.conda/envs/test_env/lib/python3.7/site-packages/pandas/core/frame.py\", line 2927, in __getitem__\n",
      "    indexer = self.columns.get_loc(key)\n",
      "  File \"/home/janeadams/.conda/envs/test_env/lib/python3.7/site-packages/pandas/core/indexes/base.py\", line 2658, in get_loc\n",
      "    return self._engine.get_loc(self._maybe_cast_indexer(key))\n",
      "  File \"pandas/_libs/index.pyx\", line 108, in pandas._libs.index.IndexEngine.get_loc\n",
      "  File \"pandas/_libs/index.pyx\", line 132, in pandas._libs.index.IndexEngine.get_loc\n",
      "  File \"pandas/_libs/hashtable_class_helper.pxi\", line 1601, in pandas._libs.hashtable.PyObjectHashTable.get_item\n",
      "  File \"pandas/_libs/hashtable_class_helper.pxi\", line 1608, in pandas._libs.hashtable.PyObjectHashTable.get_item\n",
      "KeyError: 'time'\n",
      "127.0.0.1 - - [19/Mar/2019 12:52:24] \"POST /_dash-update-component HTTP/1.1\" 500 -\n",
      "[2019-03-19 12:52:25,082] ERROR in app: Exception on /_dash-update-component [POST]\n",
      "Traceback (most recent call last):\n",
      "  File \"/home/janeadams/.conda/envs/test_env/lib/python3.7/site-packages/pandas/core/indexes/base.py\", line 2656, in get_loc\n",
      "    return self._engine.get_loc(key)\n",
      "  File \"pandas/_libs/index.pyx\", line 108, in pandas._libs.index.IndexEngine.get_loc\n",
      "  File \"pandas/_libs/index.pyx\", line 132, in pandas._libs.index.IndexEngine.get_loc\n",
      "  File \"pandas/_libs/hashtable_class_helper.pxi\", line 1601, in pandas._libs.hashtable.PyObjectHashTable.get_item\n",
      "  File \"pandas/_libs/hashtable_class_helper.pxi\", line 1608, in pandas._libs.hashtable.PyObjectHashTable.get_item\n",
      "KeyError: 'time'\n",
      "\n",
      "During handling of the above exception, another exception occurred:\n",
      "\n",
      "Traceback (most recent call last):\n",
      "  File \"/home/janeadams/.conda/envs/test_env/lib/python3.7/site-packages/flask/app.py\", line 2292, in wsgi_app\n",
      "    response = self.full_dispatch_request()\n",
      "  File \"/home/janeadams/.conda/envs/test_env/lib/python3.7/site-packages/flask/app.py\", line 1815, in full_dispatch_request\n",
      "    rv = self.handle_user_exception(e)\n",
      "  File \"/home/janeadams/.conda/envs/test_env/lib/python3.7/site-packages/flask/app.py\", line 1718, in handle_user_exception\n",
      "    reraise(exc_type, exc_value, tb)\n",
      "  File \"/home/janeadams/.conda/envs/test_env/lib/python3.7/site-packages/flask/_compat.py\", line 35, in reraise\n",
      "    raise value\n",
      "  File \"/home/janeadams/.conda/envs/test_env/lib/python3.7/site-packages/flask/app.py\", line 1813, in full_dispatch_request\n",
      "    rv = self.dispatch_request()\n",
      "  File \"/home/janeadams/.conda/envs/test_env/lib/python3.7/site-packages/flask/app.py\", line 1799, in dispatch_request\n",
      "    return self.view_functions[rule.endpoint](**req.view_args)\n",
      "  File \"/home/janeadams/.conda/envs/test_env/lib/python3.7/site-packages/dash/dash.py\", line 960, in dispatch\n",
      "    return self.callback_map[target_id]['callback'](*args)\n",
      "  File \"/home/janeadams/.conda/envs/test_env/lib/python3.7/site-packages/dash/dash.py\", line 900, in add_context\n",
      "    output_value = func(*args, **kwargs)\n",
      "  File \"<ipython-input-28-8ad0d62df5cc>\", line 25, in update_graph\n",
      "    data.append({'x':df['time'], 'y':df['counts'],'name':item})\n",
      "  File \"/home/janeadams/.conda/envs/test_env/lib/python3.7/site-packages/pandas/core/frame.py\", line 2927, in __getitem__\n",
      "    indexer = self.columns.get_loc(key)\n",
      "  File \"/home/janeadams/.conda/envs/test_env/lib/python3.7/site-packages/pandas/core/indexes/base.py\", line 2658, in get_loc\n",
      "    return self._engine.get_loc(self._maybe_cast_indexer(key))\n",
      "  File \"pandas/_libs/index.pyx\", line 108, in pandas._libs.index.IndexEngine.get_loc\n",
      "  File \"pandas/_libs/index.pyx\", line 132, in pandas._libs.index.IndexEngine.get_loc\n",
      "  File \"pandas/_libs/hashtable_class_helper.pxi\", line 1601, in pandas._libs.hashtable.PyObjectHashTable.get_item\n",
      "  File \"pandas/_libs/hashtable_class_helper.pxi\", line 1608, in pandas._libs.hashtable.PyObjectHashTable.get_item\n",
      "KeyError: 'time'\n"
     ]
    },
    {
     "name": "stderr",
     "output_type": "stream",
     "text": [
      "127.0.0.1 - - [19/Mar/2019 12:52:25] \"POST /_dash-update-component HTTP/1.1\" 500 -\n"
     ]
    }
   ],
   "source": [
    "external_stylesheets = ['styles.css']\n",
    "\n",
    "server = flask.Flask(__name__)\n",
    "\n",
    "app = dash.Dash(__name__, server=server, external_stylesheets=external_stylesheets)\n",
    "\n",
    "app.layout = html.Div([\n",
    "    dcc.Input(id='my-id', value='initial value', type='text'),\n",
    "    html.Div(id='my-div')\n",
    "])\n",
    "\n",
    "app.layout = html.Div([\n",
    "    html.H1('Twitter 1-grams'),\n",
    "    dcc.Input(id='my-id', value='initial value', type='text'),\n",
    "    dcc.Graph(id='my-graph'),\n",
    "])\n",
    "\n",
    "@app.callback(Output('my-graph', 'figure'), [Input('my-id', 'value')])\n",
    "def update_graph(input_value):\n",
    "    data=[]\n",
    "    figure = {'data':data}\n",
    "    values = input_value.split(',')\n",
    "    for item in values:\n",
    "        df = load(item)\n",
    "        data.append({'x':df['time'], 'y':df['counts'],'name':item})\n",
    "    return figure\n",
    "\n",
    "\n",
    "if __name__ == '__main__':\n",
    "    app.run_server()"
   ]
  },
  {
   "cell_type": "code",
   "execution_count": null,
   "metadata": {},
   "outputs": [],
   "source": []
  },
  {
   "cell_type": "code",
   "execution_count": null,
   "metadata": {},
   "outputs": [],
   "source": []
  }
 ],
 "metadata": {
  "kernelspec": {
   "display_name": "Python (TestEnv)",
   "language": "python",
   "name": "test_env"
  },
  "language_info": {
   "codemirror_mode": {
    "name": "ipython",
    "version": 3
   },
   "file_extension": ".py",
   "mimetype": "text/x-python",
   "name": "python",
   "nbconvert_exporter": "python",
   "pygments_lexer": "ipython3",
   "version": "3.7.2"
  }
 },
 "nbformat": 4,
 "nbformat_minor": 2
}
