{
 "cells": [
  {
   "cell_type": "code",
   "execution_count": 2,
   "metadata": {},
   "outputs": [],
   "source": [
    "import pandas as pd\n",
    "import numpy as np\n",
    "import dash\n",
    "import flask\n",
    "from dash.dependencies import Input, Output\n",
    "import dash_core_components as dcc\n",
    "import dash_html_components as html\n",
    "from pandas_datareader import data as web\n",
    "from datetime import datetime as dt"
   ]
  },
  {
   "cell_type": "code",
   "execution_count": 3,
   "metadata": {},
   "outputs": [],
   "source": [
    "import pymongo"
   ]
  },
  {
   "cell_type": "code",
   "execution_count": 4,
   "metadata": {},
   "outputs": [],
   "source": [
    "from dotenv import load_dotenv\n",
    "load_dotenv()\n",
    "import os\n",
    "password = os.getenv(\"PASSWORD\")\n",
    "username = os.getenv(\"USERNAME\")"
   ]
  },
  {
   "cell_type": "code",
   "execution_count": 5,
   "metadata": {},
   "outputs": [],
   "source": [
    "client = pymongo.MongoClient('mongodb://%s:%s@127.0.0.1' % (username, password))\n",
    "db = client[\"1-grams\"]"
   ]
  },
  {
   "cell_type": "code",
   "execution_count": null,
   "metadata": {},
   "outputs": [
    {
     "data": {
      "text/plain": [
       "\"\\nimport csv\\nwordlist = []\\nwith open('wordlist.csv', 'rt') as f:\\n    reader = csv.reader(f)\\n    wordlist = list(reader)\\n\""
      ]
     },
     "execution_count": 6,
     "metadata": {},
     "output_type": "execute_result"
    }
   ],
   "source": [
    "\"\"\"\n",
    "import csv\n",
    "wordlist = []\n",
    "with open('wordlist.csv', 'rt') as f:\n",
    "    reader = csv.reader(f)\n",
    "    wordlist = list(reader)\n",
    "\"\"\""
   ]
  },
  {
   "cell_type": "code",
   "execution_count": null,
   "metadata": {},
   "outputs": [],
   "source": [
    "def load(word):\n",
    "    try:\n",
    "        df = pd.DataFrame(list(db[\"tweets\"].find({ \"word\": word})))\n",
    "        df = df.sort_values(by=['time'])\n",
    "        df['year'] = [date.year for date in df['time']]\n",
    "        df['day'] = [date.timetuple().tm_yday for date in df['time']]\n",
    "        return df\n",
    "    except:\n",
    "        print(str(\"No timeseries found for \"+word))\n",
    "        df = pd.DataFrame()\n",
    "        return df"
   ]
  },
  {
   "cell_type": "markdown",
   "metadata": {},
   "source": [
    "# Input box for query"
   ]
  },
  {
   "cell_type": "code",
   "execution_count": null,
   "metadata": {},
   "outputs": [
    {
     "name": "stdout",
     "output_type": "stream",
     "text": [
      " * Serving Flask app \"__main__\" (lazy loading)\n",
      " * Environment: production\n",
      "   WARNING: Do not use the development server in a production environment.\n",
      "   Use a production WSGI server instead.\n",
      " * Debug mode: off\n"
     ]
    },
    {
     "name": "stderr",
     "output_type": "stream",
     "text": [
      " * Running on http://127.0.0.1:8050/ (Press CTRL+C to quit)\n",
      "127.0.0.1 - - [09/Apr/2019 15:53:30] \"GET / HTTP/1.1\" 200 -\n",
      "127.0.0.1 - - [09/Apr/2019 15:53:30] \"GET /styles.css HTTP/1.1\" 200 -\n",
      "127.0.0.1 - - [09/Apr/2019 15:53:30] \"GET /_dash-layout HTTP/1.1\" 200 -\n",
      "127.0.0.1 - - [09/Apr/2019 15:53:30] \"GET /_dash-dependencies HTTP/1.1\" 200 -\n",
      "127.0.0.1 - - [09/Apr/2019 15:53:31] \"POST /_dash-update-component HTTP/1.1\" 200 -\n",
      "127.0.0.1 - - [09/Apr/2019 15:53:43] \"GET / HTTP/1.1\" 200 -\n",
      "127.0.0.1 - - [09/Apr/2019 15:53:43] \"GET /styles.css HTTP/1.1\" 200 -\n",
      "127.0.0.1 - - [09/Apr/2019 15:53:43] \"GET /_dash-layout HTTP/1.1\" 200 -\n",
      "127.0.0.1 - - [09/Apr/2019 15:53:43] \"GET /_dash-dependencies HTTP/1.1\" 200 -\n",
      "127.0.0.1 - - [09/Apr/2019 15:53:43] \"POST /_dash-update-component HTTP/1.1\" 200 -\n",
      "127.0.0.1 - - [09/Apr/2019 15:53:53] \"POST /_dash-update-component HTTP/1.1\" 200 -\n",
      "127.0.0.1 - - [09/Apr/2019 15:53:54] \"POST /_dash-update-component HTTP/1.1\" 200 -\n",
      "127.0.0.1 - - [09/Apr/2019 15:53:55] \"POST /_dash-update-component HTTP/1.1\" 200 -\n",
      "127.0.0.1 - - [09/Apr/2019 15:53:55] \"POST /_dash-update-component HTTP/1.1\" 200 -\n",
      "127.0.0.1 - - [09/Apr/2019 15:53:55] \"POST /_dash-update-component HTTP/1.1\" 200 -\n",
      "127.0.0.1 - - [09/Apr/2019 15:53:55] \"POST /_dash-update-component HTTP/1.1\" 200 -\n",
      "127.0.0.1 - - [09/Apr/2019 15:53:55] \"POST /_dash-update-component HTTP/1.1\" 200 -\n",
      "127.0.0.1 - - [09/Apr/2019 15:53:56] \"POST /_dash-update-component HTTP/1.1\" 200 -\n",
      "[2019-04-09 15:54:21,128] ERROR in app: Exception on /_dash-update-component [POST]\n",
      "Traceback (most recent call last):\n",
      "  File \"/home/janeadams/.conda/envs/test_env/lib/python3.7/site-packages/pandas/core/indexes/base.py\", line 2656, in get_loc\n",
      "    return self._engine.get_loc(key)\n",
      "  File \"pandas/_libs/index.pyx\", line 108, in pandas._libs.index.IndexEngine.get_loc\n",
      "  File \"pandas/_libs/index.pyx\", line 132, in pandas._libs.index.IndexEngine.get_loc\n",
      "  File \"pandas/_libs/hashtable_class_helper.pxi\", line 1601, in pandas._libs.hashtable.PyObjectHashTable.get_item\n",
      "  File \"pandas/_libs/hashtable_class_helper.pxi\", line 1608, in pandas._libs.hashtable.PyObjectHashTable.get_item\n",
      "KeyError: 'time'\n",
      "\n",
      "During handling of the above exception, another exception occurred:\n",
      "\n",
      "Traceback (most recent call last):\n",
      "  File \"/home/janeadams/.conda/envs/test_env/lib/python3.7/site-packages/flask/app.py\", line 2292, in wsgi_app\n",
      "    response = self.full_dispatch_request()\n",
      "  File \"/home/janeadams/.conda/envs/test_env/lib/python3.7/site-packages/flask/app.py\", line 1815, in full_dispatch_request\n",
      "    rv = self.handle_user_exception(e)\n",
      "  File \"/home/janeadams/.conda/envs/test_env/lib/python3.7/site-packages/flask/app.py\", line 1718, in handle_user_exception\n",
      "    reraise(exc_type, exc_value, tb)\n",
      "  File \"/home/janeadams/.conda/envs/test_env/lib/python3.7/site-packages/flask/_compat.py\", line 35, in reraise\n",
      "    raise value\n",
      "  File \"/home/janeadams/.conda/envs/test_env/lib/python3.7/site-packages/flask/app.py\", line 1813, in full_dispatch_request\n",
      "    rv = self.dispatch_request()\n",
      "  File \"/home/janeadams/.conda/envs/test_env/lib/python3.7/site-packages/flask/app.py\", line 1799, in dispatch_request\n",
      "    return self.view_functions[rule.endpoint](**req.view_args)\n",
      "  File \"/home/janeadams/.conda/envs/test_env/lib/python3.7/site-packages/dash/dash.py\", line 960, in dispatch\n",
      "    return self.callback_map[target_id]['callback'](*args)\n",
      "  File \"/home/janeadams/.conda/envs/test_env/lib/python3.7/site-packages/dash/dash.py\", line 900, in add_context\n",
      "    output_value = func(*args, **kwargs)\n",
      "  File \"<ipython-input-8-fb09f0c12743>\", line 20, in update_graph\n",
      "    data.append({'x':df['time'], 'y':df['counts'],'name':item})\n",
      "  File \"/home/janeadams/.conda/envs/test_env/lib/python3.7/site-packages/pandas/core/frame.py\", line 2927, in __getitem__\n",
      "    indexer = self.columns.get_loc(key)\n",
      "  File \"/home/janeadams/.conda/envs/test_env/lib/python3.7/site-packages/pandas/core/indexes/base.py\", line 2658, in get_loc\n",
      "    return self._engine.get_loc(self._maybe_cast_indexer(key))\n",
      "  File \"pandas/_libs/index.pyx\", line 108, in pandas._libs.index.IndexEngine.get_loc\n",
      "  File \"pandas/_libs/index.pyx\", line 132, in pandas._libs.index.IndexEngine.get_loc\n",
      "  File \"pandas/_libs/hashtable_class_helper.pxi\", line 1601, in pandas._libs.hashtable.PyObjectHashTable.get_item\n",
      "  File \"pandas/_libs/hashtable_class_helper.pxi\", line 1608, in pandas._libs.hashtable.PyObjectHashTable.get_item\n",
      "KeyError: 'time'\n",
      "127.0.0.1 - - [09/Apr/2019 15:54:21] \"POST /_dash-update-component HTTP/1.1\" 500 -\n"
     ]
    },
    {
     "name": "stdout",
     "output_type": "stream",
     "text": [
      "No timeseries found for \n"
     ]
    },
    {
     "name": "stderr",
     "output_type": "stream",
     "text": [
      "127.0.0.1 - - [09/Apr/2019 15:54:23] \"POST /_dash-update-component HTTP/1.1\" 200 -\n",
      "127.0.0.1 - - [09/Apr/2019 15:54:24] \"POST /_dash-update-component HTTP/1.1\" 200 -\n",
      "127.0.0.1 - - [09/Apr/2019 15:54:24] \"POST /_dash-update-component HTTP/1.1\" 200 -\n",
      "[2019-04-09 15:54:24,347] ERROR in app: Exception on /_dash-update-component [POST]\n",
      "Traceback (most recent call last):\n",
      "  File \"/home/janeadams/.conda/envs/test_env/lib/python3.7/site-packages/pandas/core/indexes/base.py\", line 2656, in get_loc\n",
      "    return self._engine.get_loc(key)\n",
      "  File \"pandas/_libs/index.pyx\", line 108, in pandas._libs.index.IndexEngine.get_loc\n",
      "  File \"pandas/_libs/index.pyx\", line 132, in pandas._libs.index.IndexEngine.get_loc\n",
      "  File \"pandas/_libs/hashtable_class_helper.pxi\", line 1601, in pandas._libs.hashtable.PyObjectHashTable.get_item\n",
      "  File \"pandas/_libs/hashtable_class_helper.pxi\", line 1608, in pandas._libs.hashtable.PyObjectHashTable.get_item\n",
      "KeyError: 'time'\n",
      "\n",
      "During handling of the above exception, another exception occurred:\n",
      "\n",
      "Traceback (most recent call last):\n",
      "  File \"/home/janeadams/.conda/envs/test_env/lib/python3.7/site-packages/flask/app.py\", line 2292, in wsgi_app\n",
      "    response = self.full_dispatch_request()\n",
      "  File \"/home/janeadams/.conda/envs/test_env/lib/python3.7/site-packages/flask/app.py\", line 1815, in full_dispatch_request\n",
      "    rv = self.handle_user_exception(e)\n",
      "  File \"/home/janeadams/.conda/envs/test_env/lib/python3.7/site-packages/flask/app.py\", line 1718, in handle_user_exception\n",
      "    reraise(exc_type, exc_value, tb)\n",
      "  File \"/home/janeadams/.conda/envs/test_env/lib/python3.7/site-packages/flask/_compat.py\", line 35, in reraise\n",
      "    raise value\n",
      "  File \"/home/janeadams/.conda/envs/test_env/lib/python3.7/site-packages/flask/app.py\", line 1813, in full_dispatch_request\n",
      "    rv = self.dispatch_request()\n",
      "  File \"/home/janeadams/.conda/envs/test_env/lib/python3.7/site-packages/flask/app.py\", line 1799, in dispatch_request\n",
      "    return self.view_functions[rule.endpoint](**req.view_args)\n",
      "  File \"/home/janeadams/.conda/envs/test_env/lib/python3.7/site-packages/dash/dash.py\", line 960, in dispatch\n",
      "    return self.callback_map[target_id]['callback'](*args)\n",
      "  File \"/home/janeadams/.conda/envs/test_env/lib/python3.7/site-packages/dash/dash.py\", line 900, in add_context\n",
      "    output_value = func(*args, **kwargs)\n",
      "  File \"<ipython-input-8-fb09f0c12743>\", line 20, in update_graph\n",
      "    data.append({'x':df['time'], 'y':df['counts'],'name':item})\n",
      "  File \"/home/janeadams/.conda/envs/test_env/lib/python3.7/site-packages/pandas/core/frame.py\", line 2927, in __getitem__\n",
      "    indexer = self.columns.get_loc(key)\n",
      "  File \"/home/janeadams/.conda/envs/test_env/lib/python3.7/site-packages/pandas/core/indexes/base.py\", line 2658, in get_loc\n",
      "    return self._engine.get_loc(self._maybe_cast_indexer(key))\n",
      "  File \"pandas/_libs/index.pyx\", line 108, in pandas._libs.index.IndexEngine.get_loc\n",
      "  File \"pandas/_libs/index.pyx\", line 132, in pandas._libs.index.IndexEngine.get_loc\n",
      "  File \"pandas/_libs/hashtable_class_helper.pxi\", line 1601, in pandas._libs.hashtable.PyObjectHashTable.get_item\n",
      "  File \"pandas/_libs/hashtable_class_helper.pxi\", line 1608, in pandas._libs.hashtable.PyObjectHashTable.get_item\n",
      "KeyError: 'time'\n",
      "127.0.0.1 - - [09/Apr/2019 15:54:24] \"POST /_dash-update-component HTTP/1.1\" 500 -\n"
     ]
    },
    {
     "name": "stdout",
     "output_type": "stream",
     "text": [
      "No timeseries found for \n"
     ]
    },
    {
     "name": "stderr",
     "output_type": "stream",
     "text": [
      "127.0.0.1 - - [09/Apr/2019 15:54:24] \"POST /_dash-update-component HTTP/1.1\" 200 -\n",
      "127.0.0.1 - - [09/Apr/2019 15:54:24] \"POST /_dash-update-component HTTP/1.1\" 200 -\n",
      "127.0.0.1 - - [09/Apr/2019 15:54:25] \"POST /_dash-update-component HTTP/1.1\" 200 -\n",
      "127.0.0.1 - - [09/Apr/2019 15:55:54] \"POST /_dash-update-component HTTP/1.1\" 200 -\n",
      "127.0.0.1 - - [09/Apr/2019 15:55:55] \"POST /_dash-update-component HTTP/1.1\" 200 -\n",
      "127.0.0.1 - - [09/Apr/2019 15:55:56] \"POST /_dash-update-component HTTP/1.1\" 200 -\n",
      "127.0.0.1 - - [09/Apr/2019 15:55:56] \"POST /_dash-update-component HTTP/1.1\" 200 -\n",
      "127.0.0.1 - - [09/Apr/2019 15:55:57] \"POST /_dash-update-component HTTP/1.1\" 200 -\n",
      "127.0.0.1 - - [09/Apr/2019 15:55:57] \"POST /_dash-update-component HTTP/1.1\" 200 -\n",
      "127.0.0.1 - - [09/Apr/2019 15:55:57] \"POST /_dash-update-component HTTP/1.1\" 200 -\n",
      "127.0.0.1 - - [09/Apr/2019 15:55:58] \"POST /_dash-update-component HTTP/1.1\" 200 -\n",
      "127.0.0.1 - - [09/Apr/2019 15:55:58] \"POST /_dash-update-component HTTP/1.1\" 200 -\n",
      "127.0.0.1 - - [09/Apr/2019 15:55:58] \"POST /_dash-update-component HTTP/1.1\" 200 -\n",
      "127.0.0.1 - - [09/Apr/2019 15:56:00] \"POST /_dash-update-component HTTP/1.1\" 200 -\n",
      "127.0.0.1 - - [09/Apr/2019 15:56:00] \"POST /_dash-update-component HTTP/1.1\" 200 -\n",
      "127.0.0.1 - - [09/Apr/2019 15:56:00] \"POST /_dash-update-component HTTP/1.1\" 200 -\n",
      "127.0.0.1 - - [09/Apr/2019 15:56:00] \"POST /_dash-update-component HTTP/1.1\" 200 -\n",
      "127.0.0.1 - - [09/Apr/2019 15:56:00] \"POST /_dash-update-component HTTP/1.1\" 200 -\n",
      "127.0.0.1 - - [09/Apr/2019 15:56:00] \"POST /_dash-update-component HTTP/1.1\" 200 -\n",
      "127.0.0.1 - - [09/Apr/2019 15:56:21] \"POST /_dash-update-component HTTP/1.1\" 200 -\n",
      "127.0.0.1 - - [09/Apr/2019 15:56:22] \"POST /_dash-update-component HTTP/1.1\" 200 -\n",
      "127.0.0.1 - - [09/Apr/2019 15:56:22] \"POST /_dash-update-component HTTP/1.1\" 200 -\n",
      "127.0.0.1 - - [09/Apr/2019 15:56:22] \"POST /_dash-update-component HTTP/1.1\" 200 -\n",
      "127.0.0.1 - - [09/Apr/2019 15:56:23] \"POST /_dash-update-component HTTP/1.1\" 200 -\n",
      "127.0.0.1 - - [09/Apr/2019 15:56:24] \"POST /_dash-update-component HTTP/1.1\" 200 -\n",
      "127.0.0.1 - - [09/Apr/2019 15:56:25] \"POST /_dash-update-component HTTP/1.1\" 200 -\n",
      "127.0.0.1 - - [09/Apr/2019 15:56:25] \"POST /_dash-update-component HTTP/1.1\" 200 -\n",
      "127.0.0.1 - - [09/Apr/2019 15:57:40] \"POST /_dash-update-component HTTP/1.1\" 200 -\n",
      "127.0.0.1 - - [09/Apr/2019 15:57:40] \"POST /_dash-update-component HTTP/1.1\" 200 -\n",
      "127.0.0.1 - - [09/Apr/2019 15:57:41] \"POST /_dash-update-component HTTP/1.1\" 200 -\n",
      "[2019-04-09 15:57:41,049] ERROR in app: Exception on /_dash-update-component [POST]\n",
      "Traceback (most recent call last):\n",
      "  File \"/home/janeadams/.conda/envs/test_env/lib/python3.7/site-packages/pandas/core/indexes/base.py\", line 2656, in get_loc\n",
      "    return self._engine.get_loc(key)\n",
      "  File \"pandas/_libs/index.pyx\", line 108, in pandas._libs.index.IndexEngine.get_loc\n",
      "  File \"pandas/_libs/index.pyx\", line 132, in pandas._libs.index.IndexEngine.get_loc\n",
      "  File \"pandas/_libs/hashtable_class_helper.pxi\", line 1601, in pandas._libs.hashtable.PyObjectHashTable.get_item\n",
      "  File \"pandas/_libs/hashtable_class_helper.pxi\", line 1608, in pandas._libs.hashtable.PyObjectHashTable.get_item\n",
      "KeyError: 'time'\n",
      "\n",
      "During handling of the above exception, another exception occurred:\n",
      "\n",
      "Traceback (most recent call last):\n",
      "  File \"/home/janeadams/.conda/envs/test_env/lib/python3.7/site-packages/flask/app.py\", line 2292, in wsgi_app\n",
      "    response = self.full_dispatch_request()\n",
      "  File \"/home/janeadams/.conda/envs/test_env/lib/python3.7/site-packages/flask/app.py\", line 1815, in full_dispatch_request\n",
      "    rv = self.handle_user_exception(e)\n",
      "  File \"/home/janeadams/.conda/envs/test_env/lib/python3.7/site-packages/flask/app.py\", line 1718, in handle_user_exception\n",
      "    reraise(exc_type, exc_value, tb)\n",
      "  File \"/home/janeadams/.conda/envs/test_env/lib/python3.7/site-packages/flask/_compat.py\", line 35, in reraise\n",
      "    raise value\n",
      "  File \"/home/janeadams/.conda/envs/test_env/lib/python3.7/site-packages/flask/app.py\", line 1813, in full_dispatch_request\n",
      "    rv = self.dispatch_request()\n",
      "  File \"/home/janeadams/.conda/envs/test_env/lib/python3.7/site-packages/flask/app.py\", line 1799, in dispatch_request\n",
      "    return self.view_functions[rule.endpoint](**req.view_args)\n",
      "  File \"/home/janeadams/.conda/envs/test_env/lib/python3.7/site-packages/dash/dash.py\", line 960, in dispatch\n",
      "    return self.callback_map[target_id]['callback'](*args)\n",
      "  File \"/home/janeadams/.conda/envs/test_env/lib/python3.7/site-packages/dash/dash.py\", line 900, in add_context\n",
      "    output_value = func(*args, **kwargs)\n",
      "  File \"<ipython-input-8-fb09f0c12743>\", line 20, in update_graph\n",
      "    data.append({'x':df['time'], 'y':df['counts'],'name':item})\n",
      "  File \"/home/janeadams/.conda/envs/test_env/lib/python3.7/site-packages/pandas/core/frame.py\", line 2927, in __getitem__\n",
      "    indexer = self.columns.get_loc(key)\n",
      "  File \"/home/janeadams/.conda/envs/test_env/lib/python3.7/site-packages/pandas/core/indexes/base.py\", line 2658, in get_loc\n",
      "    return self._engine.get_loc(self._maybe_cast_indexer(key))\n",
      "  File \"pandas/_libs/index.pyx\", line 108, in pandas._libs.index.IndexEngine.get_loc\n",
      "  File \"pandas/_libs/index.pyx\", line 132, in pandas._libs.index.IndexEngine.get_loc\n",
      "  File \"pandas/_libs/hashtable_class_helper.pxi\", line 1601, in pandas._libs.hashtable.PyObjectHashTable.get_item\n",
      "  File \"pandas/_libs/hashtable_class_helper.pxi\", line 1608, in pandas._libs.hashtable.PyObjectHashTable.get_item\n",
      "KeyError: 'time'\n",
      "127.0.0.1 - - [09/Apr/2019 15:57:41] \"POST /_dash-update-component HTTP/1.1\" 500 -\n",
      "127.0.0.1 - - [09/Apr/2019 15:57:41] \"POST /_dash-update-component HTTP/1.1\" 200 -\n"
     ]
    },
    {
     "name": "stdout",
     "output_type": "stream",
     "text": [
      "No timeseries found for covfer\n"
     ]
    },
    {
     "name": "stderr",
     "output_type": "stream",
     "text": [
      "127.0.0.1 - - [09/Apr/2019 15:57:41] \"POST /_dash-update-component HTTP/1.1\" 200 -\n",
      "127.0.0.1 - - [09/Apr/2019 15:57:41] \"POST /_dash-update-component HTTP/1.1\" 200 -\n",
      "127.0.0.1 - - [09/Apr/2019 15:57:42] \"POST /_dash-update-component HTTP/1.1\" 200 -\n",
      "127.0.0.1 - - [09/Apr/2019 15:57:42] \"POST /_dash-update-component HTTP/1.1\" 200 -\n",
      "[2019-04-09 15:57:44,303] ERROR in app: Exception on /_dash-update-component [POST]\n",
      "Traceback (most recent call last):\n",
      "  File \"/home/janeadams/.conda/envs/test_env/lib/python3.7/site-packages/pandas/core/indexes/base.py\", line 2656, in get_loc\n",
      "    return self._engine.get_loc(key)\n",
      "  File \"pandas/_libs/index.pyx\", line 108, in pandas._libs.index.IndexEngine.get_loc\n",
      "  File \"pandas/_libs/index.pyx\", line 132, in pandas._libs.index.IndexEngine.get_loc\n",
      "  File \"pandas/_libs/hashtable_class_helper.pxi\", line 1601, in pandas._libs.hashtable.PyObjectHashTable.get_item\n",
      "  File \"pandas/_libs/hashtable_class_helper.pxi\", line 1608, in pandas._libs.hashtable.PyObjectHashTable.get_item\n",
      "KeyError: 'time'\n",
      "\n",
      "During handling of the above exception, another exception occurred:\n",
      "\n",
      "Traceback (most recent call last):\n",
      "  File \"/home/janeadams/.conda/envs/test_env/lib/python3.7/site-packages/flask/app.py\", line 2292, in wsgi_app\n",
      "    response = self.full_dispatch_request()\n",
      "  File \"/home/janeadams/.conda/envs/test_env/lib/python3.7/site-packages/flask/app.py\", line 1815, in full_dispatch_request\n",
      "    rv = self.handle_user_exception(e)\n",
      "  File \"/home/janeadams/.conda/envs/test_env/lib/python3.7/site-packages/flask/app.py\", line 1718, in handle_user_exception\n",
      "    reraise(exc_type, exc_value, tb)\n",
      "  File \"/home/janeadams/.conda/envs/test_env/lib/python3.7/site-packages/flask/_compat.py\", line 35, in reraise\n",
      "    raise value\n",
      "  File \"/home/janeadams/.conda/envs/test_env/lib/python3.7/site-packages/flask/app.py\", line 1813, in full_dispatch_request\n",
      "    rv = self.dispatch_request()\n",
      "  File \"/home/janeadams/.conda/envs/test_env/lib/python3.7/site-packages/flask/app.py\", line 1799, in dispatch_request\n",
      "    return self.view_functions[rule.endpoint](**req.view_args)\n",
      "  File \"/home/janeadams/.conda/envs/test_env/lib/python3.7/site-packages/dash/dash.py\", line 960, in dispatch\n",
      "    return self.callback_map[target_id]['callback'](*args)\n",
      "  File \"/home/janeadams/.conda/envs/test_env/lib/python3.7/site-packages/dash/dash.py\", line 900, in add_context\n",
      "    output_value = func(*args, **kwargs)\n",
      "  File \"<ipython-input-8-fb09f0c12743>\", line 20, in update_graph\n",
      "    data.append({'x':df['time'], 'y':df['counts'],'name':item})\n",
      "  File \"/home/janeadams/.conda/envs/test_env/lib/python3.7/site-packages/pandas/core/frame.py\", line 2927, in __getitem__\n",
      "    indexer = self.columns.get_loc(key)\n",
      "  File \"/home/janeadams/.conda/envs/test_env/lib/python3.7/site-packages/pandas/core/indexes/base.py\", line 2658, in get_loc\n",
      "    return self._engine.get_loc(self._maybe_cast_indexer(key))\n",
      "  File \"pandas/_libs/index.pyx\", line 108, in pandas._libs.index.IndexEngine.get_loc\n",
      "  File \"pandas/_libs/index.pyx\", line 132, in pandas._libs.index.IndexEngine.get_loc\n",
      "  File \"pandas/_libs/hashtable_class_helper.pxi\", line 1601, in pandas._libs.hashtable.PyObjectHashTable.get_item\n",
      "  File \"pandas/_libs/hashtable_class_helper.pxi\", line 1608, in pandas._libs.hashtable.PyObjectHashTable.get_item\n",
      "KeyError: 'time'\n",
      "127.0.0.1 - - [09/Apr/2019 15:57:44] \"POST /_dash-update-component HTTP/1.1\" 500 -\n"
     ]
    },
    {
     "name": "stdout",
     "output_type": "stream",
     "text": [
      "No timeseries found for \n"
     ]
    },
    {
     "name": "stderr",
     "output_type": "stream",
     "text": [
      "127.0.0.1 - - [09/Apr/2019 15:57:45] \"POST /_dash-update-component HTTP/1.1\" 200 -\n",
      "127.0.0.1 - - [09/Apr/2019 15:57:46] \"POST /_dash-update-component HTTP/1.1\" 200 -\n",
      "127.0.0.1 - - [09/Apr/2019 15:57:46] \"POST /_dash-update-component HTTP/1.1\" 200 -\n",
      "127.0.0.1 - - [09/Apr/2019 15:57:46] \"POST /_dash-update-component HTTP/1.1\" 200 -\n",
      "127.0.0.1 - - [09/Apr/2019 15:57:46] \"POST /_dash-update-component HTTP/1.1\" 200 -\n",
      "127.0.0.1 - - [09/Apr/2019 15:57:46] \"POST /_dash-update-component HTTP/1.1\" 200 -\n",
      "127.0.0.1 - - [09/Apr/2019 15:57:46] \"POST /_dash-update-component HTTP/1.1\" 200 -\n",
      "127.0.0.1 - - [09/Apr/2019 15:57:46] \"POST /_dash-update-component HTTP/1.1\" 200 -\n",
      "127.0.0.1 - - [09/Apr/2019 15:57:47] \"POST /_dash-update-component HTTP/1.1\" 200 -\n",
      "127.0.0.1 - - [09/Apr/2019 15:58:19] \"POST /_dash-update-component HTTP/1.1\" 200 -\n",
      "127.0.0.1 - - [09/Apr/2019 15:59:05] \"POST /_dash-update-component HTTP/1.1\" 200 -\n",
      "127.0.0.1 - - [09/Apr/2019 15:59:05] \"POST /_dash-update-component HTTP/1.1\" 200 -\n",
      "127.0.0.1 - - [09/Apr/2019 15:59:05] \"POST /_dash-update-component HTTP/1.1\" 200 -\n",
      "127.0.0.1 - - [09/Apr/2019 15:59:06] \"POST /_dash-update-component HTTP/1.1\" 200 -\n",
      "127.0.0.1 - - [09/Apr/2019 15:59:06] \"POST /_dash-update-component HTTP/1.1\" 200 -\n",
      "127.0.0.1 - - [09/Apr/2019 15:59:07] \"POST /_dash-update-component HTTP/1.1\" 200 -\n",
      "127.0.0.1 - - [09/Apr/2019 15:59:07] \"POST /_dash-update-component HTTP/1.1\" 200 -\n",
      "127.0.0.1 - - [09/Apr/2019 15:59:08] \"POST /_dash-update-component HTTP/1.1\" 200 -\n",
      "127.0.0.1 - - [09/Apr/2019 15:59:08] \"POST /_dash-update-component HTTP/1.1\" 200 -\n",
      "127.0.0.1 - - [09/Apr/2019 15:59:08] \"POST /_dash-update-component HTTP/1.1\" 200 -\n",
      "[2019-04-09 15:59:10,806] ERROR in app: Exception on /_dash-update-component [POST]\n",
      "Traceback (most recent call last):\n",
      "  File \"/home/janeadams/.conda/envs/test_env/lib/python3.7/site-packages/pandas/core/indexes/base.py\", line 2656, in get_loc\n",
      "    return self._engine.get_loc(key)\n",
      "  File \"pandas/_libs/index.pyx\", line 108, in pandas._libs.index.IndexEngine.get_loc\n",
      "  File \"pandas/_libs/index.pyx\", line 132, in pandas._libs.index.IndexEngine.get_loc\n",
      "  File \"pandas/_libs/hashtable_class_helper.pxi\", line 1601, in pandas._libs.hashtable.PyObjectHashTable.get_item\n",
      "  File \"pandas/_libs/hashtable_class_helper.pxi\", line 1608, in pandas._libs.hashtable.PyObjectHashTable.get_item\n",
      "KeyError: 'time'\n",
      "\n",
      "During handling of the above exception, another exception occurred:\n",
      "\n",
      "Traceback (most recent call last):\n",
      "  File \"/home/janeadams/.conda/envs/test_env/lib/python3.7/site-packages/flask/app.py\", line 2292, in wsgi_app\n",
      "    response = self.full_dispatch_request()\n",
      "  File \"/home/janeadams/.conda/envs/test_env/lib/python3.7/site-packages/flask/app.py\", line 1815, in full_dispatch_request\n",
      "    rv = self.handle_user_exception(e)\n",
      "  File \"/home/janeadams/.conda/envs/test_env/lib/python3.7/site-packages/flask/app.py\", line 1718, in handle_user_exception\n",
      "    reraise(exc_type, exc_value, tb)\n",
      "  File \"/home/janeadams/.conda/envs/test_env/lib/python3.7/site-packages/flask/_compat.py\", line 35, in reraise\n",
      "    raise value\n",
      "  File \"/home/janeadams/.conda/envs/test_env/lib/python3.7/site-packages/flask/app.py\", line 1813, in full_dispatch_request\n",
      "    rv = self.dispatch_request()\n",
      "  File \"/home/janeadams/.conda/envs/test_env/lib/python3.7/site-packages/flask/app.py\", line 1799, in dispatch_request\n",
      "    return self.view_functions[rule.endpoint](**req.view_args)\n",
      "  File \"/home/janeadams/.conda/envs/test_env/lib/python3.7/site-packages/dash/dash.py\", line 960, in dispatch\n",
      "    return self.callback_map[target_id]['callback'](*args)\n",
      "  File \"/home/janeadams/.conda/envs/test_env/lib/python3.7/site-packages/dash/dash.py\", line 900, in add_context\n",
      "    output_value = func(*args, **kwargs)\n",
      "  File \"<ipython-input-8-fb09f0c12743>\", line 20, in update_graph\n",
      "    data.append({'x':df['time'], 'y':df['counts'],'name':item})\n",
      "  File \"/home/janeadams/.conda/envs/test_env/lib/python3.7/site-packages/pandas/core/frame.py\", line 2927, in __getitem__\n",
      "    indexer = self.columns.get_loc(key)\n",
      "  File \"/home/janeadams/.conda/envs/test_env/lib/python3.7/site-packages/pandas/core/indexes/base.py\", line 2658, in get_loc\n",
      "    return self._engine.get_loc(self._maybe_cast_indexer(key))\n",
      "  File \"pandas/_libs/index.pyx\", line 108, in pandas._libs.index.IndexEngine.get_loc\n",
      "  File \"pandas/_libs/index.pyx\", line 132, in pandas._libs.index.IndexEngine.get_loc\n",
      "  File \"pandas/_libs/hashtable_class_helper.pxi\", line 1601, in pandas._libs.hashtable.PyObjectHashTable.get_item\n",
      "  File \"pandas/_libs/hashtable_class_helper.pxi\", line 1608, in pandas._libs.hashtable.PyObjectHashTable.get_item\n",
      "KeyError: 'time'\n",
      "127.0.0.1 - - [09/Apr/2019 15:59:10] \"POST /_dash-update-component HTTP/1.1\" 500 -\n"
     ]
    },
    {
     "name": "stdout",
     "output_type": "stream",
     "text": [
      "No timeseries found for \n"
     ]
    },
    {
     "name": "stderr",
     "output_type": "stream",
     "text": [
      "127.0.0.1 - - [09/Apr/2019 15:59:13] \"POST /_dash-update-component HTTP/1.1\" 200 -\n",
      "127.0.0.1 - - [09/Apr/2019 15:59:14] \"POST /_dash-update-component HTTP/1.1\" 200 -\n",
      "127.0.0.1 - - [09/Apr/2019 15:59:15] \"POST /_dash-update-component HTTP/1.1\" 200 -\n",
      "127.0.0.1 - - [09/Apr/2019 15:59:15] \"POST /_dash-update-component HTTP/1.1\" 200 -\n",
      "127.0.0.1 - - [09/Apr/2019 15:59:15] \"POST /_dash-update-component HTTP/1.1\" 200 -\n",
      "127.0.0.1 - - [09/Apr/2019 15:59:16] \"POST /_dash-update-component HTTP/1.1\" 200 -\n",
      "127.0.0.1 - - [09/Apr/2019 15:59:16] \"POST /_dash-update-component HTTP/1.1\" 200 -\n",
      "127.0.0.1 - - [09/Apr/2019 15:59:17] \"POST /_dash-update-component HTTP/1.1\" 200 -\n",
      "127.0.0.1 - - [09/Apr/2019 15:59:17] \"POST /_dash-update-component HTTP/1.1\" 200 -\n",
      "127.0.0.1 - - [09/Apr/2019 15:59:18] \"POST /_dash-update-component HTTP/1.1\" 200 -\n",
      "127.0.0.1 - - [09/Apr/2019 15:59:18] \"POST /_dash-update-component HTTP/1.1\" 200 -\n",
      "127.0.0.1 - - [09/Apr/2019 15:59:18] \"POST /_dash-update-component HTTP/1.1\" 200 -\n",
      "127.0.0.1 - - [09/Apr/2019 15:59:19] \"POST /_dash-update-component HTTP/1.1\" 200 -\n",
      "127.0.0.1 - - [09/Apr/2019 15:59:22] \"POST /_dash-update-component HTTP/1.1\" 200 -\n",
      "[2019-04-09 15:59:22,458] ERROR in app: Exception on /_dash-update-component [POST]\n",
      "Traceback (most recent call last):\n",
      "  File \"/home/janeadams/.conda/envs/test_env/lib/python3.7/site-packages/pandas/core/indexes/base.py\", line 2656, in get_loc\n",
      "    return self._engine.get_loc(key)\n",
      "  File \"pandas/_libs/index.pyx\", line 108, in pandas._libs.index.IndexEngine.get_loc\n",
      "  File \"pandas/_libs/index.pyx\", line 132, in pandas._libs.index.IndexEngine.get_loc\n",
      "  File \"pandas/_libs/hashtable_class_helper.pxi\", line 1601, in pandas._libs.hashtable.PyObjectHashTable.get_item\n",
      "  File \"pandas/_libs/hashtable_class_helper.pxi\", line 1608, in pandas._libs.hashtable.PyObjectHashTable.get_item\n",
      "KeyError: 'time'\n",
      "\n",
      "During handling of the above exception, another exception occurred:\n",
      "\n",
      "Traceback (most recent call last):\n",
      "  File \"/home/janeadams/.conda/envs/test_env/lib/python3.7/site-packages/flask/app.py\", line 2292, in wsgi_app\n",
      "    response = self.full_dispatch_request()\n",
      "  File \"/home/janeadams/.conda/envs/test_env/lib/python3.7/site-packages/flask/app.py\", line 1815, in full_dispatch_request\n",
      "    rv = self.handle_user_exception(e)\n",
      "  File \"/home/janeadams/.conda/envs/test_env/lib/python3.7/site-packages/flask/app.py\", line 1718, in handle_user_exception\n",
      "    reraise(exc_type, exc_value, tb)\n",
      "  File \"/home/janeadams/.conda/envs/test_env/lib/python3.7/site-packages/flask/_compat.py\", line 35, in reraise\n",
      "    raise value\n",
      "  File \"/home/janeadams/.conda/envs/test_env/lib/python3.7/site-packages/flask/app.py\", line 1813, in full_dispatch_request\n",
      "    rv = self.dispatch_request()\n",
      "  File \"/home/janeadams/.conda/envs/test_env/lib/python3.7/site-packages/flask/app.py\", line 1799, in dispatch_request\n",
      "    return self.view_functions[rule.endpoint](**req.view_args)\n",
      "  File \"/home/janeadams/.conda/envs/test_env/lib/python3.7/site-packages/dash/dash.py\", line 960, in dispatch\n",
      "    return self.callback_map[target_id]['callback'](*args)\n",
      "  File \"/home/janeadams/.conda/envs/test_env/lib/python3.7/site-packages/dash/dash.py\", line 900, in add_context\n",
      "    output_value = func(*args, **kwargs)\n",
      "  File \"<ipython-input-8-fb09f0c12743>\", line 20, in update_graph\n",
      "    data.append({'x':df['time'], 'y':df['counts'],'name':item})\n",
      "  File \"/home/janeadams/.conda/envs/test_env/lib/python3.7/site-packages/pandas/core/frame.py\", line 2927, in __getitem__\n",
      "    indexer = self.columns.get_loc(key)\n",
      "  File \"/home/janeadams/.conda/envs/test_env/lib/python3.7/site-packages/pandas/core/indexes/base.py\", line 2658, in get_loc\n",
      "    return self._engine.get_loc(self._maybe_cast_indexer(key))\n",
      "  File \"pandas/_libs/index.pyx\", line 108, in pandas._libs.index.IndexEngine.get_loc\n",
      "  File \"pandas/_libs/index.pyx\", line 132, in pandas._libs.index.IndexEngine.get_loc\n",
      "  File \"pandas/_libs/hashtable_class_helper.pxi\", line 1601, in pandas._libs.hashtable.PyObjectHashTable.get_item\n",
      "  File \"pandas/_libs/hashtable_class_helper.pxi\", line 1608, in pandas._libs.hashtable.PyObjectHashTable.get_item\n",
      "KeyError: 'time'\n",
      "127.0.0.1 - - [09/Apr/2019 15:59:22] \"POST /_dash-update-component HTTP/1.1\" 500 -\n"
     ]
    },
    {
     "name": "stdout",
     "output_type": "stream",
     "text": [
      "No timeseries found for #gunon\n"
     ]
    },
    {
     "name": "stderr",
     "output_type": "stream",
     "text": [
      "127.0.0.1 - - [09/Apr/2019 15:59:23] \"POST /_dash-update-component HTTP/1.1\" 200 -\n",
      "127.0.0.1 - - [09/Apr/2019 15:59:23] \"POST /_dash-update-component HTTP/1.1\" 200 -\n",
      "127.0.0.1 - - [09/Apr/2019 15:59:24] \"POST /_dash-update-component HTTP/1.1\" 200 -\n",
      "127.0.0.1 - - [09/Apr/2019 15:59:25] \"POST /_dash-update-component HTTP/1.1\" 200 -\n",
      "127.0.0.1 - - [09/Apr/2019 15:59:26] \"POST /_dash-update-component HTTP/1.1\" 200 -\n",
      "127.0.0.1 - - [09/Apr/2019 15:59:27] \"POST /_dash-update-component HTTP/1.1\" 200 -\n",
      "127.0.0.1 - - [09/Apr/2019 15:59:27] \"POST /_dash-update-component HTTP/1.1\" 200 -\n",
      "127.0.0.1 - - [09/Apr/2019 15:59:27] \"POST /_dash-update-component HTTP/1.1\" 200 -\n",
      "127.0.0.1 - - [09/Apr/2019 15:59:27] \"POST /_dash-update-component HTTP/1.1\" 200 -\n",
      "127.0.0.1 - - [09/Apr/2019 15:59:27] \"POST /_dash-update-component HTTP/1.1\" 200 -\n",
      "127.0.0.1 - - [09/Apr/2019 15:59:27] \"POST /_dash-update-component HTTP/1.1\" 200 -\n",
      "127.0.0.1 - - [09/Apr/2019 15:59:28] \"POST /_dash-update-component HTTP/1.1\" 200 -\n",
      "127.0.0.1 - - [09/Apr/2019 15:59:29] \"POST /_dash-update-component HTTP/1.1\" 200 -\n",
      "[2019-04-09 16:04:11,680] ERROR in app: Exception on /_dash-update-component [POST]\n",
      "Traceback (most recent call last):\n",
      "  File \"/home/janeadams/.conda/envs/test_env/lib/python3.7/site-packages/pandas/core/indexes/base.py\", line 2656, in get_loc\n",
      "    return self._engine.get_loc(key)\n",
      "  File \"pandas/_libs/index.pyx\", line 108, in pandas._libs.index.IndexEngine.get_loc\n",
      "  File \"pandas/_libs/index.pyx\", line 132, in pandas._libs.index.IndexEngine.get_loc\n",
      "  File \"pandas/_libs/hashtable_class_helper.pxi\", line 1601, in pandas._libs.hashtable.PyObjectHashTable.get_item\n",
      "  File \"pandas/_libs/hashtable_class_helper.pxi\", line 1608, in pandas._libs.hashtable.PyObjectHashTable.get_item\n",
      "KeyError: 'time'\n",
      "\n",
      "During handling of the above exception, another exception occurred:\n",
      "\n",
      "Traceback (most recent call last):\n",
      "  File \"/home/janeadams/.conda/envs/test_env/lib/python3.7/site-packages/flask/app.py\", line 2292, in wsgi_app\n",
      "    response = self.full_dispatch_request()\n",
      "  File \"/home/janeadams/.conda/envs/test_env/lib/python3.7/site-packages/flask/app.py\", line 1815, in full_dispatch_request\n",
      "    rv = self.handle_user_exception(e)\n",
      "  File \"/home/janeadams/.conda/envs/test_env/lib/python3.7/site-packages/flask/app.py\", line 1718, in handle_user_exception\n",
      "    reraise(exc_type, exc_value, tb)\n",
      "  File \"/home/janeadams/.conda/envs/test_env/lib/python3.7/site-packages/flask/_compat.py\", line 35, in reraise\n",
      "    raise value\n",
      "  File \"/home/janeadams/.conda/envs/test_env/lib/python3.7/site-packages/flask/app.py\", line 1813, in full_dispatch_request\n",
      "    rv = self.dispatch_request()\n",
      "  File \"/home/janeadams/.conda/envs/test_env/lib/python3.7/site-packages/flask/app.py\", line 1799, in dispatch_request\n",
      "    return self.view_functions[rule.endpoint](**req.view_args)\n",
      "  File \"/home/janeadams/.conda/envs/test_env/lib/python3.7/site-packages/dash/dash.py\", line 960, in dispatch\n",
      "    return self.callback_map[target_id]['callback'](*args)\n",
      "  File \"/home/janeadams/.conda/envs/test_env/lib/python3.7/site-packages/dash/dash.py\", line 900, in add_context\n",
      "    output_value = func(*args, **kwargs)\n",
      "  File \"<ipython-input-8-fb09f0c12743>\", line 20, in update_graph\n",
      "    data.append({'x':df['time'], 'y':df['counts'],'name':item})\n",
      "  File \"/home/janeadams/.conda/envs/test_env/lib/python3.7/site-packages/pandas/core/frame.py\", line 2927, in __getitem__\n",
      "    indexer = self.columns.get_loc(key)\n",
      "  File \"/home/janeadams/.conda/envs/test_env/lib/python3.7/site-packages/pandas/core/indexes/base.py\", line 2658, in get_loc\n",
      "    return self._engine.get_loc(self._maybe_cast_indexer(key))\n",
      "  File \"pandas/_libs/index.pyx\", line 108, in pandas._libs.index.IndexEngine.get_loc\n",
      "  File \"pandas/_libs/index.pyx\", line 132, in pandas._libs.index.IndexEngine.get_loc\n",
      "  File \"pandas/_libs/hashtable_class_helper.pxi\", line 1601, in pandas._libs.hashtable.PyObjectHashTable.get_item\n",
      "  File \"pandas/_libs/hashtable_class_helper.pxi\", line 1608, in pandas._libs.hashtable.PyObjectHashTable.get_item\n",
      "KeyError: 'time'\n",
      "127.0.0.1 - - [09/Apr/2019 16:04:11] \"POST /_dash-update-component HTTP/1.1\" 500 -\n"
     ]
    },
    {
     "name": "stdout",
     "output_type": "stream",
     "text": [
      "No timeseries found for massm\n",
      "No timeseries found for massmu\n"
     ]
    },
    {
     "name": "stderr",
     "output_type": "stream",
     "text": [
      "[2019-04-09 16:04:11,898] ERROR in app: Exception on /_dash-update-component [POST]\n",
      "Traceback (most recent call last):\n",
      "  File \"/home/janeadams/.conda/envs/test_env/lib/python3.7/site-packages/pandas/core/indexes/base.py\", line 2656, in get_loc\n",
      "    return self._engine.get_loc(key)\n",
      "  File \"pandas/_libs/index.pyx\", line 108, in pandas._libs.index.IndexEngine.get_loc\n",
      "  File \"pandas/_libs/index.pyx\", line 132, in pandas._libs.index.IndexEngine.get_loc\n",
      "  File \"pandas/_libs/hashtable_class_helper.pxi\", line 1601, in pandas._libs.hashtable.PyObjectHashTable.get_item\n",
      "  File \"pandas/_libs/hashtable_class_helper.pxi\", line 1608, in pandas._libs.hashtable.PyObjectHashTable.get_item\n",
      "KeyError: 'time'\n",
      "\n",
      "During handling of the above exception, another exception occurred:\n",
      "\n",
      "Traceback (most recent call last):\n",
      "  File \"/home/janeadams/.conda/envs/test_env/lib/python3.7/site-packages/flask/app.py\", line 2292, in wsgi_app\n",
      "    response = self.full_dispatch_request()\n",
      "  File \"/home/janeadams/.conda/envs/test_env/lib/python3.7/site-packages/flask/app.py\", line 1815, in full_dispatch_request\n",
      "    rv = self.handle_user_exception(e)\n",
      "  File \"/home/janeadams/.conda/envs/test_env/lib/python3.7/site-packages/flask/app.py\", line 1718, in handle_user_exception\n",
      "    reraise(exc_type, exc_value, tb)\n",
      "  File \"/home/janeadams/.conda/envs/test_env/lib/python3.7/site-packages/flask/_compat.py\", line 35, in reraise\n",
      "    raise value\n",
      "  File \"/home/janeadams/.conda/envs/test_env/lib/python3.7/site-packages/flask/app.py\", line 1813, in full_dispatch_request\n",
      "    rv = self.dispatch_request()\n",
      "  File \"/home/janeadams/.conda/envs/test_env/lib/python3.7/site-packages/flask/app.py\", line 1799, in dispatch_request\n",
      "    return self.view_functions[rule.endpoint](**req.view_args)\n",
      "  File \"/home/janeadams/.conda/envs/test_env/lib/python3.7/site-packages/dash/dash.py\", line 960, in dispatch\n",
      "    return self.callback_map[target_id]['callback'](*args)\n",
      "  File \"/home/janeadams/.conda/envs/test_env/lib/python3.7/site-packages/dash/dash.py\", line 900, in add_context\n",
      "    output_value = func(*args, **kwargs)\n",
      "  File \"<ipython-input-8-fb09f0c12743>\", line 20, in update_graph\n",
      "    data.append({'x':df['time'], 'y':df['counts'],'name':item})\n",
      "  File \"/home/janeadams/.conda/envs/test_env/lib/python3.7/site-packages/pandas/core/frame.py\", line 2927, in __getitem__\n",
      "    indexer = self.columns.get_loc(key)\n",
      "  File \"/home/janeadams/.conda/envs/test_env/lib/python3.7/site-packages/pandas/core/indexes/base.py\", line 2658, in get_loc\n",
      "    return self._engine.get_loc(self._maybe_cast_indexer(key))\n",
      "  File \"pandas/_libs/index.pyx\", line 108, in pandas._libs.index.IndexEngine.get_loc\n",
      "  File \"pandas/_libs/index.pyx\", line 132, in pandas._libs.index.IndexEngine.get_loc\n",
      "  File \"pandas/_libs/hashtable_class_helper.pxi\", line 1601, in pandas._libs.hashtable.PyObjectHashTable.get_item\n",
      "  File \"pandas/_libs/hashtable_class_helper.pxi\", line 1608, in pandas._libs.hashtable.PyObjectHashTable.get_item\n",
      "KeyError: 'time'\n",
      "127.0.0.1 - - [09/Apr/2019 16:04:12] \"POST /_dash-update-component HTTP/1.1\" 200 -\n",
      "127.0.0.1 - - [09/Apr/2019 16:04:12] \"POST /_dash-update-component HTTP/1.1\" 500 -\n",
      "[2019-04-09 16:04:12,078] ERROR in app: Exception on /_dash-update-component [POST]\n",
      "Traceback (most recent call last):\n",
      "  File \"/home/janeadams/.conda/envs/test_env/lib/python3.7/site-packages/pandas/core/indexes/base.py\", line 2656, in get_loc\n",
      "    return self._engine.get_loc(key)\n",
      "  File \"pandas/_libs/index.pyx\", line 108, in pandas._libs.index.IndexEngine.get_loc\n",
      "  File \"pandas/_libs/index.pyx\", line 132, in pandas._libs.index.IndexEngine.get_loc\n",
      "  File \"pandas/_libs/hashtable_class_helper.pxi\", line 1601, in pandas._libs.hashtable.PyObjectHashTable.get_item\n",
      "  File \"pandas/_libs/hashtable_class_helper.pxi\", line 1608, in pandas._libs.hashtable.PyObjectHashTable.get_item\n",
      "KeyError: 'time'\n",
      "\n",
      "During handling of the above exception, another exception occurred:\n",
      "\n",
      "Traceback (most recent call last):\n",
      "  File \"/home/janeadams/.conda/envs/test_env/lib/python3.7/site-packages/flask/app.py\", line 2292, in wsgi_app\n",
      "    response = self.full_dispatch_request()\n",
      "  File \"/home/janeadams/.conda/envs/test_env/lib/python3.7/site-packages/flask/app.py\", line 1815, in full_dispatch_request\n",
      "    rv = self.handle_user_exception(e)\n",
      "  File \"/home/janeadams/.conda/envs/test_env/lib/python3.7/site-packages/flask/app.py\", line 1718, in handle_user_exception\n",
      "    reraise(exc_type, exc_value, tb)\n",
      "  File \"/home/janeadams/.conda/envs/test_env/lib/python3.7/site-packages/flask/_compat.py\", line 35, in reraise\n",
      "    raise value\n",
      "  File \"/home/janeadams/.conda/envs/test_env/lib/python3.7/site-packages/flask/app.py\", line 1813, in full_dispatch_request\n",
      "    rv = self.dispatch_request()\n",
      "  File \"/home/janeadams/.conda/envs/test_env/lib/python3.7/site-packages/flask/app.py\", line 1799, in dispatch_request\n",
      "    return self.view_functions[rule.endpoint](**req.view_args)\n",
      "  File \"/home/janeadams/.conda/envs/test_env/lib/python3.7/site-packages/dash/dash.py\", line 960, in dispatch\n",
      "    return self.callback_map[target_id]['callback'](*args)\n",
      "  File \"/home/janeadams/.conda/envs/test_env/lib/python3.7/site-packages/dash/dash.py\", line 900, in add_context\n",
      "    output_value = func(*args, **kwargs)\n",
      "  File \"<ipython-input-8-fb09f0c12743>\", line 20, in update_graph\n",
      "    data.append({'x':df['time'], 'y':df['counts'],'name':item})\n",
      "  File \"/home/janeadams/.conda/envs/test_env/lib/python3.7/site-packages/pandas/core/frame.py\", line 2927, in __getitem__\n",
      "    indexer = self.columns.get_loc(key)\n",
      "  File \"/home/janeadams/.conda/envs/test_env/lib/python3.7/site-packages/pandas/core/indexes/base.py\", line 2658, in get_loc\n",
      "    return self._engine.get_loc(self._maybe_cast_indexer(key))\n",
      "  File \"pandas/_libs/index.pyx\", line 108, in pandas._libs.index.IndexEngine.get_loc\n",
      "  File \"pandas/_libs/index.pyx\", line 132, in pandas._libs.index.IndexEngine.get_loc\n",
      "  File \"pandas/_libs/hashtable_class_helper.pxi\", line 1601, in pandas._libs.hashtable.PyObjectHashTable.get_item\n",
      "  File \"pandas/_libs/hashtable_class_helper.pxi\", line 1608, in pandas._libs.hashtable.PyObjectHashTable.get_item\n",
      "KeyError: 'time'\n",
      "127.0.0.1 - - [09/Apr/2019 16:04:12] \"POST /_dash-update-component HTTP/1.1\" 500 -\n"
     ]
    },
    {
     "name": "stdout",
     "output_type": "stream",
     "text": [
      "No timeseries found for massmut\n",
      "No timeseries found for massmutu\n",
      "No timeseries found for massmutua\n"
     ]
    },
    {
     "name": "stderr",
     "output_type": "stream",
     "text": [
      "[2019-04-09 16:04:12,218] ERROR in app: Exception on /_dash-update-component [POST]\n",
      "Traceback (most recent call last):\n",
      "  File \"/home/janeadams/.conda/envs/test_env/lib/python3.7/site-packages/pandas/core/indexes/base.py\", line 2656, in get_loc\n",
      "    return self._engine.get_loc(key)\n",
      "  File \"pandas/_libs/index.pyx\", line 108, in pandas._libs.index.IndexEngine.get_loc\n",
      "  File \"pandas/_libs/index.pyx\", line 132, in pandas._libs.index.IndexEngine.get_loc\n",
      "  File \"pandas/_libs/hashtable_class_helper.pxi\", line 1601, in pandas._libs.hashtable.PyObjectHashTable.get_item\n",
      "  File \"pandas/_libs/hashtable_class_helper.pxi\", line 1608, in pandas._libs.hashtable.PyObjectHashTable.get_item\n",
      "KeyError: 'time'\n",
      "\n",
      "During handling of the above exception, another exception occurred:\n",
      "\n",
      "Traceback (most recent call last):\n",
      "  File \"/home/janeadams/.conda/envs/test_env/lib/python3.7/site-packages/flask/app.py\", line 2292, in wsgi_app\n",
      "    response = self.full_dispatch_request()\n",
      "  File \"/home/janeadams/.conda/envs/test_env/lib/python3.7/site-packages/flask/app.py\", line 1815, in full_dispatch_request\n",
      "    rv = self.handle_user_exception(e)\n",
      "  File \"/home/janeadams/.conda/envs/test_env/lib/python3.7/site-packages/flask/app.py\", line 1718, in handle_user_exception\n",
      "    reraise(exc_type, exc_value, tb)\n",
      "  File \"/home/janeadams/.conda/envs/test_env/lib/python3.7/site-packages/flask/_compat.py\", line 35, in reraise\n",
      "    raise value\n",
      "  File \"/home/janeadams/.conda/envs/test_env/lib/python3.7/site-packages/flask/app.py\", line 1813, in full_dispatch_request\n",
      "    rv = self.dispatch_request()\n",
      "  File \"/home/janeadams/.conda/envs/test_env/lib/python3.7/site-packages/flask/app.py\", line 1799, in dispatch_request\n",
      "    return self.view_functions[rule.endpoint](**req.view_args)\n",
      "  File \"/home/janeadams/.conda/envs/test_env/lib/python3.7/site-packages/dash/dash.py\", line 960, in dispatch\n",
      "    return self.callback_map[target_id]['callback'](*args)\n",
      "  File \"/home/janeadams/.conda/envs/test_env/lib/python3.7/site-packages/dash/dash.py\", line 900, in add_context\n",
      "    output_value = func(*args, **kwargs)\n",
      "  File \"<ipython-input-8-fb09f0c12743>\", line 20, in update_graph\n",
      "    data.append({'x':df['time'], 'y':df['counts'],'name':item})\n",
      "  File \"/home/janeadams/.conda/envs/test_env/lib/python3.7/site-packages/pandas/core/frame.py\", line 2927, in __getitem__\n",
      "    indexer = self.columns.get_loc(key)\n",
      "  File \"/home/janeadams/.conda/envs/test_env/lib/python3.7/site-packages/pandas/core/indexes/base.py\", line 2658, in get_loc\n",
      "    return self._engine.get_loc(self._maybe_cast_indexer(key))\n",
      "  File \"pandas/_libs/index.pyx\", line 108, in pandas._libs.index.IndexEngine.get_loc\n",
      "  File \"pandas/_libs/index.pyx\", line 132, in pandas._libs.index.IndexEngine.get_loc\n",
      "  File \"pandas/_libs/hashtable_class_helper.pxi\", line 1601, in pandas._libs.hashtable.PyObjectHashTable.get_item\n",
      "  File \"pandas/_libs/hashtable_class_helper.pxi\", line 1608, in pandas._libs.hashtable.PyObjectHashTable.get_item\n",
      "KeyError: 'time'\n",
      "127.0.0.1 - - [09/Apr/2019 16:04:12] \"POST /_dash-update-component HTTP/1.1\" 500 -\n",
      "[2019-04-09 16:04:12,238] ERROR in app: Exception on /_dash-update-component [POST]\n",
      "Traceback (most recent call last):\n",
      "  File \"/home/janeadams/.conda/envs/test_env/lib/python3.7/site-packages/pandas/core/indexes/base.py\", line 2656, in get_loc\n",
      "    return self._engine.get_loc(key)\n",
      "  File \"pandas/_libs/index.pyx\", line 108, in pandas._libs.index.IndexEngine.get_loc\n",
      "  File \"pandas/_libs/index.pyx\", line 132, in pandas._libs.index.IndexEngine.get_loc\n",
      "  File \"pandas/_libs/hashtable_class_helper.pxi\", line 1601, in pandas._libs.hashtable.PyObjectHashTable.get_item\n",
      "  File \"pandas/_libs/hashtable_class_helper.pxi\", line 1608, in pandas._libs.hashtable.PyObjectHashTable.get_item\n",
      "KeyError: 'time'\n",
      "\n",
      "During handling of the above exception, another exception occurred:\n",
      "\n",
      "Traceback (most recent call last):\n",
      "  File \"/home/janeadams/.conda/envs/test_env/lib/python3.7/site-packages/flask/app.py\", line 2292, in wsgi_app\n",
      "    response = self.full_dispatch_request()\n",
      "  File \"/home/janeadams/.conda/envs/test_env/lib/python3.7/site-packages/flask/app.py\", line 1815, in full_dispatch_request\n",
      "    rv = self.handle_user_exception(e)\n",
      "  File \"/home/janeadams/.conda/envs/test_env/lib/python3.7/site-packages/flask/app.py\", line 1718, in handle_user_exception\n",
      "    reraise(exc_type, exc_value, tb)\n",
      "  File \"/home/janeadams/.conda/envs/test_env/lib/python3.7/site-packages/flask/_compat.py\", line 35, in reraise\n",
      "    raise value\n",
      "  File \"/home/janeadams/.conda/envs/test_env/lib/python3.7/site-packages/flask/app.py\", line 1813, in full_dispatch_request\n",
      "    rv = self.dispatch_request()\n",
      "  File \"/home/janeadams/.conda/envs/test_env/lib/python3.7/site-packages/flask/app.py\", line 1799, in dispatch_request\n",
      "    return self.view_functions[rule.endpoint](**req.view_args)\n",
      "  File \"/home/janeadams/.conda/envs/test_env/lib/python3.7/site-packages/dash/dash.py\", line 960, in dispatch\n",
      "    return self.callback_map[target_id]['callback'](*args)\n",
      "  File \"/home/janeadams/.conda/envs/test_env/lib/python3.7/site-packages/dash/dash.py\", line 900, in add_context\n",
      "    output_value = func(*args, **kwargs)\n",
      "  File \"<ipython-input-8-fb09f0c12743>\", line 20, in update_graph\n",
      "    data.append({'x':df['time'], 'y':df['counts'],'name':item})\n",
      "  File \"/home/janeadams/.conda/envs/test_env/lib/python3.7/site-packages/pandas/core/frame.py\", line 2927, in __getitem__\n",
      "    indexer = self.columns.get_loc(key)\n",
      "  File \"/home/janeadams/.conda/envs/test_env/lib/python3.7/site-packages/pandas/core/indexes/base.py\", line 2658, in get_loc\n",
      "    return self._engine.get_loc(self._maybe_cast_indexer(key))\n",
      "  File \"pandas/_libs/index.pyx\", line 108, in pandas._libs.index.IndexEngine.get_loc\n",
      "  File \"pandas/_libs/index.pyx\", line 132, in pandas._libs.index.IndexEngine.get_loc\n",
      "  File \"pandas/_libs/hashtable_class_helper.pxi\", line 1601, in pandas._libs.hashtable.PyObjectHashTable.get_item\n",
      "  File \"pandas/_libs/hashtable_class_helper.pxi\", line 1608, in pandas._libs.hashtable.PyObjectHashTable.get_item\n",
      "KeyError: 'time'\n",
      "127.0.0.1 - - [09/Apr/2019 16:04:12] \"POST /_dash-update-component HTTP/1.1\" 200 -\n",
      "127.0.0.1 - - [09/Apr/2019 16:04:12] \"POST /_dash-update-component HTTP/1.1\" 500 -\n",
      "127.0.0.1 - - [09/Apr/2019 16:04:12] \"POST /_dash-update-component HTTP/1.1\" 200 -\n",
      "127.0.0.1 - - [09/Apr/2019 16:04:12] \"POST /_dash-update-component HTTP/1.1\" 200 -\n",
      "127.0.0.1 - - [09/Apr/2019 16:04:13] \"POST /_dash-update-component HTTP/1.1\" 200 -\n",
      "[2019-04-09 16:04:37,361] ERROR in app: Exception on /_dash-update-component [POST]\n",
      "Traceback (most recent call last):\n",
      "  File \"/home/janeadams/.conda/envs/test_env/lib/python3.7/site-packages/pandas/core/indexes/base.py\", line 2656, in get_loc\n",
      "    return self._engine.get_loc(key)\n",
      "  File \"pandas/_libs/index.pyx\", line 108, in pandas._libs.index.IndexEngine.get_loc\n",
      "  File \"pandas/_libs/index.pyx\", line 132, in pandas._libs.index.IndexEngine.get_loc\n",
      "  File \"pandas/_libs/hashtable_class_helper.pxi\", line 1601, in pandas._libs.hashtable.PyObjectHashTable.get_item\n",
      "  File \"pandas/_libs/hashtable_class_helper.pxi\", line 1608, in pandas._libs.hashtable.PyObjectHashTable.get_item\n",
      "KeyError: 'time'\n",
      "\n",
      "During handling of the above exception, another exception occurred:\n",
      "\n",
      "Traceback (most recent call last):\n",
      "  File \"/home/janeadams/.conda/envs/test_env/lib/python3.7/site-packages/flask/app.py\", line 2292, in wsgi_app\n",
      "    response = self.full_dispatch_request()\n",
      "  File \"/home/janeadams/.conda/envs/test_env/lib/python3.7/site-packages/flask/app.py\", line 1815, in full_dispatch_request\n",
      "    rv = self.handle_user_exception(e)\n",
      "  File \"/home/janeadams/.conda/envs/test_env/lib/python3.7/site-packages/flask/app.py\", line 1718, in handle_user_exception\n",
      "    reraise(exc_type, exc_value, tb)\n",
      "  File \"/home/janeadams/.conda/envs/test_env/lib/python3.7/site-packages/flask/_compat.py\", line 35, in reraise\n",
      "    raise value\n",
      "  File \"/home/janeadams/.conda/envs/test_env/lib/python3.7/site-packages/flask/app.py\", line 1813, in full_dispatch_request\n",
      "    rv = self.dispatch_request()\n",
      "  File \"/home/janeadams/.conda/envs/test_env/lib/python3.7/site-packages/flask/app.py\", line 1799, in dispatch_request\n",
      "    return self.view_functions[rule.endpoint](**req.view_args)\n",
      "  File \"/home/janeadams/.conda/envs/test_env/lib/python3.7/site-packages/dash/dash.py\", line 960, in dispatch\n",
      "    return self.callback_map[target_id]['callback'](*args)\n",
      "  File \"/home/janeadams/.conda/envs/test_env/lib/python3.7/site-packages/dash/dash.py\", line 900, in add_context\n",
      "    output_value = func(*args, **kwargs)\n",
      "  File \"<ipython-input-8-fb09f0c12743>\", line 20, in update_graph\n",
      "    data.append({'x':df['time'], 'y':df['counts'],'name':item})\n",
      "  File \"/home/janeadams/.conda/envs/test_env/lib/python3.7/site-packages/pandas/core/frame.py\", line 2927, in __getitem__\n",
      "    indexer = self.columns.get_loc(key)\n",
      "  File \"/home/janeadams/.conda/envs/test_env/lib/python3.7/site-packages/pandas/core/indexes/base.py\", line 2658, in get_loc\n",
      "    return self._engine.get_loc(self._maybe_cast_indexer(key))\n",
      "  File \"pandas/_libs/index.pyx\", line 108, in pandas._libs.index.IndexEngine.get_loc\n",
      "  File \"pandas/_libs/index.pyx\", line 132, in pandas._libs.index.IndexEngine.get_loc\n",
      "  File \"pandas/_libs/hashtable_class_helper.pxi\", line 1601, in pandas._libs.hashtable.PyObjectHashTable.get_item\n",
      "  File \"pandas/_libs/hashtable_class_helper.pxi\", line 1608, in pandas._libs.hashtable.PyObjectHashTable.get_item\n",
      "KeyError: 'time'\n"
     ]
    },
    {
     "name": "stderr",
     "output_type": "stream",
     "text": [
      "127.0.0.1 - - [09/Apr/2019 16:04:37] \"POST /_dash-update-component HTTP/1.1\" 500 -\n",
      "[2019-04-09 16:04:37,491] ERROR in app: Exception on /_dash-update-component [POST]\n",
      "Traceback (most recent call last):\n",
      "  File \"/home/janeadams/.conda/envs/test_env/lib/python3.7/site-packages/pandas/core/indexes/base.py\", line 2656, in get_loc\n",
      "    return self._engine.get_loc(key)\n",
      "  File \"pandas/_libs/index.pyx\", line 108, in pandas._libs.index.IndexEngine.get_loc\n",
      "  File \"pandas/_libs/index.pyx\", line 132, in pandas._libs.index.IndexEngine.get_loc\n",
      "  File \"pandas/_libs/hashtable_class_helper.pxi\", line 1601, in pandas._libs.hashtable.PyObjectHashTable.get_item\n",
      "  File \"pandas/_libs/hashtable_class_helper.pxi\", line 1608, in pandas._libs.hashtable.PyObjectHashTable.get_item\n",
      "KeyError: 'time'\n",
      "\n",
      "During handling of the above exception, another exception occurred:\n",
      "\n",
      "Traceback (most recent call last):\n",
      "  File \"/home/janeadams/.conda/envs/test_env/lib/python3.7/site-packages/flask/app.py\", line 2292, in wsgi_app\n",
      "    response = self.full_dispatch_request()\n",
      "  File \"/home/janeadams/.conda/envs/test_env/lib/python3.7/site-packages/flask/app.py\", line 1815, in full_dispatch_request\n",
      "    rv = self.handle_user_exception(e)\n",
      "  File \"/home/janeadams/.conda/envs/test_env/lib/python3.7/site-packages/flask/app.py\", line 1718, in handle_user_exception\n",
      "    reraise(exc_type, exc_value, tb)\n",
      "  File \"/home/janeadams/.conda/envs/test_env/lib/python3.7/site-packages/flask/_compat.py\", line 35, in reraise\n",
      "    raise value\n",
      "  File \"/home/janeadams/.conda/envs/test_env/lib/python3.7/site-packages/flask/app.py\", line 1813, in full_dispatch_request\n",
      "    rv = self.dispatch_request()\n",
      "  File \"/home/janeadams/.conda/envs/test_env/lib/python3.7/site-packages/flask/app.py\", line 1799, in dispatch_request\n",
      "    return self.view_functions[rule.endpoint](**req.view_args)\n",
      "  File \"/home/janeadams/.conda/envs/test_env/lib/python3.7/site-packages/dash/dash.py\", line 960, in dispatch\n",
      "    return self.callback_map[target_id]['callback'](*args)\n",
      "  File \"/home/janeadams/.conda/envs/test_env/lib/python3.7/site-packages/dash/dash.py\", line 900, in add_context\n",
      "    output_value = func(*args, **kwargs)\n",
      "  File \"<ipython-input-8-fb09f0c12743>\", line 20, in update_graph\n",
      "    data.append({'x':df['time'], 'y':df['counts'],'name':item})\n",
      "  File \"/home/janeadams/.conda/envs/test_env/lib/python3.7/site-packages/pandas/core/frame.py\", line 2927, in __getitem__\n",
      "    indexer = self.columns.get_loc(key)\n",
      "  File \"/home/janeadams/.conda/envs/test_env/lib/python3.7/site-packages/pandas/core/indexes/base.py\", line 2658, in get_loc\n",
      "    return self._engine.get_loc(self._maybe_cast_indexer(key))\n",
      "  File \"pandas/_libs/index.pyx\", line 108, in pandas._libs.index.IndexEngine.get_loc\n",
      "  File \"pandas/_libs/index.pyx\", line 132, in pandas._libs.index.IndexEngine.get_loc\n",
      "  File \"pandas/_libs/hashtable_class_helper.pxi\", line 1601, in pandas._libs.hashtable.PyObjectHashTable.get_item\n",
      "  File \"pandas/_libs/hashtable_class_helper.pxi\", line 1608, in pandas._libs.hashtable.PyObjectHashTable.get_item\n",
      "KeyError: 'time'\n",
      "127.0.0.1 - - [09/Apr/2019 16:04:37] \"POST /_dash-update-component HTTP/1.1\" 500 -\n"
     ]
    },
    {
     "name": "stdout",
     "output_type": "stream",
     "text": [
      "No timeseries found for \n",
      "No timeseries found for  \n"
     ]
    },
    {
     "name": "stderr",
     "output_type": "stream",
     "text": [
      "[2019-04-09 16:04:37,835] ERROR in app: Exception on /_dash-update-component [POST]\n",
      "Traceback (most recent call last):\n",
      "  File \"/home/janeadams/.conda/envs/test_env/lib/python3.7/site-packages/pandas/core/indexes/base.py\", line 2656, in get_loc\n",
      "    return self._engine.get_loc(key)\n",
      "  File \"pandas/_libs/index.pyx\", line 108, in pandas._libs.index.IndexEngine.get_loc\n",
      "  File \"pandas/_libs/index.pyx\", line 132, in pandas._libs.index.IndexEngine.get_loc\n",
      "  File \"pandas/_libs/hashtable_class_helper.pxi\", line 1601, in pandas._libs.hashtable.PyObjectHashTable.get_item\n",
      "  File \"pandas/_libs/hashtable_class_helper.pxi\", line 1608, in pandas._libs.hashtable.PyObjectHashTable.get_item\n",
      "KeyError: 'time'\n",
      "\n",
      "During handling of the above exception, another exception occurred:\n",
      "\n",
      "Traceback (most recent call last):\n",
      "  File \"/home/janeadams/.conda/envs/test_env/lib/python3.7/site-packages/flask/app.py\", line 2292, in wsgi_app\n",
      "    response = self.full_dispatch_request()\n",
      "  File \"/home/janeadams/.conda/envs/test_env/lib/python3.7/site-packages/flask/app.py\", line 1815, in full_dispatch_request\n",
      "    rv = self.handle_user_exception(e)\n",
      "  File \"/home/janeadams/.conda/envs/test_env/lib/python3.7/site-packages/flask/app.py\", line 1718, in handle_user_exception\n",
      "    reraise(exc_type, exc_value, tb)\n",
      "  File \"/home/janeadams/.conda/envs/test_env/lib/python3.7/site-packages/flask/_compat.py\", line 35, in reraise\n",
      "    raise value\n",
      "  File \"/home/janeadams/.conda/envs/test_env/lib/python3.7/site-packages/flask/app.py\", line 1813, in full_dispatch_request\n",
      "    rv = self.dispatch_request()\n",
      "  File \"/home/janeadams/.conda/envs/test_env/lib/python3.7/site-packages/flask/app.py\", line 1799, in dispatch_request\n",
      "    return self.view_functions[rule.endpoint](**req.view_args)\n",
      "  File \"/home/janeadams/.conda/envs/test_env/lib/python3.7/site-packages/dash/dash.py\", line 960, in dispatch\n",
      "    return self.callback_map[target_id]['callback'](*args)\n",
      "  File \"/home/janeadams/.conda/envs/test_env/lib/python3.7/site-packages/dash/dash.py\", line 900, in add_context\n",
      "    output_value = func(*args, **kwargs)\n",
      "  File \"<ipython-input-8-fb09f0c12743>\", line 20, in update_graph\n",
      "    data.append({'x':df['time'], 'y':df['counts'],'name':item})\n",
      "  File \"/home/janeadams/.conda/envs/test_env/lib/python3.7/site-packages/pandas/core/frame.py\", line 2927, in __getitem__\n",
      "    indexer = self.columns.get_loc(key)\n",
      "  File \"/home/janeadams/.conda/envs/test_env/lib/python3.7/site-packages/pandas/core/indexes/base.py\", line 2658, in get_loc\n",
      "    return self._engine.get_loc(self._maybe_cast_indexer(key))\n",
      "  File \"pandas/_libs/index.pyx\", line 108, in pandas._libs.index.IndexEngine.get_loc\n",
      "  File \"pandas/_libs/index.pyx\", line 132, in pandas._libs.index.IndexEngine.get_loc\n",
      "  File \"pandas/_libs/hashtable_class_helper.pxi\", line 1601, in pandas._libs.hashtable.PyObjectHashTable.get_item\n",
      "  File \"pandas/_libs/hashtable_class_helper.pxi\", line 1608, in pandas._libs.hashtable.PyObjectHashTable.get_item\n",
      "KeyError: 'time'\n",
      "127.0.0.1 - - [09/Apr/2019 16:04:37] \"POST /_dash-update-component HTTP/1.1\" 500 -\n"
     ]
    },
    {
     "name": "stdout",
     "output_type": "stream",
     "text": [
      "No timeseries found for  @\n"
     ]
    },
    {
     "name": "stderr",
     "output_type": "stream",
     "text": [
      "[2019-04-09 16:04:38,088] ERROR in app: Exception on /_dash-update-component [POST]\n",
      "Traceback (most recent call last):\n",
      "  File \"/home/janeadams/.conda/envs/test_env/lib/python3.7/site-packages/pandas/core/indexes/base.py\", line 2656, in get_loc\n",
      "    return self._engine.get_loc(key)\n",
      "  File \"pandas/_libs/index.pyx\", line 108, in pandas._libs.index.IndexEngine.get_loc\n",
      "  File \"pandas/_libs/index.pyx\", line 132, in pandas._libs.index.IndexEngine.get_loc\n",
      "  File \"pandas/_libs/hashtable_class_helper.pxi\", line 1601, in pandas._libs.hashtable.PyObjectHashTable.get_item\n",
      "  File \"pandas/_libs/hashtable_class_helper.pxi\", line 1608, in pandas._libs.hashtable.PyObjectHashTable.get_item\n",
      "KeyError: 'time'\n",
      "\n",
      "During handling of the above exception, another exception occurred:\n",
      "\n",
      "Traceback (most recent call last):\n",
      "  File \"/home/janeadams/.conda/envs/test_env/lib/python3.7/site-packages/flask/app.py\", line 2292, in wsgi_app\n",
      "    response = self.full_dispatch_request()\n",
      "  File \"/home/janeadams/.conda/envs/test_env/lib/python3.7/site-packages/flask/app.py\", line 1815, in full_dispatch_request\n",
      "    rv = self.handle_user_exception(e)\n",
      "  File \"/home/janeadams/.conda/envs/test_env/lib/python3.7/site-packages/flask/app.py\", line 1718, in handle_user_exception\n",
      "    reraise(exc_type, exc_value, tb)\n",
      "  File \"/home/janeadams/.conda/envs/test_env/lib/python3.7/site-packages/flask/_compat.py\", line 35, in reraise\n",
      "    raise value\n",
      "  File \"/home/janeadams/.conda/envs/test_env/lib/python3.7/site-packages/flask/app.py\", line 1813, in full_dispatch_request\n",
      "    rv = self.dispatch_request()\n",
      "  File \"/home/janeadams/.conda/envs/test_env/lib/python3.7/site-packages/flask/app.py\", line 1799, in dispatch_request\n",
      "    return self.view_functions[rule.endpoint](**req.view_args)\n",
      "  File \"/home/janeadams/.conda/envs/test_env/lib/python3.7/site-packages/dash/dash.py\", line 960, in dispatch\n",
      "    return self.callback_map[target_id]['callback'](*args)\n",
      "  File \"/home/janeadams/.conda/envs/test_env/lib/python3.7/site-packages/dash/dash.py\", line 900, in add_context\n",
      "    output_value = func(*args, **kwargs)\n",
      "  File \"<ipython-input-8-fb09f0c12743>\", line 20, in update_graph\n",
      "    data.append({'x':df['time'], 'y':df['counts'],'name':item})\n",
      "  File \"/home/janeadams/.conda/envs/test_env/lib/python3.7/site-packages/pandas/core/frame.py\", line 2927, in __getitem__\n",
      "    indexer = self.columns.get_loc(key)\n",
      "  File \"/home/janeadams/.conda/envs/test_env/lib/python3.7/site-packages/pandas/core/indexes/base.py\", line 2658, in get_loc\n",
      "    return self._engine.get_loc(self._maybe_cast_indexer(key))\n",
      "  File \"pandas/_libs/index.pyx\", line 108, in pandas._libs.index.IndexEngine.get_loc\n",
      "  File \"pandas/_libs/index.pyx\", line 132, in pandas._libs.index.IndexEngine.get_loc\n",
      "  File \"pandas/_libs/hashtable_class_helper.pxi\", line 1601, in pandas._libs.hashtable.PyObjectHashTable.get_item\n",
      "  File \"pandas/_libs/hashtable_class_helper.pxi\", line 1608, in pandas._libs.hashtable.PyObjectHashTable.get_item\n",
      "KeyError: 'time'\n",
      "127.0.0.1 - - [09/Apr/2019 16:04:38] \"POST /_dash-update-component HTTP/1.1\" 500 -\n",
      "[2019-04-09 16:04:38,234] ERROR in app: Exception on /_dash-update-component [POST]\n",
      "Traceback (most recent call last):\n",
      "  File \"/home/janeadams/.conda/envs/test_env/lib/python3.7/site-packages/pandas/core/indexes/base.py\", line 2656, in get_loc\n",
      "    return self._engine.get_loc(key)\n",
      "  File \"pandas/_libs/index.pyx\", line 108, in pandas._libs.index.IndexEngine.get_loc\n",
      "  File \"pandas/_libs/index.pyx\", line 132, in pandas._libs.index.IndexEngine.get_loc\n",
      "  File \"pandas/_libs/hashtable_class_helper.pxi\", line 1601, in pandas._libs.hashtable.PyObjectHashTable.get_item\n",
      "  File \"pandas/_libs/hashtable_class_helper.pxi\", line 1608, in pandas._libs.hashtable.PyObjectHashTable.get_item\n",
      "KeyError: 'time'\n",
      "\n",
      "During handling of the above exception, another exception occurred:\n",
      "\n",
      "Traceback (most recent call last):\n",
      "  File \"/home/janeadams/.conda/envs/test_env/lib/python3.7/site-packages/flask/app.py\", line 2292, in wsgi_app\n",
      "    response = self.full_dispatch_request()\n",
      "  File \"/home/janeadams/.conda/envs/test_env/lib/python3.7/site-packages/flask/app.py\", line 1815, in full_dispatch_request\n",
      "    rv = self.handle_user_exception(e)\n",
      "  File \"/home/janeadams/.conda/envs/test_env/lib/python3.7/site-packages/flask/app.py\", line 1718, in handle_user_exception\n",
      "    reraise(exc_type, exc_value, tb)\n",
      "  File \"/home/janeadams/.conda/envs/test_env/lib/python3.7/site-packages/flask/_compat.py\", line 35, in reraise\n",
      "    raise value\n",
      "  File \"/home/janeadams/.conda/envs/test_env/lib/python3.7/site-packages/flask/app.py\", line 1813, in full_dispatch_request\n",
      "    rv = self.dispatch_request()\n",
      "  File \"/home/janeadams/.conda/envs/test_env/lib/python3.7/site-packages/flask/app.py\", line 1799, in dispatch_request\n",
      "    return self.view_functions[rule.endpoint](**req.view_args)\n",
      "  File \"/home/janeadams/.conda/envs/test_env/lib/python3.7/site-packages/dash/dash.py\", line 960, in dispatch\n",
      "    return self.callback_map[target_id]['callback'](*args)\n",
      "  File \"/home/janeadams/.conda/envs/test_env/lib/python3.7/site-packages/dash/dash.py\", line 900, in add_context\n",
      "    output_value = func(*args, **kwargs)\n",
      "  File \"<ipython-input-8-fb09f0c12743>\", line 20, in update_graph\n",
      "    data.append({'x':df['time'], 'y':df['counts'],'name':item})\n",
      "  File \"/home/janeadams/.conda/envs/test_env/lib/python3.7/site-packages/pandas/core/frame.py\", line 2927, in __getitem__\n",
      "    indexer = self.columns.get_loc(key)\n",
      "  File \"/home/janeadams/.conda/envs/test_env/lib/python3.7/site-packages/pandas/core/indexes/base.py\", line 2658, in get_loc\n",
      "    return self._engine.get_loc(self._maybe_cast_indexer(key))\n",
      "  File \"pandas/_libs/index.pyx\", line 108, in pandas._libs.index.IndexEngine.get_loc\n",
      "  File \"pandas/_libs/index.pyx\", line 132, in pandas._libs.index.IndexEngine.get_loc\n",
      "  File \"pandas/_libs/hashtable_class_helper.pxi\", line 1601, in pandas._libs.hashtable.PyObjectHashTable.get_item\n",
      "  File \"pandas/_libs/hashtable_class_helper.pxi\", line 1608, in pandas._libs.hashtable.PyObjectHashTable.get_item\n",
      "KeyError: 'time'\n",
      "127.0.0.1 - - [09/Apr/2019 16:04:38] \"POST /_dash-update-component HTTP/1.1\" 500 -\n"
     ]
    },
    {
     "name": "stdout",
     "output_type": "stream",
     "text": [
      "No timeseries found for  @m\n",
      "No timeseries found for  @ma\n"
     ]
    },
    {
     "name": "stderr",
     "output_type": "stream",
     "text": [
      "[2019-04-09 16:04:38,570] ERROR in app: Exception on /_dash-update-component [POST]\n",
      "Traceback (most recent call last):\n",
      "  File \"/home/janeadams/.conda/envs/test_env/lib/python3.7/site-packages/pandas/core/indexes/base.py\", line 2656, in get_loc\n",
      "    return self._engine.get_loc(key)\n",
      "  File \"pandas/_libs/index.pyx\", line 108, in pandas._libs.index.IndexEngine.get_loc\n",
      "  File \"pandas/_libs/index.pyx\", line 132, in pandas._libs.index.IndexEngine.get_loc\n",
      "  File \"pandas/_libs/hashtable_class_helper.pxi\", line 1601, in pandas._libs.hashtable.PyObjectHashTable.get_item\n",
      "  File \"pandas/_libs/hashtable_class_helper.pxi\", line 1608, in pandas._libs.hashtable.PyObjectHashTable.get_item\n",
      "KeyError: 'time'\n",
      "\n",
      "During handling of the above exception, another exception occurred:\n",
      "\n",
      "Traceback (most recent call last):\n",
      "  File \"/home/janeadams/.conda/envs/test_env/lib/python3.7/site-packages/flask/app.py\", line 2292, in wsgi_app\n",
      "    response = self.full_dispatch_request()\n",
      "  File \"/home/janeadams/.conda/envs/test_env/lib/python3.7/site-packages/flask/app.py\", line 1815, in full_dispatch_request\n",
      "    rv = self.handle_user_exception(e)\n",
      "  File \"/home/janeadams/.conda/envs/test_env/lib/python3.7/site-packages/flask/app.py\", line 1718, in handle_user_exception\n",
      "    reraise(exc_type, exc_value, tb)\n",
      "  File \"/home/janeadams/.conda/envs/test_env/lib/python3.7/site-packages/flask/_compat.py\", line 35, in reraise\n",
      "    raise value\n",
      "  File \"/home/janeadams/.conda/envs/test_env/lib/python3.7/site-packages/flask/app.py\", line 1813, in full_dispatch_request\n",
      "    rv = self.dispatch_request()\n",
      "  File \"/home/janeadams/.conda/envs/test_env/lib/python3.7/site-packages/flask/app.py\", line 1799, in dispatch_request\n",
      "    return self.view_functions[rule.endpoint](**req.view_args)\n",
      "  File \"/home/janeadams/.conda/envs/test_env/lib/python3.7/site-packages/dash/dash.py\", line 960, in dispatch\n",
      "    return self.callback_map[target_id]['callback'](*args)\n",
      "  File \"/home/janeadams/.conda/envs/test_env/lib/python3.7/site-packages/dash/dash.py\", line 900, in add_context\n",
      "    output_value = func(*args, **kwargs)\n",
      "  File \"<ipython-input-8-fb09f0c12743>\", line 20, in update_graph\n",
      "    data.append({'x':df['time'], 'y':df['counts'],'name':item})\n",
      "  File \"/home/janeadams/.conda/envs/test_env/lib/python3.7/site-packages/pandas/core/frame.py\", line 2927, in __getitem__\n",
      "    indexer = self.columns.get_loc(key)\n",
      "  File \"/home/janeadams/.conda/envs/test_env/lib/python3.7/site-packages/pandas/core/indexes/base.py\", line 2658, in get_loc\n",
      "    return self._engine.get_loc(self._maybe_cast_indexer(key))\n",
      "  File \"pandas/_libs/index.pyx\", line 108, in pandas._libs.index.IndexEngine.get_loc\n",
      "  File \"pandas/_libs/index.pyx\", line 132, in pandas._libs.index.IndexEngine.get_loc\n",
      "  File \"pandas/_libs/hashtable_class_helper.pxi\", line 1601, in pandas._libs.hashtable.PyObjectHashTable.get_item\n",
      "  File \"pandas/_libs/hashtable_class_helper.pxi\", line 1608, in pandas._libs.hashtable.PyObjectHashTable.get_item\n",
      "KeyError: 'time'\n",
      "127.0.0.1 - - [09/Apr/2019 16:04:38] \"POST /_dash-update-component HTTP/1.1\" 500 -\n",
      "[2019-04-09 16:04:38,706] ERROR in app: Exception on /_dash-update-component [POST]\n",
      "Traceback (most recent call last):\n",
      "  File \"/home/janeadams/.conda/envs/test_env/lib/python3.7/site-packages/pandas/core/indexes/base.py\", line 2656, in get_loc\n",
      "    return self._engine.get_loc(key)\n",
      "  File \"pandas/_libs/index.pyx\", line 108, in pandas._libs.index.IndexEngine.get_loc\n",
      "  File \"pandas/_libs/index.pyx\", line 132, in pandas._libs.index.IndexEngine.get_loc\n",
      "  File \"pandas/_libs/hashtable_class_helper.pxi\", line 1601, in pandas._libs.hashtable.PyObjectHashTable.get_item\n",
      "  File \"pandas/_libs/hashtable_class_helper.pxi\", line 1608, in pandas._libs.hashtable.PyObjectHashTable.get_item\n",
      "KeyError: 'time'\n",
      "\n",
      "During handling of the above exception, another exception occurred:\n",
      "\n",
      "Traceback (most recent call last):\n",
      "  File \"/home/janeadams/.conda/envs/test_env/lib/python3.7/site-packages/flask/app.py\", line 2292, in wsgi_app\n",
      "    response = self.full_dispatch_request()\n",
      "  File \"/home/janeadams/.conda/envs/test_env/lib/python3.7/site-packages/flask/app.py\", line 1815, in full_dispatch_request\n",
      "    rv = self.handle_user_exception(e)\n",
      "  File \"/home/janeadams/.conda/envs/test_env/lib/python3.7/site-packages/flask/app.py\", line 1718, in handle_user_exception\n",
      "    reraise(exc_type, exc_value, tb)\n",
      "  File \"/home/janeadams/.conda/envs/test_env/lib/python3.7/site-packages/flask/_compat.py\", line 35, in reraise\n",
      "    raise value\n",
      "  File \"/home/janeadams/.conda/envs/test_env/lib/python3.7/site-packages/flask/app.py\", line 1813, in full_dispatch_request\n",
      "    rv = self.dispatch_request()\n",
      "  File \"/home/janeadams/.conda/envs/test_env/lib/python3.7/site-packages/flask/app.py\", line 1799, in dispatch_request\n",
      "    return self.view_functions[rule.endpoint](**req.view_args)\n",
      "  File \"/home/janeadams/.conda/envs/test_env/lib/python3.7/site-packages/dash/dash.py\", line 960, in dispatch\n",
      "    return self.callback_map[target_id]['callback'](*args)\n",
      "  File \"/home/janeadams/.conda/envs/test_env/lib/python3.7/site-packages/dash/dash.py\", line 900, in add_context\n",
      "    output_value = func(*args, **kwargs)\n",
      "  File \"<ipython-input-8-fb09f0c12743>\", line 20, in update_graph\n",
      "    data.append({'x':df['time'], 'y':df['counts'],'name':item})\n",
      "  File \"/home/janeadams/.conda/envs/test_env/lib/python3.7/site-packages/pandas/core/frame.py\", line 2927, in __getitem__\n",
      "    indexer = self.columns.get_loc(key)\n",
      "  File \"/home/janeadams/.conda/envs/test_env/lib/python3.7/site-packages/pandas/core/indexes/base.py\", line 2658, in get_loc\n",
      "    return self._engine.get_loc(self._maybe_cast_indexer(key))\n",
      "  File \"pandas/_libs/index.pyx\", line 108, in pandas._libs.index.IndexEngine.get_loc\n",
      "  File \"pandas/_libs/index.pyx\", line 132, in pandas._libs.index.IndexEngine.get_loc\n",
      "  File \"pandas/_libs/hashtable_class_helper.pxi\", line 1601, in pandas._libs.hashtable.PyObjectHashTable.get_item\n",
      "  File \"pandas/_libs/hashtable_class_helper.pxi\", line 1608, in pandas._libs.hashtable.PyObjectHashTable.get_item\n",
      "KeyError: 'time'\n",
      "127.0.0.1 - - [09/Apr/2019 16:04:38] \"POST /_dash-update-component HTTP/1.1\" 500 -\n"
     ]
    },
    {
     "name": "stdout",
     "output_type": "stream",
     "text": [
      "No timeseries found for  @m\n",
      "No timeseries found for  @\n"
     ]
    },
    {
     "name": "stderr",
     "output_type": "stream",
     "text": [
      "[2019-04-09 16:04:38,850] ERROR in app: Exception on /_dash-update-component [POST]\n",
      "Traceback (most recent call last):\n",
      "  File \"/home/janeadams/.conda/envs/test_env/lib/python3.7/site-packages/pandas/core/indexes/base.py\", line 2656, in get_loc\n",
      "    return self._engine.get_loc(key)\n",
      "  File \"pandas/_libs/index.pyx\", line 108, in pandas._libs.index.IndexEngine.get_loc\n",
      "  File \"pandas/_libs/index.pyx\", line 132, in pandas._libs.index.IndexEngine.get_loc\n",
      "  File \"pandas/_libs/hashtable_class_helper.pxi\", line 1601, in pandas._libs.hashtable.PyObjectHashTable.get_item\n",
      "  File \"pandas/_libs/hashtable_class_helper.pxi\", line 1608, in pandas._libs.hashtable.PyObjectHashTable.get_item\n",
      "KeyError: 'time'\n",
      "\n",
      "During handling of the above exception, another exception occurred:\n",
      "\n",
      "Traceback (most recent call last):\n",
      "  File \"/home/janeadams/.conda/envs/test_env/lib/python3.7/site-packages/flask/app.py\", line 2292, in wsgi_app\n",
      "    response = self.full_dispatch_request()\n",
      "  File \"/home/janeadams/.conda/envs/test_env/lib/python3.7/site-packages/flask/app.py\", line 1815, in full_dispatch_request\n",
      "    rv = self.handle_user_exception(e)\n",
      "  File \"/home/janeadams/.conda/envs/test_env/lib/python3.7/site-packages/flask/app.py\", line 1718, in handle_user_exception\n",
      "    reraise(exc_type, exc_value, tb)\n",
      "  File \"/home/janeadams/.conda/envs/test_env/lib/python3.7/site-packages/flask/_compat.py\", line 35, in reraise\n",
      "    raise value\n",
      "  File \"/home/janeadams/.conda/envs/test_env/lib/python3.7/site-packages/flask/app.py\", line 1813, in full_dispatch_request\n",
      "    rv = self.dispatch_request()\n",
      "  File \"/home/janeadams/.conda/envs/test_env/lib/python3.7/site-packages/flask/app.py\", line 1799, in dispatch_request\n",
      "    return self.view_functions[rule.endpoint](**req.view_args)\n",
      "  File \"/home/janeadams/.conda/envs/test_env/lib/python3.7/site-packages/dash/dash.py\", line 960, in dispatch\n",
      "    return self.callback_map[target_id]['callback'](*args)\n",
      "  File \"/home/janeadams/.conda/envs/test_env/lib/python3.7/site-packages/dash/dash.py\", line 900, in add_context\n",
      "    output_value = func(*args, **kwargs)\n",
      "  File \"<ipython-input-8-fb09f0c12743>\", line 20, in update_graph\n",
      "    data.append({'x':df['time'], 'y':df['counts'],'name':item})\n",
      "  File \"/home/janeadams/.conda/envs/test_env/lib/python3.7/site-packages/pandas/core/frame.py\", line 2927, in __getitem__\n",
      "    indexer = self.columns.get_loc(key)\n",
      "  File \"/home/janeadams/.conda/envs/test_env/lib/python3.7/site-packages/pandas/core/indexes/base.py\", line 2658, in get_loc\n",
      "    return self._engine.get_loc(self._maybe_cast_indexer(key))\n",
      "  File \"pandas/_libs/index.pyx\", line 108, in pandas._libs.index.IndexEngine.get_loc\n",
      "  File \"pandas/_libs/index.pyx\", line 132, in pandas._libs.index.IndexEngine.get_loc\n",
      "  File \"pandas/_libs/hashtable_class_helper.pxi\", line 1601, in pandas._libs.hashtable.PyObjectHashTable.get_item\n",
      "  File \"pandas/_libs/hashtable_class_helper.pxi\", line 1608, in pandas._libs.hashtable.PyObjectHashTable.get_item\n",
      "KeyError: 'time'\n",
      "127.0.0.1 - - [09/Apr/2019 16:04:38] \"POST /_dash-update-component HTTP/1.1\" 500 -\n",
      "[2019-04-09 16:04:38,968] ERROR in app: Exception on /_dash-update-component [POST]\n",
      "Traceback (most recent call last):\n",
      "  File \"/home/janeadams/.conda/envs/test_env/lib/python3.7/site-packages/pandas/core/indexes/base.py\", line 2656, in get_loc\n",
      "    return self._engine.get_loc(key)\n",
      "  File \"pandas/_libs/index.pyx\", line 108, in pandas._libs.index.IndexEngine.get_loc\n",
      "  File \"pandas/_libs/index.pyx\", line 132, in pandas._libs.index.IndexEngine.get_loc\n",
      "  File \"pandas/_libs/hashtable_class_helper.pxi\", line 1601, in pandas._libs.hashtable.PyObjectHashTable.get_item\n",
      "  File \"pandas/_libs/hashtable_class_helper.pxi\", line 1608, in pandas._libs.hashtable.PyObjectHashTable.get_item\n",
      "KeyError: 'time'\n",
      "\n",
      "During handling of the above exception, another exception occurred:\n",
      "\n",
      "Traceback (most recent call last):\n",
      "  File \"/home/janeadams/.conda/envs/test_env/lib/python3.7/site-packages/flask/app.py\", line 2292, in wsgi_app\n",
      "    response = self.full_dispatch_request()\n",
      "  File \"/home/janeadams/.conda/envs/test_env/lib/python3.7/site-packages/flask/app.py\", line 1815, in full_dispatch_request\n",
      "    rv = self.handle_user_exception(e)\n",
      "  File \"/home/janeadams/.conda/envs/test_env/lib/python3.7/site-packages/flask/app.py\", line 1718, in handle_user_exception\n",
      "    reraise(exc_type, exc_value, tb)\n",
      "  File \"/home/janeadams/.conda/envs/test_env/lib/python3.7/site-packages/flask/_compat.py\", line 35, in reraise\n",
      "    raise value\n",
      "  File \"/home/janeadams/.conda/envs/test_env/lib/python3.7/site-packages/flask/app.py\", line 1813, in full_dispatch_request\n",
      "    rv = self.dispatch_request()\n",
      "  File \"/home/janeadams/.conda/envs/test_env/lib/python3.7/site-packages/flask/app.py\", line 1799, in dispatch_request\n",
      "    return self.view_functions[rule.endpoint](**req.view_args)\n",
      "  File \"/home/janeadams/.conda/envs/test_env/lib/python3.7/site-packages/dash/dash.py\", line 960, in dispatch\n",
      "    return self.callback_map[target_id]['callback'](*args)\n",
      "  File \"/home/janeadams/.conda/envs/test_env/lib/python3.7/site-packages/dash/dash.py\", line 900, in add_context\n",
      "    output_value = func(*args, **kwargs)\n",
      "  File \"<ipython-input-8-fb09f0c12743>\", line 20, in update_graph\n",
      "    data.append({'x':df['time'], 'y':df['counts'],'name':item})\n",
      "  File \"/home/janeadams/.conda/envs/test_env/lib/python3.7/site-packages/pandas/core/frame.py\", line 2927, in __getitem__\n",
      "    indexer = self.columns.get_loc(key)\n",
      "  File \"/home/janeadams/.conda/envs/test_env/lib/python3.7/site-packages/pandas/core/indexes/base.py\", line 2658, in get_loc\n",
      "    return self._engine.get_loc(self._maybe_cast_indexer(key))\n",
      "  File \"pandas/_libs/index.pyx\", line 108, in pandas._libs.index.IndexEngine.get_loc\n",
      "  File \"pandas/_libs/index.pyx\", line 132, in pandas._libs.index.IndexEngine.get_loc\n",
      "  File \"pandas/_libs/hashtable_class_helper.pxi\", line 1601, in pandas._libs.hashtable.PyObjectHashTable.get_item\n",
      "  File \"pandas/_libs/hashtable_class_helper.pxi\", line 1608, in pandas._libs.hashtable.PyObjectHashTable.get_item\n",
      "KeyError: 'time'\n",
      "127.0.0.1 - - [09/Apr/2019 16:04:38] \"POST /_dash-update-component HTTP/1.1\" 500 -\n"
     ]
    },
    {
     "name": "stdout",
     "output_type": "stream",
     "text": [
      "No timeseries found for  \n",
      "No timeseries found for \n"
     ]
    },
    {
     "name": "stderr",
     "output_type": "stream",
     "text": [
      "127.0.0.1 - - [09/Apr/2019 16:04:39] \"POST /_dash-update-component HTTP/1.1\" 200 -\n",
      "127.0.0.1 - - [09/Apr/2019 16:04:39] \"POST /_dash-update-component HTTP/1.1\" 200 -\n",
      "[2019-04-09 16:04:39,923] ERROR in app: Exception on /_dash-update-component [POST]\n",
      "Traceback (most recent call last):\n",
      "  File \"/home/janeadams/.conda/envs/test_env/lib/python3.7/site-packages/pandas/core/indexes/base.py\", line 2656, in get_loc\n",
      "    return self._engine.get_loc(key)\n",
      "  File \"pandas/_libs/index.pyx\", line 108, in pandas._libs.index.IndexEngine.get_loc\n",
      "  File \"pandas/_libs/index.pyx\", line 132, in pandas._libs.index.IndexEngine.get_loc\n",
      "  File \"pandas/_libs/hashtable_class_helper.pxi\", line 1601, in pandas._libs.hashtable.PyObjectHashTable.get_item\n",
      "  File \"pandas/_libs/hashtable_class_helper.pxi\", line 1608, in pandas._libs.hashtable.PyObjectHashTable.get_item\n",
      "KeyError: 'time'\n",
      "\n",
      "During handling of the above exception, another exception occurred:\n",
      "\n",
      "Traceback (most recent call last):\n",
      "  File \"/home/janeadams/.conda/envs/test_env/lib/python3.7/site-packages/flask/app.py\", line 2292, in wsgi_app\n",
      "    response = self.full_dispatch_request()\n",
      "  File \"/home/janeadams/.conda/envs/test_env/lib/python3.7/site-packages/flask/app.py\", line 1815, in full_dispatch_request\n",
      "    rv = self.handle_user_exception(e)\n",
      "  File \"/home/janeadams/.conda/envs/test_env/lib/python3.7/site-packages/flask/app.py\", line 1718, in handle_user_exception\n",
      "    reraise(exc_type, exc_value, tb)\n",
      "  File \"/home/janeadams/.conda/envs/test_env/lib/python3.7/site-packages/flask/_compat.py\", line 35, in reraise\n",
      "    raise value\n",
      "  File \"/home/janeadams/.conda/envs/test_env/lib/python3.7/site-packages/flask/app.py\", line 1813, in full_dispatch_request\n",
      "    rv = self.dispatch_request()\n",
      "  File \"/home/janeadams/.conda/envs/test_env/lib/python3.7/site-packages/flask/app.py\", line 1799, in dispatch_request\n",
      "    return self.view_functions[rule.endpoint](**req.view_args)\n",
      "  File \"/home/janeadams/.conda/envs/test_env/lib/python3.7/site-packages/dash/dash.py\", line 960, in dispatch\n",
      "    return self.callback_map[target_id]['callback'](*args)\n",
      "  File \"/home/janeadams/.conda/envs/test_env/lib/python3.7/site-packages/dash/dash.py\", line 900, in add_context\n",
      "    output_value = func(*args, **kwargs)\n",
      "  File \"<ipython-input-8-fb09f0c12743>\", line 20, in update_graph\n",
      "    data.append({'x':df['time'], 'y':df['counts'],'name':item})\n",
      "  File \"/home/janeadams/.conda/envs/test_env/lib/python3.7/site-packages/pandas/core/frame.py\", line 2927, in __getitem__\n",
      "    indexer = self.columns.get_loc(key)\n",
      "  File \"/home/janeadams/.conda/envs/test_env/lib/python3.7/site-packages/pandas/core/indexes/base.py\", line 2658, in get_loc\n",
      "    return self._engine.get_loc(self._maybe_cast_indexer(key))\n",
      "  File \"pandas/_libs/index.pyx\", line 108, in pandas._libs.index.IndexEngine.get_loc\n",
      "  File \"pandas/_libs/index.pyx\", line 132, in pandas._libs.index.IndexEngine.get_loc\n",
      "  File \"pandas/_libs/hashtable_class_helper.pxi\", line 1601, in pandas._libs.hashtable.PyObjectHashTable.get_item\n",
      "  File \"pandas/_libs/hashtable_class_helper.pxi\", line 1608, in pandas._libs.hashtable.PyObjectHashTable.get_item\n",
      "KeyError: 'time'\n",
      "127.0.0.1 - - [09/Apr/2019 16:04:39] \"POST /_dash-update-component HTTP/1.1\" 500 -\n",
      "[2019-04-09 16:04:40,059] ERROR in app: Exception on /_dash-update-component [POST]\n",
      "Traceback (most recent call last):\n",
      "  File \"/home/janeadams/.conda/envs/test_env/lib/python3.7/site-packages/pandas/core/indexes/base.py\", line 2656, in get_loc\n",
      "    return self._engine.get_loc(key)\n",
      "  File \"pandas/_libs/index.pyx\", line 108, in pandas._libs.index.IndexEngine.get_loc\n",
      "  File \"pandas/_libs/index.pyx\", line 132, in pandas._libs.index.IndexEngine.get_loc\n",
      "  File \"pandas/_libs/hashtable_class_helper.pxi\", line 1601, in pandas._libs.hashtable.PyObjectHashTable.get_item\n",
      "  File \"pandas/_libs/hashtable_class_helper.pxi\", line 1608, in pandas._libs.hashtable.PyObjectHashTable.get_item\n",
      "KeyError: 'time'\n",
      "\n",
      "During handling of the above exception, another exception occurred:\n",
      "\n",
      "Traceback (most recent call last):\n",
      "  File \"/home/janeadams/.conda/envs/test_env/lib/python3.7/site-packages/flask/app.py\", line 2292, in wsgi_app\n",
      "    response = self.full_dispatch_request()\n",
      "  File \"/home/janeadams/.conda/envs/test_env/lib/python3.7/site-packages/flask/app.py\", line 1815, in full_dispatch_request\n",
      "    rv = self.handle_user_exception(e)\n",
      "  File \"/home/janeadams/.conda/envs/test_env/lib/python3.7/site-packages/flask/app.py\", line 1718, in handle_user_exception\n",
      "    reraise(exc_type, exc_value, tb)\n",
      "  File \"/home/janeadams/.conda/envs/test_env/lib/python3.7/site-packages/flask/_compat.py\", line 35, in reraise\n",
      "    raise value\n",
      "  File \"/home/janeadams/.conda/envs/test_env/lib/python3.7/site-packages/flask/app.py\", line 1813, in full_dispatch_request\n",
      "    rv = self.dispatch_request()\n",
      "  File \"/home/janeadams/.conda/envs/test_env/lib/python3.7/site-packages/flask/app.py\", line 1799, in dispatch_request\n",
      "    return self.view_functions[rule.endpoint](**req.view_args)\n",
      "  File \"/home/janeadams/.conda/envs/test_env/lib/python3.7/site-packages/dash/dash.py\", line 960, in dispatch\n",
      "    return self.callback_map[target_id]['callback'](*args)\n",
      "  File \"/home/janeadams/.conda/envs/test_env/lib/python3.7/site-packages/dash/dash.py\", line 900, in add_context\n",
      "    output_value = func(*args, **kwargs)\n",
      "  File \"<ipython-input-8-fb09f0c12743>\", line 20, in update_graph\n",
      "    data.append({'x':df['time'], 'y':df['counts'],'name':item})\n",
      "  File \"/home/janeadams/.conda/envs/test_env/lib/python3.7/site-packages/pandas/core/frame.py\", line 2927, in __getitem__\n",
      "    indexer = self.columns.get_loc(key)\n",
      "  File \"/home/janeadams/.conda/envs/test_env/lib/python3.7/site-packages/pandas/core/indexes/base.py\", line 2658, in get_loc\n",
      "    return self._engine.get_loc(self._maybe_cast_indexer(key))\n",
      "  File \"pandas/_libs/index.pyx\", line 108, in pandas._libs.index.IndexEngine.get_loc\n",
      "  File \"pandas/_libs/index.pyx\", line 132, in pandas._libs.index.IndexEngine.get_loc\n",
      "  File \"pandas/_libs/hashtable_class_helper.pxi\", line 1601, in pandas._libs.hashtable.PyObjectHashTable.get_item\n",
      "  File \"pandas/_libs/hashtable_class_helper.pxi\", line 1608, in pandas._libs.hashtable.PyObjectHashTable.get_item\n",
      "KeyError: 'time'\n",
      "127.0.0.1 - - [09/Apr/2019 16:04:40] \"POST /_dash-update-component HTTP/1.1\" 500 -\n"
     ]
    },
    {
     "name": "stdout",
     "output_type": "stream",
     "text": [
      "No timeseries found for @massm\n",
      "No timeseries found for @massmt\n"
     ]
    },
    {
     "name": "stderr",
     "output_type": "stream",
     "text": [
      "[2019-04-09 16:04:40,186] ERROR in app: Exception on /_dash-update-component [POST]\n",
      "Traceback (most recent call last):\n",
      "  File \"/home/janeadams/.conda/envs/test_env/lib/python3.7/site-packages/pandas/core/indexes/base.py\", line 2656, in get_loc\n",
      "    return self._engine.get_loc(key)\n",
      "  File \"pandas/_libs/index.pyx\", line 108, in pandas._libs.index.IndexEngine.get_loc\n",
      "  File \"pandas/_libs/index.pyx\", line 132, in pandas._libs.index.IndexEngine.get_loc\n",
      "  File \"pandas/_libs/hashtable_class_helper.pxi\", line 1601, in pandas._libs.hashtable.PyObjectHashTable.get_item\n",
      "  File \"pandas/_libs/hashtable_class_helper.pxi\", line 1608, in pandas._libs.hashtable.PyObjectHashTable.get_item\n",
      "KeyError: 'time'\n",
      "\n",
      "During handling of the above exception, another exception occurred:\n",
      "\n",
      "Traceback (most recent call last):\n",
      "  File \"/home/janeadams/.conda/envs/test_env/lib/python3.7/site-packages/flask/app.py\", line 2292, in wsgi_app\n",
      "    response = self.full_dispatch_request()\n",
      "  File \"/home/janeadams/.conda/envs/test_env/lib/python3.7/site-packages/flask/app.py\", line 1815, in full_dispatch_request\n",
      "    rv = self.handle_user_exception(e)\n",
      "  File \"/home/janeadams/.conda/envs/test_env/lib/python3.7/site-packages/flask/app.py\", line 1718, in handle_user_exception\n",
      "    reraise(exc_type, exc_value, tb)\n",
      "  File \"/home/janeadams/.conda/envs/test_env/lib/python3.7/site-packages/flask/_compat.py\", line 35, in reraise\n",
      "    raise value\n",
      "  File \"/home/janeadams/.conda/envs/test_env/lib/python3.7/site-packages/flask/app.py\", line 1813, in full_dispatch_request\n",
      "    rv = self.dispatch_request()\n",
      "  File \"/home/janeadams/.conda/envs/test_env/lib/python3.7/site-packages/flask/app.py\", line 1799, in dispatch_request\n",
      "    return self.view_functions[rule.endpoint](**req.view_args)\n",
      "  File \"/home/janeadams/.conda/envs/test_env/lib/python3.7/site-packages/dash/dash.py\", line 960, in dispatch\n",
      "    return self.callback_map[target_id]['callback'](*args)\n",
      "  File \"/home/janeadams/.conda/envs/test_env/lib/python3.7/site-packages/dash/dash.py\", line 900, in add_context\n",
      "    output_value = func(*args, **kwargs)\n",
      "  File \"<ipython-input-8-fb09f0c12743>\", line 20, in update_graph\n",
      "    data.append({'x':df['time'], 'y':df['counts'],'name':item})\n",
      "  File \"/home/janeadams/.conda/envs/test_env/lib/python3.7/site-packages/pandas/core/frame.py\", line 2927, in __getitem__\n",
      "    indexer = self.columns.get_loc(key)\n",
      "  File \"/home/janeadams/.conda/envs/test_env/lib/python3.7/site-packages/pandas/core/indexes/base.py\", line 2658, in get_loc\n",
      "    return self._engine.get_loc(self._maybe_cast_indexer(key))\n",
      "  File \"pandas/_libs/index.pyx\", line 108, in pandas._libs.index.IndexEngine.get_loc\n",
      "  File \"pandas/_libs/index.pyx\", line 132, in pandas._libs.index.IndexEngine.get_loc\n",
      "  File \"pandas/_libs/hashtable_class_helper.pxi\", line 1601, in pandas._libs.hashtable.PyObjectHashTable.get_item\n",
      "  File \"pandas/_libs/hashtable_class_helper.pxi\", line 1608, in pandas._libs.hashtable.PyObjectHashTable.get_item\n",
      "KeyError: 'time'\n",
      "127.0.0.1 - - [09/Apr/2019 16:04:40] \"POST /_dash-update-component HTTP/1.1\" 500 -\n"
     ]
    },
    {
     "name": "stdout",
     "output_type": "stream",
     "text": [
      "No timeseries found for @massmtu\n"
     ]
    },
    {
     "name": "stderr",
     "output_type": "stream",
     "text": [
      "127.0.0.1 - - [09/Apr/2019 16:04:40] \"POST /_dash-update-component HTTP/1.1\" 200 -\n",
      "[2019-04-09 16:04:40,513] ERROR in app: Exception on /_dash-update-component [POST]\n",
      "Traceback (most recent call last):\n",
      "  File \"/home/janeadams/.conda/envs/test_env/lib/python3.7/site-packages/pandas/core/indexes/base.py\", line 2656, in get_loc\n",
      "    return self._engine.get_loc(key)\n",
      "  File \"pandas/_libs/index.pyx\", line 108, in pandas._libs.index.IndexEngine.get_loc\n",
      "  File \"pandas/_libs/index.pyx\", line 132, in pandas._libs.index.IndexEngine.get_loc\n",
      "  File \"pandas/_libs/hashtable_class_helper.pxi\", line 1601, in pandas._libs.hashtable.PyObjectHashTable.get_item\n",
      "  File \"pandas/_libs/hashtable_class_helper.pxi\", line 1608, in pandas._libs.hashtable.PyObjectHashTable.get_item\n",
      "KeyError: 'time'\n",
      "\n",
      "During handling of the above exception, another exception occurred:\n",
      "\n",
      "Traceback (most recent call last):\n",
      "  File \"/home/janeadams/.conda/envs/test_env/lib/python3.7/site-packages/flask/app.py\", line 2292, in wsgi_app\n",
      "    response = self.full_dispatch_request()\n",
      "  File \"/home/janeadams/.conda/envs/test_env/lib/python3.7/site-packages/flask/app.py\", line 1815, in full_dispatch_request\n",
      "    rv = self.handle_user_exception(e)\n",
      "  File \"/home/janeadams/.conda/envs/test_env/lib/python3.7/site-packages/flask/app.py\", line 1718, in handle_user_exception\n",
      "    reraise(exc_type, exc_value, tb)\n",
      "  File \"/home/janeadams/.conda/envs/test_env/lib/python3.7/site-packages/flask/_compat.py\", line 35, in reraise\n",
      "    raise value\n",
      "  File \"/home/janeadams/.conda/envs/test_env/lib/python3.7/site-packages/flask/app.py\", line 1813, in full_dispatch_request\n",
      "    rv = self.dispatch_request()\n",
      "  File \"/home/janeadams/.conda/envs/test_env/lib/python3.7/site-packages/flask/app.py\", line 1799, in dispatch_request\n",
      "    return self.view_functions[rule.endpoint](**req.view_args)\n",
      "  File \"/home/janeadams/.conda/envs/test_env/lib/python3.7/site-packages/dash/dash.py\", line 960, in dispatch\n",
      "    return self.callback_map[target_id]['callback'](*args)\n",
      "  File \"/home/janeadams/.conda/envs/test_env/lib/python3.7/site-packages/dash/dash.py\", line 900, in add_context\n",
      "    output_value = func(*args, **kwargs)\n",
      "  File \"<ipython-input-8-fb09f0c12743>\", line 20, in update_graph\n",
      "    data.append({'x':df['time'], 'y':df['counts'],'name':item})\n",
      "  File \"/home/janeadams/.conda/envs/test_env/lib/python3.7/site-packages/pandas/core/frame.py\", line 2927, in __getitem__\n",
      "    indexer = self.columns.get_loc(key)\n",
      "  File \"/home/janeadams/.conda/envs/test_env/lib/python3.7/site-packages/pandas/core/indexes/base.py\", line 2658, in get_loc\n",
      "    return self._engine.get_loc(self._maybe_cast_indexer(key))\n",
      "  File \"pandas/_libs/index.pyx\", line 108, in pandas._libs.index.IndexEngine.get_loc\n",
      "  File \"pandas/_libs/index.pyx\", line 132, in pandas._libs.index.IndexEngine.get_loc\n",
      "  File \"pandas/_libs/hashtable_class_helper.pxi\", line 1601, in pandas._libs.hashtable.PyObjectHashTable.get_item\n",
      "  File \"pandas/_libs/hashtable_class_helper.pxi\", line 1608, in pandas._libs.hashtable.PyObjectHashTable.get_item\n",
      "KeyError: 'time'\n",
      "127.0.0.1 - - [09/Apr/2019 16:04:40] \"POST /_dash-update-component HTTP/1.1\" 500 -\n",
      "[2019-04-09 16:04:40,611] ERROR in app: Exception on /_dash-update-component [POST]\n",
      "Traceback (most recent call last):\n",
      "  File \"/home/janeadams/.conda/envs/test_env/lib/python3.7/site-packages/pandas/core/indexes/base.py\", line 2656, in get_loc\n",
      "    return self._engine.get_loc(key)\n",
      "  File \"pandas/_libs/index.pyx\", line 108, in pandas._libs.index.IndexEngine.get_loc\n",
      "  File \"pandas/_libs/index.pyx\", line 132, in pandas._libs.index.IndexEngine.get_loc\n",
      "  File \"pandas/_libs/hashtable_class_helper.pxi\", line 1601, in pandas._libs.hashtable.PyObjectHashTable.get_item\n",
      "  File \"pandas/_libs/hashtable_class_helper.pxi\", line 1608, in pandas._libs.hashtable.PyObjectHashTable.get_item\n",
      "KeyError: 'time'\n",
      "\n",
      "During handling of the above exception, another exception occurred:\n",
      "\n",
      "Traceback (most recent call last):\n",
      "  File \"/home/janeadams/.conda/envs/test_env/lib/python3.7/site-packages/flask/app.py\", line 2292, in wsgi_app\n",
      "    response = self.full_dispatch_request()\n",
      "  File \"/home/janeadams/.conda/envs/test_env/lib/python3.7/site-packages/flask/app.py\", line 1815, in full_dispatch_request\n",
      "    rv = self.handle_user_exception(e)\n",
      "  File \"/home/janeadams/.conda/envs/test_env/lib/python3.7/site-packages/flask/app.py\", line 1718, in handle_user_exception\n",
      "    reraise(exc_type, exc_value, tb)\n",
      "  File \"/home/janeadams/.conda/envs/test_env/lib/python3.7/site-packages/flask/_compat.py\", line 35, in reraise\n",
      "    raise value\n",
      "  File \"/home/janeadams/.conda/envs/test_env/lib/python3.7/site-packages/flask/app.py\", line 1813, in full_dispatch_request\n",
      "    rv = self.dispatch_request()\n",
      "  File \"/home/janeadams/.conda/envs/test_env/lib/python3.7/site-packages/flask/app.py\", line 1799, in dispatch_request\n",
      "    return self.view_functions[rule.endpoint](**req.view_args)\n",
      "  File \"/home/janeadams/.conda/envs/test_env/lib/python3.7/site-packages/dash/dash.py\", line 960, in dispatch\n",
      "    return self.callback_map[target_id]['callback'](*args)\n",
      "  File \"/home/janeadams/.conda/envs/test_env/lib/python3.7/site-packages/dash/dash.py\", line 900, in add_context\n",
      "    output_value = func(*args, **kwargs)\n",
      "  File \"<ipython-input-8-fb09f0c12743>\", line 20, in update_graph\n",
      "    data.append({'x':df['time'], 'y':df['counts'],'name':item})\n",
      "  File \"/home/janeadams/.conda/envs/test_env/lib/python3.7/site-packages/pandas/core/frame.py\", line 2927, in __getitem__\n",
      "    indexer = self.columns.get_loc(key)\n",
      "  File \"/home/janeadams/.conda/envs/test_env/lib/python3.7/site-packages/pandas/core/indexes/base.py\", line 2658, in get_loc\n",
      "    return self._engine.get_loc(self._maybe_cast_indexer(key))\n",
      "  File \"pandas/_libs/index.pyx\", line 108, in pandas._libs.index.IndexEngine.get_loc\n",
      "  File \"pandas/_libs/index.pyx\", line 132, in pandas._libs.index.IndexEngine.get_loc\n",
      "  File \"pandas/_libs/hashtable_class_helper.pxi\", line 1601, in pandas._libs.hashtable.PyObjectHashTable.get_item\n",
      "  File \"pandas/_libs/hashtable_class_helper.pxi\", line 1608, in pandas._libs.hashtable.PyObjectHashTable.get_item\n",
      "KeyError: 'time'\n",
      "127.0.0.1 - - [09/Apr/2019 16:04:40] \"POST /_dash-update-component HTTP/1.1\" 500 -\n"
     ]
    },
    {
     "name": "stdout",
     "output_type": "stream",
     "text": [
      "No timeseries found for @massmt\n",
      "No timeseries found for @massm\n"
     ]
    },
    {
     "name": "stderr",
     "output_type": "stream",
     "text": [
      "[2019-04-09 16:04:40,785] ERROR in app: Exception on /_dash-update-component [POST]\n",
      "Traceback (most recent call last):\n",
      "  File \"/home/janeadams/.conda/envs/test_env/lib/python3.7/site-packages/pandas/core/indexes/base.py\", line 2656, in get_loc\n",
      "    return self._engine.get_loc(key)\n",
      "  File \"pandas/_libs/index.pyx\", line 108, in pandas._libs.index.IndexEngine.get_loc\n",
      "  File \"pandas/_libs/index.pyx\", line 132, in pandas._libs.index.IndexEngine.get_loc\n",
      "  File \"pandas/_libs/hashtable_class_helper.pxi\", line 1601, in pandas._libs.hashtable.PyObjectHashTable.get_item\n",
      "  File \"pandas/_libs/hashtable_class_helper.pxi\", line 1608, in pandas._libs.hashtable.PyObjectHashTable.get_item\n",
      "KeyError: 'time'\n",
      "\n",
      "During handling of the above exception, another exception occurred:\n",
      "\n",
      "Traceback (most recent call last):\n",
      "  File \"/home/janeadams/.conda/envs/test_env/lib/python3.7/site-packages/flask/app.py\", line 2292, in wsgi_app\n",
      "    response = self.full_dispatch_request()\n",
      "  File \"/home/janeadams/.conda/envs/test_env/lib/python3.7/site-packages/flask/app.py\", line 1815, in full_dispatch_request\n",
      "    rv = self.handle_user_exception(e)\n",
      "  File \"/home/janeadams/.conda/envs/test_env/lib/python3.7/site-packages/flask/app.py\", line 1718, in handle_user_exception\n",
      "    reraise(exc_type, exc_value, tb)\n",
      "  File \"/home/janeadams/.conda/envs/test_env/lib/python3.7/site-packages/flask/_compat.py\", line 35, in reraise\n",
      "    raise value\n",
      "  File \"/home/janeadams/.conda/envs/test_env/lib/python3.7/site-packages/flask/app.py\", line 1813, in full_dispatch_request\n",
      "    rv = self.dispatch_request()\n",
      "  File \"/home/janeadams/.conda/envs/test_env/lib/python3.7/site-packages/flask/app.py\", line 1799, in dispatch_request\n",
      "    return self.view_functions[rule.endpoint](**req.view_args)\n",
      "  File \"/home/janeadams/.conda/envs/test_env/lib/python3.7/site-packages/dash/dash.py\", line 960, in dispatch\n",
      "    return self.callback_map[target_id]['callback'](*args)\n",
      "  File \"/home/janeadams/.conda/envs/test_env/lib/python3.7/site-packages/dash/dash.py\", line 900, in add_context\n",
      "    output_value = func(*args, **kwargs)\n",
      "  File \"<ipython-input-8-fb09f0c12743>\", line 20, in update_graph\n",
      "    data.append({'x':df['time'], 'y':df['counts'],'name':item})\n",
      "  File \"/home/janeadams/.conda/envs/test_env/lib/python3.7/site-packages/pandas/core/frame.py\", line 2927, in __getitem__\n",
      "    indexer = self.columns.get_loc(key)\n",
      "  File \"/home/janeadams/.conda/envs/test_env/lib/python3.7/site-packages/pandas/core/indexes/base.py\", line 2658, in get_loc\n",
      "    return self._engine.get_loc(self._maybe_cast_indexer(key))\n",
      "  File \"pandas/_libs/index.pyx\", line 108, in pandas._libs.index.IndexEngine.get_loc\n",
      "  File \"pandas/_libs/index.pyx\", line 132, in pandas._libs.index.IndexEngine.get_loc\n",
      "  File \"pandas/_libs/hashtable_class_helper.pxi\", line 1601, in pandas._libs.hashtable.PyObjectHashTable.get_item\n",
      "  File \"pandas/_libs/hashtable_class_helper.pxi\", line 1608, in pandas._libs.hashtable.PyObjectHashTable.get_item\n",
      "KeyError: 'time'\n",
      "127.0.0.1 - - [09/Apr/2019 16:04:40] \"POST /_dash-update-component HTTP/1.1\" 500 -\n",
      "[2019-04-09 16:04:40,896] ERROR in app: Exception on /_dash-update-component [POST]\n",
      "Traceback (most recent call last):\n",
      "  File \"/home/janeadams/.conda/envs/test_env/lib/python3.7/site-packages/pandas/core/indexes/base.py\", line 2656, in get_loc\n",
      "    return self._engine.get_loc(key)\n",
      "  File \"pandas/_libs/index.pyx\", line 108, in pandas._libs.index.IndexEngine.get_loc\n",
      "  File \"pandas/_libs/index.pyx\", line 132, in pandas._libs.index.IndexEngine.get_loc\n",
      "  File \"pandas/_libs/hashtable_class_helper.pxi\", line 1601, in pandas._libs.hashtable.PyObjectHashTable.get_item\n",
      "  File \"pandas/_libs/hashtable_class_helper.pxi\", line 1608, in pandas._libs.hashtable.PyObjectHashTable.get_item\n",
      "KeyError: 'time'\n",
      "\n",
      "During handling of the above exception, another exception occurred:\n",
      "\n",
      "Traceback (most recent call last):\n",
      "  File \"/home/janeadams/.conda/envs/test_env/lib/python3.7/site-packages/flask/app.py\", line 2292, in wsgi_app\n",
      "    response = self.full_dispatch_request()\n",
      "  File \"/home/janeadams/.conda/envs/test_env/lib/python3.7/site-packages/flask/app.py\", line 1815, in full_dispatch_request\n",
      "    rv = self.handle_user_exception(e)\n",
      "  File \"/home/janeadams/.conda/envs/test_env/lib/python3.7/site-packages/flask/app.py\", line 1718, in handle_user_exception\n",
      "    reraise(exc_type, exc_value, tb)\n",
      "  File \"/home/janeadams/.conda/envs/test_env/lib/python3.7/site-packages/flask/_compat.py\", line 35, in reraise\n",
      "    raise value\n",
      "  File \"/home/janeadams/.conda/envs/test_env/lib/python3.7/site-packages/flask/app.py\", line 1813, in full_dispatch_request\n",
      "    rv = self.dispatch_request()\n",
      "  File \"/home/janeadams/.conda/envs/test_env/lib/python3.7/site-packages/flask/app.py\", line 1799, in dispatch_request\n",
      "    return self.view_functions[rule.endpoint](**req.view_args)\n",
      "  File \"/home/janeadams/.conda/envs/test_env/lib/python3.7/site-packages/dash/dash.py\", line 960, in dispatch\n",
      "    return self.callback_map[target_id]['callback'](*args)\n",
      "  File \"/home/janeadams/.conda/envs/test_env/lib/python3.7/site-packages/dash/dash.py\", line 900, in add_context\n",
      "    output_value = func(*args, **kwargs)\n",
      "  File \"<ipython-input-8-fb09f0c12743>\", line 20, in update_graph\n",
      "    data.append({'x':df['time'], 'y':df['counts'],'name':item})\n",
      "  File \"/home/janeadams/.conda/envs/test_env/lib/python3.7/site-packages/pandas/core/frame.py\", line 2927, in __getitem__\n",
      "    indexer = self.columns.get_loc(key)\n",
      "  File \"/home/janeadams/.conda/envs/test_env/lib/python3.7/site-packages/pandas/core/indexes/base.py\", line 2658, in get_loc\n",
      "    return self._engine.get_loc(self._maybe_cast_indexer(key))\n",
      "  File \"pandas/_libs/index.pyx\", line 108, in pandas._libs.index.IndexEngine.get_loc\n",
      "  File \"pandas/_libs/index.pyx\", line 132, in pandas._libs.index.IndexEngine.get_loc\n",
      "  File \"pandas/_libs/hashtable_class_helper.pxi\", line 1601, in pandas._libs.hashtable.PyObjectHashTable.get_item\n",
      "  File \"pandas/_libs/hashtable_class_helper.pxi\", line 1608, in pandas._libs.hashtable.PyObjectHashTable.get_item\n",
      "KeyError: 'time'\n",
      "127.0.0.1 - - [09/Apr/2019 16:04:40] \"POST /_dash-update-component HTTP/1.1\" 500 -\n"
     ]
    },
    {
     "name": "stdout",
     "output_type": "stream",
     "text": [
      "No timeseries found for @massmu\n",
      "No timeseries found for @massmut\n"
     ]
    },
    {
     "name": "stderr",
     "output_type": "stream",
     "text": [
      "127.0.0.1 - - [09/Apr/2019 16:04:41] \"POST /_dash-update-component HTTP/1.1\" 200 -\n",
      "[2019-04-09 16:04:41,314] ERROR in app: Exception on /_dash-update-component [POST]\n",
      "Traceback (most recent call last):\n",
      "  File \"/home/janeadams/.conda/envs/test_env/lib/python3.7/site-packages/pandas/core/indexes/base.py\", line 2656, in get_loc\n",
      "    return self._engine.get_loc(key)\n",
      "  File \"pandas/_libs/index.pyx\", line 108, in pandas._libs.index.IndexEngine.get_loc\n",
      "  File \"pandas/_libs/index.pyx\", line 132, in pandas._libs.index.IndexEngine.get_loc\n",
      "  File \"pandas/_libs/hashtable_class_helper.pxi\", line 1601, in pandas._libs.hashtable.PyObjectHashTable.get_item\n",
      "  File \"pandas/_libs/hashtable_class_helper.pxi\", line 1608, in pandas._libs.hashtable.PyObjectHashTable.get_item\n",
      "KeyError: 'time'\n",
      "\n",
      "During handling of the above exception, another exception occurred:\n",
      "\n",
      "Traceback (most recent call last):\n",
      "  File \"/home/janeadams/.conda/envs/test_env/lib/python3.7/site-packages/flask/app.py\", line 2292, in wsgi_app\n",
      "    response = self.full_dispatch_request()\n",
      "  File \"/home/janeadams/.conda/envs/test_env/lib/python3.7/site-packages/flask/app.py\", line 1815, in full_dispatch_request\n",
      "    rv = self.handle_user_exception(e)\n",
      "  File \"/home/janeadams/.conda/envs/test_env/lib/python3.7/site-packages/flask/app.py\", line 1718, in handle_user_exception\n",
      "    reraise(exc_type, exc_value, tb)\n",
      "  File \"/home/janeadams/.conda/envs/test_env/lib/python3.7/site-packages/flask/_compat.py\", line 35, in reraise\n",
      "    raise value\n",
      "  File \"/home/janeadams/.conda/envs/test_env/lib/python3.7/site-packages/flask/app.py\", line 1813, in full_dispatch_request\n",
      "    rv = self.dispatch_request()\n",
      "  File \"/home/janeadams/.conda/envs/test_env/lib/python3.7/site-packages/flask/app.py\", line 1799, in dispatch_request\n",
      "    return self.view_functions[rule.endpoint](**req.view_args)\n",
      "  File \"/home/janeadams/.conda/envs/test_env/lib/python3.7/site-packages/dash/dash.py\", line 960, in dispatch\n",
      "    return self.callback_map[target_id]['callback'](*args)\n",
      "  File \"/home/janeadams/.conda/envs/test_env/lib/python3.7/site-packages/dash/dash.py\", line 900, in add_context\n",
      "    output_value = func(*args, **kwargs)\n",
      "  File \"<ipython-input-8-fb09f0c12743>\", line 20, in update_graph\n",
      "    data.append({'x':df['time'], 'y':df['counts'],'name':item})\n",
      "  File \"/home/janeadams/.conda/envs/test_env/lib/python3.7/site-packages/pandas/core/frame.py\", line 2927, in __getitem__\n",
      "    indexer = self.columns.get_loc(key)\n",
      "  File \"/home/janeadams/.conda/envs/test_env/lib/python3.7/site-packages/pandas/core/indexes/base.py\", line 2658, in get_loc\n",
      "    return self._engine.get_loc(self._maybe_cast_indexer(key))\n",
      "  File \"pandas/_libs/index.pyx\", line 108, in pandas._libs.index.IndexEngine.get_loc\n",
      "  File \"pandas/_libs/index.pyx\", line 132, in pandas._libs.index.IndexEngine.get_loc\n",
      "  File \"pandas/_libs/hashtable_class_helper.pxi\", line 1601, in pandas._libs.hashtable.PyObjectHashTable.get_item\n",
      "  File \"pandas/_libs/hashtable_class_helper.pxi\", line 1608, in pandas._libs.hashtable.PyObjectHashTable.get_item\n",
      "KeyError: 'time'\n",
      "127.0.0.1 - - [09/Apr/2019 16:04:41] \"POST /_dash-update-component HTTP/1.1\" 500 -\n",
      "[2019-04-09 16:04:41,450] ERROR in app: Exception on /_dash-update-component [POST]\n",
      "Traceback (most recent call last):\n",
      "  File \"/home/janeadams/.conda/envs/test_env/lib/python3.7/site-packages/pandas/core/indexes/base.py\", line 2656, in get_loc\n",
      "    return self._engine.get_loc(key)\n",
      "  File \"pandas/_libs/index.pyx\", line 108, in pandas._libs.index.IndexEngine.get_loc\n",
      "  File \"pandas/_libs/index.pyx\", line 132, in pandas._libs.index.IndexEngine.get_loc\n",
      "  File \"pandas/_libs/hashtable_class_helper.pxi\", line 1601, in pandas._libs.hashtable.PyObjectHashTable.get_item\n",
      "  File \"pandas/_libs/hashtable_class_helper.pxi\", line 1608, in pandas._libs.hashtable.PyObjectHashTable.get_item\n",
      "KeyError: 'time'\n",
      "\n",
      "During handling of the above exception, another exception occurred:\n",
      "\n",
      "Traceback (most recent call last):\n",
      "  File \"/home/janeadams/.conda/envs/test_env/lib/python3.7/site-packages/flask/app.py\", line 2292, in wsgi_app\n",
      "    response = self.full_dispatch_request()\n",
      "  File \"/home/janeadams/.conda/envs/test_env/lib/python3.7/site-packages/flask/app.py\", line 1815, in full_dispatch_request\n",
      "    rv = self.handle_user_exception(e)\n",
      "  File \"/home/janeadams/.conda/envs/test_env/lib/python3.7/site-packages/flask/app.py\", line 1718, in handle_user_exception\n",
      "    reraise(exc_type, exc_value, tb)\n",
      "  File \"/home/janeadams/.conda/envs/test_env/lib/python3.7/site-packages/flask/_compat.py\", line 35, in reraise\n",
      "    raise value\n",
      "  File \"/home/janeadams/.conda/envs/test_env/lib/python3.7/site-packages/flask/app.py\", line 1813, in full_dispatch_request\n",
      "    rv = self.dispatch_request()\n",
      "  File \"/home/janeadams/.conda/envs/test_env/lib/python3.7/site-packages/flask/app.py\", line 1799, in dispatch_request\n",
      "    return self.view_functions[rule.endpoint](**req.view_args)\n",
      "  File \"/home/janeadams/.conda/envs/test_env/lib/python3.7/site-packages/dash/dash.py\", line 960, in dispatch\n",
      "    return self.callback_map[target_id]['callback'](*args)\n",
      "  File \"/home/janeadams/.conda/envs/test_env/lib/python3.7/site-packages/dash/dash.py\", line 900, in add_context\n",
      "    output_value = func(*args, **kwargs)\n",
      "  File \"<ipython-input-8-fb09f0c12743>\", line 20, in update_graph\n",
      "    data.append({'x':df['time'], 'y':df['counts'],'name':item})\n",
      "  File \"/home/janeadams/.conda/envs/test_env/lib/python3.7/site-packages/pandas/core/frame.py\", line 2927, in __getitem__\n",
      "    indexer = self.columns.get_loc(key)\n",
      "  File \"/home/janeadams/.conda/envs/test_env/lib/python3.7/site-packages/pandas/core/indexes/base.py\", line 2658, in get_loc\n",
      "    return self._engine.get_loc(self._maybe_cast_indexer(key))\n",
      "  File \"pandas/_libs/index.pyx\", line 108, in pandas._libs.index.IndexEngine.get_loc\n",
      "  File \"pandas/_libs/index.pyx\", line 132, in pandas._libs.index.IndexEngine.get_loc\n",
      "  File \"pandas/_libs/hashtable_class_helper.pxi\", line 1601, in pandas._libs.hashtable.PyObjectHashTable.get_item\n",
      "  File \"pandas/_libs/hashtable_class_helper.pxi\", line 1608, in pandas._libs.hashtable.PyObjectHashTable.get_item\n",
      "KeyError: 'time'\n",
      "127.0.0.1 - - [09/Apr/2019 16:04:41] \"POST /_dash-update-component HTTP/1.1\" 500 -\n"
     ]
    },
    {
     "name": "stdout",
     "output_type": "stream",
     "text": [
      "No timeseries found for @massmutu\n",
      "No timeseries found for @massmutua\n"
     ]
    },
    {
     "name": "stderr",
     "output_type": "stream",
     "text": [
      "127.0.0.1 - - [09/Apr/2019 16:04:41] \"POST /_dash-update-component HTTP/1.1\" 200 -\n",
      "127.0.0.1 - - [09/Apr/2019 16:04:41] \"POST /_dash-update-component HTTP/1.1\" 200 -\n",
      "[2019-04-09 16:05:05,335] ERROR in app: Exception on /_dash-update-component [POST]\n",
      "Traceback (most recent call last):\n",
      "  File \"/home/janeadams/.conda/envs/test_env/lib/python3.7/site-packages/pandas/core/indexes/base.py\", line 2656, in get_loc\n",
      "    return self._engine.get_loc(key)\n",
      "  File \"pandas/_libs/index.pyx\", line 108, in pandas._libs.index.IndexEngine.get_loc\n",
      "  File \"pandas/_libs/index.pyx\", line 132, in pandas._libs.index.IndexEngine.get_loc\n",
      "  File \"pandas/_libs/hashtable_class_helper.pxi\", line 1601, in pandas._libs.hashtable.PyObjectHashTable.get_item\n",
      "  File \"pandas/_libs/hashtable_class_helper.pxi\", line 1608, in pandas._libs.hashtable.PyObjectHashTable.get_item\n",
      "KeyError: 'time'\n",
      "\n",
      "During handling of the above exception, another exception occurred:\n",
      "\n",
      "Traceback (most recent call last):\n",
      "  File \"/home/janeadams/.conda/envs/test_env/lib/python3.7/site-packages/flask/app.py\", line 2292, in wsgi_app\n",
      "    response = self.full_dispatch_request()\n",
      "  File \"/home/janeadams/.conda/envs/test_env/lib/python3.7/site-packages/flask/app.py\", line 1815, in full_dispatch_request\n",
      "    rv = self.handle_user_exception(e)\n",
      "  File \"/home/janeadams/.conda/envs/test_env/lib/python3.7/site-packages/flask/app.py\", line 1718, in handle_user_exception\n",
      "    reraise(exc_type, exc_value, tb)\n",
      "  File \"/home/janeadams/.conda/envs/test_env/lib/python3.7/site-packages/flask/_compat.py\", line 35, in reraise\n",
      "    raise value\n",
      "  File \"/home/janeadams/.conda/envs/test_env/lib/python3.7/site-packages/flask/app.py\", line 1813, in full_dispatch_request\n",
      "    rv = self.dispatch_request()\n",
      "  File \"/home/janeadams/.conda/envs/test_env/lib/python3.7/site-packages/flask/app.py\", line 1799, in dispatch_request\n",
      "    return self.view_functions[rule.endpoint](**req.view_args)\n",
      "  File \"/home/janeadams/.conda/envs/test_env/lib/python3.7/site-packages/dash/dash.py\", line 960, in dispatch\n",
      "    return self.callback_map[target_id]['callback'](*args)\n",
      "  File \"/home/janeadams/.conda/envs/test_env/lib/python3.7/site-packages/dash/dash.py\", line 900, in add_context\n",
      "    output_value = func(*args, **kwargs)\n",
      "  File \"<ipython-input-8-fb09f0c12743>\", line 20, in update_graph\n",
      "    data.append({'x':df['time'], 'y':df['counts'],'name':item})\n",
      "  File \"/home/janeadams/.conda/envs/test_env/lib/python3.7/site-packages/pandas/core/frame.py\", line 2927, in __getitem__\n",
      "    indexer = self.columns.get_loc(key)\n",
      "  File \"/home/janeadams/.conda/envs/test_env/lib/python3.7/site-packages/pandas/core/indexes/base.py\", line 2658, in get_loc\n",
      "    return self._engine.get_loc(self._maybe_cast_indexer(key))\n",
      "  File \"pandas/_libs/index.pyx\", line 108, in pandas._libs.index.IndexEngine.get_loc\n",
      "  File \"pandas/_libs/index.pyx\", line 132, in pandas._libs.index.IndexEngine.get_loc\n",
      "  File \"pandas/_libs/hashtable_class_helper.pxi\", line 1601, in pandas._libs.hashtable.PyObjectHashTable.get_item\n",
      "  File \"pandas/_libs/hashtable_class_helper.pxi\", line 1608, in pandas._libs.hashtable.PyObjectHashTable.get_item\n",
      "KeyError: 'time'\n",
      "127.0.0.1 - - [09/Apr/2019 16:05:05] \"POST /_dash-update-component HTTP/1.1\" 500 -\n"
     ]
    },
    {
     "name": "stdout",
     "output_type": "stream",
     "text": [
      "No timeseries found for \n"
     ]
    },
    {
     "name": "stderr",
     "output_type": "stream",
     "text": [
      "127.0.0.1 - - [09/Apr/2019 16:05:06] \"POST /_dash-update-component HTTP/1.1\" 200 -\n",
      "127.0.0.1 - - [09/Apr/2019 16:05:06] \"POST /_dash-update-component HTTP/1.1\" 200 -\n",
      "127.0.0.1 - - [09/Apr/2019 16:05:06] \"POST /_dash-update-component HTTP/1.1\" 200 -\n",
      "[2019-04-09 16:05:06,823] ERROR in app: Exception on /_dash-update-component [POST]\n",
      "Traceback (most recent call last):\n",
      "  File \"/home/janeadams/.conda/envs/test_env/lib/python3.7/site-packages/pandas/core/indexes/base.py\", line 2656, in get_loc\n",
      "    return self._engine.get_loc(key)\n",
      "  File \"pandas/_libs/index.pyx\", line 108, in pandas._libs.index.IndexEngine.get_loc\n",
      "  File \"pandas/_libs/index.pyx\", line 132, in pandas._libs.index.IndexEngine.get_loc\n",
      "  File \"pandas/_libs/hashtable_class_helper.pxi\", line 1601, in pandas._libs.hashtable.PyObjectHashTable.get_item\n",
      "  File \"pandas/_libs/hashtable_class_helper.pxi\", line 1608, in pandas._libs.hashtable.PyObjectHashTable.get_item\n",
      "KeyError: 'time'\n",
      "\n",
      "During handling of the above exception, another exception occurred:\n",
      "\n",
      "Traceback (most recent call last):\n",
      "  File \"/home/janeadams/.conda/envs/test_env/lib/python3.7/site-packages/flask/app.py\", line 2292, in wsgi_app\n",
      "    response = self.full_dispatch_request()\n",
      "  File \"/home/janeadams/.conda/envs/test_env/lib/python3.7/site-packages/flask/app.py\", line 1815, in full_dispatch_request\n",
      "    rv = self.handle_user_exception(e)\n",
      "  File \"/home/janeadams/.conda/envs/test_env/lib/python3.7/site-packages/flask/app.py\", line 1718, in handle_user_exception\n",
      "    reraise(exc_type, exc_value, tb)\n",
      "  File \"/home/janeadams/.conda/envs/test_env/lib/python3.7/site-packages/flask/_compat.py\", line 35, in reraise\n",
      "    raise value\n",
      "  File \"/home/janeadams/.conda/envs/test_env/lib/python3.7/site-packages/flask/app.py\", line 1813, in full_dispatch_request\n",
      "    rv = self.dispatch_request()\n",
      "  File \"/home/janeadams/.conda/envs/test_env/lib/python3.7/site-packages/flask/app.py\", line 1799, in dispatch_request\n",
      "    return self.view_functions[rule.endpoint](**req.view_args)\n",
      "  File \"/home/janeadams/.conda/envs/test_env/lib/python3.7/site-packages/dash/dash.py\", line 960, in dispatch\n",
      "    return self.callback_map[target_id]['callback'](*args)\n",
      "  File \"/home/janeadams/.conda/envs/test_env/lib/python3.7/site-packages/dash/dash.py\", line 900, in add_context\n",
      "    output_value = func(*args, **kwargs)\n",
      "  File \"<ipython-input-8-fb09f0c12743>\", line 20, in update_graph\n",
      "    data.append({'x':df['time'], 'y':df['counts'],'name':item})\n",
      "  File \"/home/janeadams/.conda/envs/test_env/lib/python3.7/site-packages/pandas/core/frame.py\", line 2927, in __getitem__\n",
      "    indexer = self.columns.get_loc(key)\n",
      "  File \"/home/janeadams/.conda/envs/test_env/lib/python3.7/site-packages/pandas/core/indexes/base.py\", line 2658, in get_loc\n",
      "    return self._engine.get_loc(self._maybe_cast_indexer(key))\n",
      "  File \"pandas/_libs/index.pyx\", line 108, in pandas._libs.index.IndexEngine.get_loc\n",
      "  File \"pandas/_libs/index.pyx\", line 132, in pandas._libs.index.IndexEngine.get_loc\n",
      "  File \"pandas/_libs/hashtable_class_helper.pxi\", line 1601, in pandas._libs.hashtable.PyObjectHashTable.get_item\n",
      "  File \"pandas/_libs/hashtable_class_helper.pxi\", line 1608, in pandas._libs.hashtable.PyObjectHashTable.get_item\n",
      "KeyError: 'time'\n",
      "127.0.0.1 - - [09/Apr/2019 16:05:06] \"POST /_dash-update-component HTTP/1.1\" 500 -\n",
      "[2019-04-09 16:05:06,849] ERROR in app: Exception on /_dash-update-component [POST]\n",
      "Traceback (most recent call last):\n",
      "  File \"/home/janeadams/.conda/envs/test_env/lib/python3.7/site-packages/pandas/core/indexes/base.py\", line 2656, in get_loc\n",
      "    return self._engine.get_loc(key)\n",
      "  File \"pandas/_libs/index.pyx\", line 108, in pandas._libs.index.IndexEngine.get_loc\n",
      "  File \"pandas/_libs/index.pyx\", line 132, in pandas._libs.index.IndexEngine.get_loc\n",
      "  File \"pandas/_libs/hashtable_class_helper.pxi\", line 1601, in pandas._libs.hashtable.PyObjectHashTable.get_item\n",
      "  File \"pandas/_libs/hashtable_class_helper.pxi\", line 1608, in pandas._libs.hashtable.PyObjectHashTable.get_item\n",
      "KeyError: 'time'\n",
      "\n",
      "During handling of the above exception, another exception occurred:\n",
      "\n",
      "Traceback (most recent call last):\n",
      "  File \"/home/janeadams/.conda/envs/test_env/lib/python3.7/site-packages/flask/app.py\", line 2292, in wsgi_app\n",
      "    response = self.full_dispatch_request()\n",
      "  File \"/home/janeadams/.conda/envs/test_env/lib/python3.7/site-packages/flask/app.py\", line 1815, in full_dispatch_request\n",
      "    rv = self.handle_user_exception(e)\n",
      "  File \"/home/janeadams/.conda/envs/test_env/lib/python3.7/site-packages/flask/app.py\", line 1718, in handle_user_exception\n",
      "    reraise(exc_type, exc_value, tb)\n",
      "  File \"/home/janeadams/.conda/envs/test_env/lib/python3.7/site-packages/flask/_compat.py\", line 35, in reraise\n",
      "    raise value\n",
      "  File \"/home/janeadams/.conda/envs/test_env/lib/python3.7/site-packages/flask/app.py\", line 1813, in full_dispatch_request\n",
      "    rv = self.dispatch_request()\n",
      "  File \"/home/janeadams/.conda/envs/test_env/lib/python3.7/site-packages/flask/app.py\", line 1799, in dispatch_request\n",
      "    return self.view_functions[rule.endpoint](**req.view_args)\n",
      "  File \"/home/janeadams/.conda/envs/test_env/lib/python3.7/site-packages/dash/dash.py\", line 960, in dispatch\n",
      "    return self.callback_map[target_id]['callback'](*args)\n",
      "  File \"/home/janeadams/.conda/envs/test_env/lib/python3.7/site-packages/dash/dash.py\", line 900, in add_context\n",
      "    output_value = func(*args, **kwargs)\n",
      "  File \"<ipython-input-8-fb09f0c12743>\", line 20, in update_graph\n",
      "    data.append({'x':df['time'], 'y':df['counts'],'name':item})\n",
      "  File \"/home/janeadams/.conda/envs/test_env/lib/python3.7/site-packages/pandas/core/frame.py\", line 2927, in __getitem__\n",
      "    indexer = self.columns.get_loc(key)\n",
      "  File \"/home/janeadams/.conda/envs/test_env/lib/python3.7/site-packages/pandas/core/indexes/base.py\", line 2658, in get_loc\n",
      "    return self._engine.get_loc(self._maybe_cast_indexer(key))\n",
      "  File \"pandas/_libs/index.pyx\", line 108, in pandas._libs.index.IndexEngine.get_loc\n",
      "  File \"pandas/_libs/index.pyx\", line 132, in pandas._libs.index.IndexEngine.get_loc\n",
      "  File \"pandas/_libs/hashtable_class_helper.pxi\", line 1601, in pandas._libs.hashtable.PyObjectHashTable.get_item\n",
      "  File \"pandas/_libs/hashtable_class_helper.pxi\", line 1608, in pandas._libs.hashtable.PyObjectHashTable.get_item\n",
      "KeyError: 'time'\n",
      "127.0.0.1 - - [09/Apr/2019 16:05:06] \"POST /_dash-update-component HTTP/1.1\" 500 -\n",
      "[2019-04-09 16:05:06,929] ERROR in app: Exception on /_dash-update-component [POST]\n",
      "Traceback (most recent call last):\n",
      "  File \"/home/janeadams/.conda/envs/test_env/lib/python3.7/site-packages/pandas/core/indexes/base.py\", line 2656, in get_loc\n",
      "    return self._engine.get_loc(key)\n",
      "  File \"pandas/_libs/index.pyx\", line 108, in pandas._libs.index.IndexEngine.get_loc\n",
      "  File \"pandas/_libs/index.pyx\", line 132, in pandas._libs.index.IndexEngine.get_loc\n",
      "  File \"pandas/_libs/hashtable_class_helper.pxi\", line 1601, in pandas._libs.hashtable.PyObjectHashTable.get_item\n",
      "  File \"pandas/_libs/hashtable_class_helper.pxi\", line 1608, in pandas._libs.hashtable.PyObjectHashTable.get_item\n",
      "KeyError: 'time'\n",
      "\n",
      "During handling of the above exception, another exception occurred:\n",
      "\n",
      "Traceback (most recent call last):\n",
      "  File \"/home/janeadams/.conda/envs/test_env/lib/python3.7/site-packages/flask/app.py\", line 2292, in wsgi_app\n",
      "    response = self.full_dispatch_request()\n",
      "  File \"/home/janeadams/.conda/envs/test_env/lib/python3.7/site-packages/flask/app.py\", line 1815, in full_dispatch_request\n",
      "    rv = self.handle_user_exception(e)\n",
      "  File \"/home/janeadams/.conda/envs/test_env/lib/python3.7/site-packages/flask/app.py\", line 1718, in handle_user_exception\n",
      "    reraise(exc_type, exc_value, tb)\n",
      "  File \"/home/janeadams/.conda/envs/test_env/lib/python3.7/site-packages/flask/_compat.py\", line 35, in reraise\n",
      "    raise value\n",
      "  File \"/home/janeadams/.conda/envs/test_env/lib/python3.7/site-packages/flask/app.py\", line 1813, in full_dispatch_request\n",
      "    rv = self.dispatch_request()\n",
      "  File \"/home/janeadams/.conda/envs/test_env/lib/python3.7/site-packages/flask/app.py\", line 1799, in dispatch_request\n",
      "    return self.view_functions[rule.endpoint](**req.view_args)\n",
      "  File \"/home/janeadams/.conda/envs/test_env/lib/python3.7/site-packages/dash/dash.py\", line 960, in dispatch\n",
      "    return self.callback_map[target_id]['callback'](*args)\n",
      "  File \"/home/janeadams/.conda/envs/test_env/lib/python3.7/site-packages/dash/dash.py\", line 900, in add_context\n",
      "    output_value = func(*args, **kwargs)\n",
      "  File \"<ipython-input-8-fb09f0c12743>\", line 20, in update_graph\n",
      "    data.append({'x':df['time'], 'y':df['counts'],'name':item})\n",
      "  File \"/home/janeadams/.conda/envs/test_env/lib/python3.7/site-packages/pandas/core/frame.py\", line 2927, in __getitem__\n",
      "    indexer = self.columns.get_loc(key)\n",
      "  File \"/home/janeadams/.conda/envs/test_env/lib/python3.7/site-packages/pandas/core/indexes/base.py\", line 2658, in get_loc\n",
      "    return self._engine.get_loc(self._maybe_cast_indexer(key))\n",
      "  File \"pandas/_libs/index.pyx\", line 108, in pandas._libs.index.IndexEngine.get_loc\n",
      "  File \"pandas/_libs/index.pyx\", line 132, in pandas._libs.index.IndexEngine.get_loc\n",
      "  File \"pandas/_libs/hashtable_class_helper.pxi\", line 1601, in pandas._libs.hashtable.PyObjectHashTable.get_item\n",
      "  File \"pandas/_libs/hashtable_class_helper.pxi\", line 1608, in pandas._libs.hashtable.PyObjectHashTable.get_item\n",
      "KeyError: 'time'\n"
     ]
    },
    {
     "name": "stderr",
     "output_type": "stream",
     "text": [
      "127.0.0.1 - - [09/Apr/2019 16:05:06] \"POST /_dash-update-component HTTP/1.1\" 500 -\n",
      "[2019-04-09 16:05:06,957] ERROR in app: Exception on /_dash-update-component [POST]\n",
      "Traceback (most recent call last):\n",
      "  File \"/home/janeadams/.conda/envs/test_env/lib/python3.7/site-packages/pandas/core/indexes/base.py\", line 2656, in get_loc\n",
      "    return self._engine.get_loc(key)\n",
      "  File \"pandas/_libs/index.pyx\", line 108, in pandas._libs.index.IndexEngine.get_loc\n",
      "  File \"pandas/_libs/index.pyx\", line 132, in pandas._libs.index.IndexEngine.get_loc\n",
      "  File \"pandas/_libs/hashtable_class_helper.pxi\", line 1601, in pandas._libs.hashtable.PyObjectHashTable.get_item\n",
      "  File \"pandas/_libs/hashtable_class_helper.pxi\", line 1608, in pandas._libs.hashtable.PyObjectHashTable.get_item\n",
      "KeyError: 'time'\n",
      "\n",
      "During handling of the above exception, another exception occurred:\n",
      "\n",
      "Traceback (most recent call last):\n",
      "  File \"/home/janeadams/.conda/envs/test_env/lib/python3.7/site-packages/flask/app.py\", line 2292, in wsgi_app\n",
      "    response = self.full_dispatch_request()\n",
      "  File \"/home/janeadams/.conda/envs/test_env/lib/python3.7/site-packages/flask/app.py\", line 1815, in full_dispatch_request\n",
      "    rv = self.handle_user_exception(e)\n",
      "  File \"/home/janeadams/.conda/envs/test_env/lib/python3.7/site-packages/flask/app.py\", line 1718, in handle_user_exception\n",
      "    reraise(exc_type, exc_value, tb)\n",
      "  File \"/home/janeadams/.conda/envs/test_env/lib/python3.7/site-packages/flask/_compat.py\", line 35, in reraise\n",
      "    raise value\n",
      "  File \"/home/janeadams/.conda/envs/test_env/lib/python3.7/site-packages/flask/app.py\", line 1813, in full_dispatch_request\n",
      "    rv = self.dispatch_request()\n",
      "  File \"/home/janeadams/.conda/envs/test_env/lib/python3.7/site-packages/flask/app.py\", line 1799, in dispatch_request\n",
      "    return self.view_functions[rule.endpoint](**req.view_args)\n",
      "  File \"/home/janeadams/.conda/envs/test_env/lib/python3.7/site-packages/dash/dash.py\", line 960, in dispatch\n",
      "    return self.callback_map[target_id]['callback'](*args)\n",
      "  File \"/home/janeadams/.conda/envs/test_env/lib/python3.7/site-packages/dash/dash.py\", line 900, in add_context\n",
      "    output_value = func(*args, **kwargs)\n",
      "  File \"<ipython-input-8-fb09f0c12743>\", line 20, in update_graph\n",
      "    data.append({'x':df['time'], 'y':df['counts'],'name':item})\n",
      "  File \"/home/janeadams/.conda/envs/test_env/lib/python3.7/site-packages/pandas/core/frame.py\", line 2927, in __getitem__\n",
      "    indexer = self.columns.get_loc(key)\n",
      "  File \"/home/janeadams/.conda/envs/test_env/lib/python3.7/site-packages/pandas/core/indexes/base.py\", line 2658, in get_loc\n",
      "    return self._engine.get_loc(self._maybe_cast_indexer(key))\n",
      "  File \"pandas/_libs/index.pyx\", line 108, in pandas._libs.index.IndexEngine.get_loc\n",
      "  File \"pandas/_libs/index.pyx\", line 132, in pandas._libs.index.IndexEngine.get_loc\n",
      "  File \"pandas/_libs/hashtable_class_helper.pxi\", line 1601, in pandas._libs.hashtable.PyObjectHashTable.get_item\n",
      "  File \"pandas/_libs/hashtable_class_helper.pxi\", line 1608, in pandas._libs.hashtable.PyObjectHashTable.get_item\n",
      "KeyError: 'time'\n",
      "127.0.0.1 - - [09/Apr/2019 16:05:06] \"POST /_dash-update-component HTTP/1.1\" 200 -\n",
      "127.0.0.1 - - [09/Apr/2019 16:05:07] \"POST /_dash-update-component HTTP/1.1\" 500 -\n"
     ]
    },
    {
     "name": "stdout",
     "output_type": "stream",
     "text": [
      "No timeseries found for #massmu\n",
      "No timeseries found for #massmut\n",
      "No timeseries found for #massmutu\n",
      "No timeseries found for #massmutua\n"
     ]
    },
    {
     "name": "stderr",
     "output_type": "stream",
     "text": [
      "127.0.0.1 - - [09/Apr/2019 16:05:07] \"POST /_dash-update-component HTTP/1.1\" 200 -\n",
      "127.0.0.1 - - [09/Apr/2019 16:05:08] \"POST /_dash-update-component HTTP/1.1\" 200 -\n",
      "127.0.0.1 - - [09/Apr/2019 16:05:08] \"POST /_dash-update-component HTTP/1.1\" 200 -\n",
      "127.0.0.1 - - [09/Apr/2019 16:06:46] \"POST /_dash-update-component HTTP/1.1\" 200 -\n",
      "127.0.0.1 - - [09/Apr/2019 16:06:47] \"POST /_dash-update-component HTTP/1.1\" 200 -\n",
      "127.0.0.1 - - [09/Apr/2019 16:06:48] \"POST /_dash-update-component HTTP/1.1\" 200 -\n",
      "127.0.0.1 - - [09/Apr/2019 16:06:48] \"POST /_dash-update-component HTTP/1.1\" 200 -\n",
      "127.0.0.1 - - [09/Apr/2019 16:06:48] \"POST /_dash-update-component HTTP/1.1\" 200 -\n",
      "127.0.0.1 - - [09/Apr/2019 16:06:48] \"POST /_dash-update-component HTTP/1.1\" 200 -\n",
      "127.0.0.1 - - [09/Apr/2019 16:06:48] \"POST /_dash-update-component HTTP/1.1\" 200 -\n",
      "127.0.0.1 - - [09/Apr/2019 16:06:48] \"POST /_dash-update-component HTTP/1.1\" 200 -\n",
      "[2019-04-09 16:06:49,894] ERROR in app: Exception on /_dash-update-component [POST]\n",
      "Traceback (most recent call last):\n",
      "  File \"/home/janeadams/.conda/envs/test_env/lib/python3.7/site-packages/pandas/core/indexes/base.py\", line 2656, in get_loc\n",
      "    return self._engine.get_loc(key)\n",
      "  File \"pandas/_libs/index.pyx\", line 108, in pandas._libs.index.IndexEngine.get_loc\n",
      "  File \"pandas/_libs/index.pyx\", line 132, in pandas._libs.index.IndexEngine.get_loc\n",
      "  File \"pandas/_libs/hashtable_class_helper.pxi\", line 1601, in pandas._libs.hashtable.PyObjectHashTable.get_item\n",
      "  File \"pandas/_libs/hashtable_class_helper.pxi\", line 1608, in pandas._libs.hashtable.PyObjectHashTable.get_item\n",
      "KeyError: 'time'\n",
      "\n",
      "During handling of the above exception, another exception occurred:\n",
      "\n",
      "Traceback (most recent call last):\n",
      "  File \"/home/janeadams/.conda/envs/test_env/lib/python3.7/site-packages/flask/app.py\", line 2292, in wsgi_app\n",
      "    response = self.full_dispatch_request()\n",
      "  File \"/home/janeadams/.conda/envs/test_env/lib/python3.7/site-packages/flask/app.py\", line 1815, in full_dispatch_request\n",
      "    rv = self.handle_user_exception(e)\n",
      "  File \"/home/janeadams/.conda/envs/test_env/lib/python3.7/site-packages/flask/app.py\", line 1718, in handle_user_exception\n",
      "    reraise(exc_type, exc_value, tb)\n",
      "  File \"/home/janeadams/.conda/envs/test_env/lib/python3.7/site-packages/flask/_compat.py\", line 35, in reraise\n",
      "    raise value\n",
      "  File \"/home/janeadams/.conda/envs/test_env/lib/python3.7/site-packages/flask/app.py\", line 1813, in full_dispatch_request\n",
      "    rv = self.dispatch_request()\n",
      "  File \"/home/janeadams/.conda/envs/test_env/lib/python3.7/site-packages/flask/app.py\", line 1799, in dispatch_request\n",
      "    return self.view_functions[rule.endpoint](**req.view_args)\n",
      "  File \"/home/janeadams/.conda/envs/test_env/lib/python3.7/site-packages/dash/dash.py\", line 960, in dispatch\n",
      "    return self.callback_map[target_id]['callback'](*args)\n",
      "  File \"/home/janeadams/.conda/envs/test_env/lib/python3.7/site-packages/dash/dash.py\", line 900, in add_context\n",
      "    output_value = func(*args, **kwargs)\n",
      "  File \"<ipython-input-8-fb09f0c12743>\", line 20, in update_graph\n",
      "    data.append({'x':df['time'], 'y':df['counts'],'name':item})\n",
      "  File \"/home/janeadams/.conda/envs/test_env/lib/python3.7/site-packages/pandas/core/frame.py\", line 2927, in __getitem__\n",
      "    indexer = self.columns.get_loc(key)\n",
      "  File \"/home/janeadams/.conda/envs/test_env/lib/python3.7/site-packages/pandas/core/indexes/base.py\", line 2658, in get_loc\n",
      "    return self._engine.get_loc(self._maybe_cast_indexer(key))\n",
      "  File \"pandas/_libs/index.pyx\", line 108, in pandas._libs.index.IndexEngine.get_loc\n",
      "  File \"pandas/_libs/index.pyx\", line 132, in pandas._libs.index.IndexEngine.get_loc\n",
      "  File \"pandas/_libs/hashtable_class_helper.pxi\", line 1601, in pandas._libs.hashtable.PyObjectHashTable.get_item\n",
      "  File \"pandas/_libs/hashtable_class_helper.pxi\", line 1608, in pandas._libs.hashtable.PyObjectHashTable.get_item\n",
      "KeyError: 'time'\n",
      "127.0.0.1 - - [09/Apr/2019 16:06:50] \"POST /_dash-update-component HTTP/1.1\" 500 -\n"
     ]
    },
    {
     "name": "stdout",
     "output_type": "stream",
     "text": [
      "No timeseries found for \n"
     ]
    },
    {
     "name": "stderr",
     "output_type": "stream",
     "text": [
      "127.0.0.1 - - [09/Apr/2019 16:06:50] \"POST /_dash-update-component HTTP/1.1\" 200 -\n",
      "127.0.0.1 - - [09/Apr/2019 16:06:53] \"POST /_dash-update-component HTTP/1.1\" 200 -\n",
      "127.0.0.1 - - [09/Apr/2019 16:06:53] \"POST /_dash-update-component HTTP/1.1\" 200 -\n",
      "127.0.0.1 - - [09/Apr/2019 16:06:54] \"POST /_dash-update-component HTTP/1.1\" 200 -\n",
      "127.0.0.1 - - [09/Apr/2019 16:06:54] \"POST /_dash-update-component HTTP/1.1\" 200 -\n",
      "127.0.0.1 - - [09/Apr/2019 16:06:54] \"POST /_dash-update-component HTTP/1.1\" 200 -\n",
      "127.0.0.1 - - [09/Apr/2019 16:06:55] \"POST /_dash-update-component HTTP/1.1\" 200 -\n",
      "127.0.0.1 - - [09/Apr/2019 16:06:55] \"POST /_dash-update-component HTTP/1.1\" 200 -\n",
      "127.0.0.1 - - [09/Apr/2019 16:06:56] \"POST /_dash-update-component HTTP/1.1\" 200 -\n",
      "127.0.0.1 - - [09/Apr/2019 16:06:56] \"POST /_dash-update-component HTTP/1.1\" 200 -\n"
     ]
    }
   ],
   "source": [
    "external_stylesheets = ['styles.css']\n",
    "\n",
    "server = flask.Flask(__name__)\n",
    "\n",
    "app = dash.Dash(__name__, server=server, external_stylesheets=external_stylesheets)\n",
    "\n",
    "app.layout = html.Div([\n",
    "    html.H1('Twitter 1-grams'),\n",
    "    dcc.Input(id='my-id', value='@realdonaldtrump', type='text'),\n",
    "    dcc.Graph(id='my-graph'),\n",
    "])\n",
    "\n",
    "@app.callback(Output('my-graph', 'figure'), [Input('my-id', 'value')])\n",
    "def update_graph(input_value):\n",
    "    data=[]\n",
    "    figure = {'data':data}\n",
    "    values = input_value.split(',')\n",
    "    for item in values:\n",
    "        df = load(item)\n",
    "        data.append({'x':df['time'], 'y':df['counts'],'name':item})\n",
    "    return figure\n",
    "\n",
    "\n",
    "if __name__ == '__main__':\n",
    "    app.run_server(port=8050)"
   ]
  },
  {
   "cell_type": "markdown",
   "metadata": {},
   "source": [
    "# Dropdown for query"
   ]
  },
  {
   "cell_type": "code",
   "execution_count": null,
   "metadata": {},
   "outputs": [],
   "source": [
    "import numpy as np"
   ]
  },
  {
   "cell_type": "code",
   "execution_count": null,
   "metadata": {},
   "outputs": [],
   "source": [
    "from numpy import random"
   ]
  },
  {
   "cell_type": "code",
   "execution_count": null,
   "metadata": {},
   "outputs": [],
   "source": [
    "nums = random.randint(0,len(wordlist),size=10000)"
   ]
  },
  {
   "cell_type": "code",
   "execution_count": null,
   "metadata": {},
   "outputs": [],
   "source": [
    "options = []\n",
    "for num in nums:\n",
    "    word = wordlist[num][0]\n",
    "    options.append({'label': word,'value': word})"
   ]
  },
  {
   "cell_type": "code",
   "execution_count": null,
   "metadata": {},
   "outputs": [],
   "source": [
    "external_stylesheets = ['styles.css']\n",
    "\n",
    "server = flask.Flask(__name__)\n",
    "\n",
    "app = dash.Dash(__name__, server=server, external_stylesheets=external_stylesheets)\n",
    "\n",
    "app.layout = html.Div([\n",
    "    html.H1('Twitter 1-grams'),\n",
    "    html.Div([\n",
    "        dcc.Dropdown(id='my-dropdown', options=options, value=['@realdonaldtrump','covfefe'], multi=True)]),\n",
    "    dcc.Graph(id='my-graph')\n",
    "])\n",
    "\n",
    "@app.callback(Output('my-graph', 'figure'), [Input('my-dropdown', 'value')])\n",
    "\n",
    "def update_graph(input_value):\n",
    "    data=[]\n",
    "    figure = {'data':data}\n",
    "    for item in input_value:\n",
    "        df = load(item)\n",
    "        data.append({'x':df['time'], 'y':df['counts'],'name':item})\n",
    "    return figure\n",
    "\n",
    "\n",
    "if __name__ == '__main__':\n",
    "    app.run_server()"
   ]
  },
  {
   "cell_type": "code",
   "execution_count": null,
   "metadata": {},
   "outputs": [],
   "source": []
  }
 ],
 "metadata": {
  "kernelspec": {
   "display_name": "Python (TestEnv)",
   "language": "python",
   "name": "test_env"
  },
  "language_info": {
   "codemirror_mode": {
    "name": "ipython",
    "version": 3
   },
   "file_extension": ".py",
   "mimetype": "text/x-python",
   "name": "python",
   "nbconvert_exporter": "python",
   "pygments_lexer": "ipython3",
   "version": "3.7.2"
  }
 },
 "nbformat": 4,
 "nbformat_minor": 2
}
